Workbook

Sheet 입고(2606)
F4: 재고정리
A6: 품명 | C6: 06월 | AH6: 합계
B7: 05월재고 | C7: 1일 | D7: 2일 | E7: 3일 | F7: 4일 | G7: 5일 | H7: 6일 | I7: 7일 | J7: 8일 | K7: 9일 | L7: 10일 | M7: 11일 | N7: 12일 | O7: 13일 | P7: 14일 | Q7: 15일 | R7: 16일 | S7: 17일 | T7: 18일 | U7: 19일 | V7: 20일 | W7: 21일 | X7: 22일 | Y7: 23일 | Z7: 24일 | AA7: 25일 | AB7: 26일 | AC7: 27일 | AD7: 28일 | AE7: 29일 | AF7: 30일
B8: (반제품) | C8: 월 | D8: 화 | E8: 수 | F8: 목 | G8: 금 | H8: 토 | I8: 일 | J8: 월 | K8: 화 | L8: 수 | M8: 목 | N8: 금 | O8: 토 | P8: 일 | Q8: 월 | R8: 화 | S8: 수 | T8: 목 | U8: 금 | V8: 토 | W8: 일 | X8: 월 | Y8: 화 | Z8: 수 | AA8: 목 | AB8: 금 | AC8: 토 | AD8: 일 | AE8: 월 | AF8: 화
A9: 발포소켓 몸체(100)-몸통 | B9: 0 | D9: 900 | G9: 900 | M9: 900 | S9: 900 | U9: 900 | AE9: 900 | AH9: =SUM(C9:AF9) -> 5400
A10: 발포소켓 몸체(100)(150H) | AH10: =SUM(C10:AF10) -> 0
A11: 발포소켓 몸체(100)(170H) | AH11: =SUM(C11:AF11) -> 0
A12: 발포소켓 몸체(100)(180H) | AH12: =SUM(C12:AF12) -> 0
A13: 발포소켓 몸체(100)(190H) | AH13: =SUM(C13:AF13) -> 0
A14: 발포소켓 몸체(100)(200H) | AH14: =SUM(C14:AF14) -> 0
A15: 발포소켓 몸체(100)(210H) | B15: 680 | D15: 960 | G15: 960 | K15: 1680 | M15: 1200 | Q15: 1680 | S15: 1200 | U15: 1200 | Y15: 1680 | AA15: 1680 | AE15: 1200 | AH15: =SUM(C15:AF15) -> 13440
A16: 발포소켓 몸체(100)(240H) | AH16: =SUM(C16:AF16) -> 0
A17: 발포소켓 몸체(100)(250H) | AH17: =SUM(C17:AF17) -> 0
A18: 발포소켓 몸체(100)(260H) | AH18: =SUM(C18:AF18) -> 0
A19: 발포소켓 몸체(75) | D19: 960 | AH19: =SUM(C19:AF19) -> 960
A20: 발포소켓 몸체(50) | G20: 1260 | AH20: =SUM(C20:AF20) -> 1260
A21: 보호철판 / 100 | B21: 1139 | D21: 1860 | G21: 1860 | K21: 1680 | M21: 2100 | Q21: 1680 | S21: 2100 | U21: 2100 | Y21: 1680 | AA21: 1680 | AE21: 2100 | AH21: =SUM(C21:AF21) -> 18840
A22: 보호철판 / 75 | B22: 70 | D22: 960 | AH22: =SUM(C22:AF22) -> 960
A23: 보호철판 / 50 | B23: 356 | G23: 1260 | AH23: =SUM(C23:AF23) -> 1260
A24: 볼트,너트,와샤 | B24: 3060 | D24: 11500 | G24: 12500 | K24: 6500 | M24: 8500 | Q24: 6500 | S24: 8500 | U24: 8500 | Y24: 6500 | AA24: 6500 | AE24: 8500 | AH24: =SUM(C24:AF24) -> 84000
A25: 한국파렛트(총수량) | B25: 8 | D25: 8 | G25: 8 | K25: 7 | M25: 9 | Q25: 7 | S25: 7 | U25: 9 | Y25: 7 | AA25: 7 | AE25: 9 | AH25: =SUM(C25:AF25) -> 78
A26: 화창파렛트(검정) | AH26: =SUM(C26:AF26) -> 0
A27: 박스/내화충전발포소켓(210) | AH27: =SUM(C27:AF27) -> 0
A28: ES박스 | AH28: =SUM(C28:AF28) -> 0
A29: 화창박스 | AH29: =SUM(C29:AF29) -> 0
A30: 시트(재단)100 | AH30: =SUM(C30:AF30) -> 0
A31: 시트(재단)75 | AH31: =SUM(C31:AF31) -> 0
A32: 시트(재단)50 | AH32: =SUM(C32:AF32) -> 0
A33: 시트(압출) | B33: 70 | G33: 63 | J33: 32 | M33: 234 | Z33: 34 | AB33: 139 | AH33: =SUM(B33:AF33) -> 572
O34: =SUM(O9:O33) -> 0 | S34: =SUM(S9:S33) -> 12707 | T34: =SUM(T9:T33) -> 0 | V34: =SUM(V9:V33) -> 0 | X34: =SUM(X9:X33) -> 0 | AB34: =SUM(AB9:AB33) -> 139 | AC34: =SUM(AC9:AC33) -> 0 | AE34: =SUM(AE9:AE33) -> 12709 | AF34: =SUM(AF9:AF33) -> 0

Sheet 출고(2606)
A6: 품명 | C6: 06월 | AH6: 합계
B7: 05월 재고 | C7: 1일 | D7: 2일 | E7: 3일 | F7: 4일 | G7: 5일 | H7: 6일 | I7: 7일 | J7: 8일 | K7: 9일 | L7: 10일 | M7: 11일 | N7: 12일 | O7: 13일 | P7: 14일 | Q7: 15일 | R7: 16일 | S7: 17일 | T7: 18일 | U7: 19일 | V7: 20일 | W7: 21일 | X7: 22일 | Y7: 23일 | Z7: 24일 | AA7: 25일 | AB7: 26일 | AC7: 27일 | AD7: 28일 | AE7: 29일 | AF7: 30일
C8: 월 | D8: 화 | E8: 수 | F8: 목 | G8: 금 | H8: 토 | I8: 일 | J8: 월 | K8: 화 | L8: 수 | M8: 목 | N8: 금 | O8: 토 | P8: 일 | Q8: 월 | R8: 화 | S8: 수 | T8: 목 | U8: 금 | V8: 토 | W8: 일 | X8: 월 | Y8: 화 | Z8: 수 | AA8: 목 | AB8: 금 | AC8: 토 | AD8: 일 | AE8: 월 | AF8: 화
A9: 발포소켓 몸체(100)-몸통 | K9: 1200 | M9: 600 | Q9: 300 | S9: 600 | U9: 300 | Y9: 900 | AA9: 600 | AH9: =SUM(C9:AF9) -> 4500
A10: 발포소켓 몸체(100)(150H) | AH10: =SUM(C10:AF10) -> 0
A11: 발포소켓 몸체(100)(170H) | AH11: =SUM(C11:AF11) -> 0
A12: 발포소켓 몸체(100)(180H) | AH12: =SUM(C12:AF12) -> 0
A13: 발포소켓 몸체(100)(190H) | AH13: =SUM(C13:AF13) -> 0
A14: 발포소켓 몸체(100)(200H) | AH14: =SUM(C14:AF14) -> 0
A15: 발포소켓 몸체(100)(210H) | D15: 1680 | G15: 960 | K15: 960 | M15: 1440 | Q15: 1440 | S15: 1440 | U15: 1440 | Y15: 1200 | AA15: 1440 | AE15: 1920 | AH15: =SUM(C15:AF15) -> 13920
A16: 발포소켓 몸체(100)(240H) | AH16: =SUM(C16:AF16) -> 0
A17: 발포소켓 몸체(100)(250H) | AH17: =SUM(C17:AF17) -> 0
A18: 발포소켓 몸체(100)(260H) | AH18: =SUM(C18:AF18) -> 0
A19: 발포소켓 몸체(75) | G19: 960 | AH19: =SUM(C19:AF19) -> 960
A20: 발포소켓 몸체(50) | Q20: 300 | U20: 480 | AH20: =SUM(C20:AF20) -> 780
A21: 보호철판 / 100 | AH21: =SUM(C21:AF21) -> 0
A22: 보호철판 / 75 | AH22: =SUM(C22:AF22) -> 0
A23: 보호철판 / 50 | AH23: =SUM(C23:AF23) -> 0
A24: 볼트,너트,와샤 | AH24: =SUM(C24:AF24) -> 0
A25: 한국파렛트 | D25: 7 | G25: 6 | K25: 8 | M25: 8 | Q25: 8 | S25: 8 | U25: 8 | Y25: 8 | AA25: 8 | AE25: 8 | AH25: =SUM(C25:AF25) -> 77
A26: 화창파렛트 | AH26: =SUM(C26:AF26) -> 0
A27: 박스/내화충전발포소켓(210) | AH27: =SUM(C27:AF27) -> 0
A28: ES박스 | AH28: =SUM(C28:AF28) -> 0
A29: 화창박스 | AH29: =SUM(C29:AF29) -> 0
A30: 시트(재단)100 | AH30: =SUM(C30:AF30) -> 0
A31: 시트(재단)75 | AH31: =SUM(C31:AF31) -> 0
A32: 시트(재단)50 | AH32: =SUM(C32:AF32) -> 0
A33: 시트(압출) | AH33: =SUM(C33:AF33) -> 0
O34: =SUM(O9:O33) -> 0 | S34: =SUM(S9:S33) -> 2048 | T34: =SUM(T9:T33) -> 0 | V34: =SUM(V9:V33) -> 0 | X34: =SUM(X9:X33) -> 0 | AB34: =SUM(AB9:AB33) -> 0 | AC34: =SUM(AC9:AC33) -> 0 | AE34: =SUM(AE9:AE33) -> 1928 | AF34: =SUM(AF9:AF33) -> 0

Sheet 생산량(2606)
F4: 재고정리
A6: 품명 | C6: 06월 | AH6: 합계
B7: 05월 재고 | C7: 1일 | D7: 2일 | E7: 3일 | F7: 4일 | G7: 5일 | H7: 6일 | I7: 7일 | J7: 8일 | K7: 9일 | L7: 10일 | M7: 11일 | N7: 12일 | O7: 13일 | P7: 14일 | Q7: 15일 | R7: 16일 | S7: 17일 | T7: 18일 | U7: 19일 | V7: 20일 | W7: 21일 | X7: 22일 | Y7: 23일 | Z7: 24일 | AA7: 25일 | AB7: 26일 | AC7: 27일 | AD7: 28일 | AE7: 29일 | AF7: 30일
B8: (완제품) | C8: 월 | D8: 화 | E8: 수 | F8: 목 | G8: 금 | H8: 토 | I8: 일 | J8: 월 | K8: 화 | L8: 수 | M8: 목 | N8: 금 | O8: 토 | P8: 일 | Q8: 월 | R8: 화 | S8: 수 | T8: 목 | U8: 금 | V8: 토 | W8: 일 | X8: 월 | Y8: 화 | Z8: 수 | AA8: 목 | AB8: 금 | AC8: 토 | AD8: 일 | AE8: 월 | AF8: 화
A9: 발포소켓 몸체(100)-몸통 | G9: 900 | J9: 300 | K9: 600 | N9: 300 | Q9: 600 | T9: 300 | U9: 600 | X9: 300 | Y9: 600 | AF9: 600 | AH9: =SUM(C9:AF9) -> 5100
A10: 발포소켓 몸체(100)(150H) | AH10: =SUM(C10:AF10) -> 0
A11: 발포소켓 몸체(100)(170H) | AH11: =SUM(C11:AF11) -> 0
A12: 발포소켓 몸체(100)(180H) | AH12: =SUM(C12:AF12) -> 0
A13: 발포소켓 몸체(100)(190H) | AH13: =SUM(C13:AF13) -> 0
A14: 발포소켓 몸체(100)(200H) | AH14: =SUM(C14:AF14) -> 0
A15: 발포소켓 몸체(100)(210H) | B15: 1000 | C15: 680 | D15: 960 | G15: 240 | J15: 720 | K15: 480 | L15: 960 | M15: 720 | N15: 720 | Q15: 480 | R15: 1200 | S15: 480 | T15: 720 | U15: 480 | X15: 720 | Y15: 480 | Z15: 960 | AA15: 960 | AB15: 960 | AE15: 720 | AF15: 480 | AH15: =SUM(C15:AF15) -> 14120
A16: 발포소켓 몸체(100)(240H) | AH16: =SUM(C16:AF16) -> 0
A17: 발포소켓 몸체(100)(250H) | AH17: =SUM(C17:AF17) -> 0
A18: 발포소켓 몸체(100)(260H) | AH18: =SUM(C18:AF18) -> 0
A19: 발포소켓 몸체(75) | F19: 960 | AH19: =SUM(C19:AF19) -> 960
A20: 발포소켓 몸체(50) | M20: 300 | S20: 480 | AE20: 480 | AH20: =SUM(C20:AF20) -> 1260
A21: 보호철판 / 100 | B21: 1000 | C21: =SUM(C9:C18) -> 680 | D21: =SUM(D9:D18) -> 960 | F21: =SUM(F9:F18) -> 0 | G21: =SUM(G9:G18) -> 1140 | J21: =SUM(J9:J18) -> 1020 | K21: =SUM(K9:K18) -> 1080 | L21: =SUM(L9:L18) -> 960 | M21: =SUM(M9:M18) -> 720 | N21: =SUM(N9:N18) -> 1020 | Q21: =SUM(Q9:Q18) -> 1080 | R21: =SUM(R9:R18) -> 1200 | S21: =SUM(S9:S18) -> 480 | T21: =SUM(T9:T18) -> 1020 | U21: =SUM(U9:U18) -> 1080 | X21: =SUM(X9:X18) -> 1020 | Y21: =SUM(Y9:Y18) -> 1080 | Z21: =SUM(Z9:Z18) -> 960 | AA21: =SUM(AA9:AA18) -> 960 | AB21: =SUM(AB9:AB18) -> 960 | AE21: =SUM(AE9:AE18) -> 720 | AF21: =SUM(AF9:AF18) -> 1080 | AH21: =SUM(C21:AF21) -> 19220
A22: 보호철판 / 75 | C22: =C19 -> 0 | D22: =D19 -> 0 | F22: =F19 -> 960 | G22: =G19 -> 0 | J22: =J19 -> 0 | K22: =K19 -> 0 | L22: =L19 -> 0 | M22: =M19 -> 0 | N22: =N19 -> 0 | Q22: =Q19 -> 0 | R22: =R19 -> 0 | S22: =S19 -> 0 | T22: =T19 -> 0 | U22: =U19 -> 0 | X22: =X19 -> 0 | Y22: =Y19 -> 0 | Z22: =Z19 -> 0 | AA22: =AA19 -> 0 | AB22: =AB19 -> 0 | AE22: =AE19 -> 0 | AF22: =AF19 -> 0 | AH22: =SUM(C22:AF22) -> 960
A23: 보호철판 / 50 | C23: =C20 -> 0 | D23: =D20 -> 0 | F23: =F20 -> 0 | G23: =G20 -> 0 | J23: =J20 -> 0 | K23: =K20 -> 0 | L23: =L20 -> 0 | M23: =M20 -> 300 | N23: =N20 -> 0 | Q23: =Q20 -> 0 | R23: =R20 -> 0 | S23: =S20 -> 480 | T23: =T20 -> 0 | U23: =U20 -> 0 | X23: =X20 -> 0 | Y23: =Y20 -> 0 | Z23: =Z20 -> 0 | AA23: =AA20 -> 0 | AB23: =AB20 -> 0 | AE23: =AE20 -> 480 | AF23: =AF20 -> 0 | AH23: =SUM(C23:AF23) -> 1260
A24: 볼트,너트,와샤 | B24: 4000 | C24: =SUM(C21:C23)*4 -> 2720 | D24: =SUM(D21:D23)*4 -> 3840 | F24: =SUM(F21:F23)*4 -> 3840 | G24: =SUM(G21:G23)*4 -> 4560 | J24: =SUM(J21:J23)*4 -> 4080 | K24: =SUM(K21:K23)*4 -> 4320 | L24: =SUM(L21:L23)*4 -> 3840 | M24: =SUM(M21:M23)*4 -> 4080 | N24: =SUM(N21:N23)*4 -> 4080 | Q24: =SUM(Q21:Q23)*4 -> 4320 | R24: =SUM(R21:R23)*4 -> 4800 | S24: =SUM(S21:S23)*4 -> 3840 | T24: =SUM(T21:T23)*4 -> 4080 | U24: =SUM(U21:U23)*4 -> 4320 | X24: =SUM(X21:X23)*4 -> 4080 | Y24: =SUM(Y21:Y23)*4 -> 4320 | Z24: =SUM(Z21:Z23)*4 -> 3840 | AA24: =SUM(AA21:AA23)*4 -> 3840 | AB24: =SUM(AB21:AB23)*4 -> 3840 | AE24: =SUM(AE21:AE23)*4 -> 4800 | AF24: =SUM(AF21:AF23)*4 -> 4320 | AH24: =SUM(C24:AF24) -> 85760
A25: 한국파렛트 | AH25: =SUM(C25:AF25) -> 0
A26: 화창파렛트 | AH26: =SUM(C26:AF26) -> 0
AH27: =SUM(C27:AF27) -> 0
AH28: =SUM(C28:AF28) -> 0
AH29: =SUM(C29:AF29) -> 0
A30: 시트(재단)100 | B30: 863 | D30: 2150 | G30: 2450 | K30: 1250 | M30: 1450 | Q30: 1450 | R30: 1200 | S30: 1200 | U30: 1700 | X30: 1600 | Z30: 1350 | AB30: 1400 | AE30: 1350 | AF30: 1350 | AH30: =SUM(C30:AF30) -> 19900
A31: 시트(재단)75 | B31: 473 | F31: 500 | AH31: =SUM(C31:AF31) -> 500
A32: 시트(재단)50 | B32: 300 | R32: 450 | S32: 520 | AH32: =SUM(C32:AF32) -> 970
A33: 시트(압출) - 재단수량 | D33: 54 | F33: 16 | G33: 63 | K33: 32 | M33: 36 | Q33: 36 | R33: 38 | S33: 40 | U33: 43 | X33: 41 | Z33: 34 | AB33: 35 | AE33: 34 | AF33: 34 | AH33: =SUM(C33:AF33) -> 536
O34: =SUM(O9:O33) -> 0 | S34: =SUM(S9:S33) -> 7520 | T34: =SUM(T9:T33) -> 6120 | V34: =SUM(V9:V33) -> 0 | X34: =SUM(X9:X33) -> 7761 | AB34: =SUM(AB9:AB33) -> 7195 | AC34: =SUM(AC9:AC33) -> 0 | AE34: =SUM(AE9:AE33) -> 8584 | AF34: =SUM(AF9:AF33) -> 7864

Sheet 통합현황
B2: 2026년 06월 FN테크 제품현황
B3: 반제품, 완제품 현황 | L3: 시트 재고현황
B4: 타입/현황 | C4: 전월재고(반제품) | D4: 전월재고(완제품) | E4: 06월입고 | F4: 06월출고 | G4: 생산수량(완제품) | H4: 반제품 계 | I4: 완제품 계 | J4: 총 합계 | L4: 타입/현황 | M4: 전월재고 | N4: 생산수량 | O4: 재단시트재고 | P4: 압출시트재고
B5: 100(몸통) | C5: ='입고(2606)'!B9 -> 0 | D5: ='생산량(2606)'!B9 -> 0 | E5: ='입고(2606)'!AH9 -> 5400 | F5: ='출고(2606)'!AH9 -> 4500 | G5: ='생산량(2606)'!AH9 -> 5100 | H5: =(C5+E5)-G5 -> 300 | I5: =(D5+G5)-F5 -> 600 | J5: =I5+H5 -> 900 | L5: 100 | M5: ='생산량(2606)'!B30 -> 863 | N5: ='생산량(2606)'!AH30 -> 19900 | O5: =(N5+M5)-SUM('생산량(2606)'!AH9:AH18) -> 1543 | P5: ='입고(2606)'!AH33-'생산량(2606)'!AH33 -> 36 | Q5: 스티커동봉 | R5: 최진영차장출력
B6: 100(150H) | C6: ='입고(2606)'!B10 -> 0 | D6: ='생산량(2606)'!B10 -> 0 | E6: ='입고(2606)'!AH10 -> 0 | F6: ='출고(2606)'!AH10 -> 0 | G6: ='생산량(2606)'!AH10 -> 0 | H6: =(C6+E6)-G6 -> 0 | I6: =(D6+G6)-F6 -> 0 | J6: =I6+H6 -> 0
B7: 100(170H) | C7: ='입고(2606)'!B11 -> 0 | D7: ='생산량(2606)'!B11 -> 0 | E7: ='입고(2606)'!AH11 -> 0 | F7: ='출고(2606)'!AH11 -> 0 | G7: ='생산량(2606)'!AH11 -> 0 | H7: =(C7+E7)-G7 -> 0 | I7: =(D7+G7)-F7 -> 0 | J7: =I7+H7 -> 0
B8: 100(180H) | C8: ='입고(2606)'!B12 -> 0 | D8: ='생산량(2606)'!B12 -> 0 | E8: ='입고(2606)'!AH12 -> 0 | F8: ='출고(2606)'!AH12 -> 0 | G8: ='생산량(2606)'!AH12 -> 0 | H8: =(C8+E8)-G8 -> 0 | I8: =(D8+G8)-F8 -> 0 | J8: =I8+H8 -> 0
B9: 100(190H) | C9: ='입고(2606)'!B13 -> 0 | D9: ='생산량(2606)'!B13 -> 0 | E9: ='입고(2606)'!AH13 -> 0 | F9: ='출고(2606)'!AH13 -> 0 | G9: ='생산량(2606)'!AH13 -> 0 | H9: =(C9+E9)-G9 -> 0 | I9: =(D9+G9)-F9 -> 0 | J9: =I9+H9 -> 0
B10: 100(200H) | C10: ='입고(2606)'!B14 -> 0 | D10: ='생산량(2606)'!B14 -> 0 | E10: ='입고(2606)'!AH14 -> 0 | F10: ='출고(2606)'!AH14 -> 0 | G10: ='생산량(2606)'!AH14 -> 0 | H10: =(C10+E10)-G10 -> 0 | I10: =(D10+G10)-F10 -> 0 | J10: =I10+H10 -> 0
B11: 100(210H) | C11: ='입고(2606)'!B15 -> 680 | D11: ='생산량(2606)'!B15 -> 1000 | E11: ='입고(2606)'!AH15 -> 13440 | F11: ='출고(2606)'!AH15 -> 13920 | G11: ='생산량(2606)'!AH15 -> 14120 | H11: =(C11+E11)-G11 -> 0 | I11: =(D11+G11)-F11 -> 1200 | J11: =I11+H11 -> 1200 | L11: 75 | M11: ='생산량(2606)'!B31 -> 473 | N11: ='생산량(2606)'!AH31 -> 500 | O11: =(N11+M11)-'생산량(2606)'!AH19 -> 13 | Q11: 스티커부착작업 | R11: 최진영차장출력
B12: 100(240H) | C12: ='입고(2606)'!B16 -> 0 | D12: ='생산량(2606)'!B16 -> 0 | E12: ='입고(2606)'!AH16 -> 0 | F12: ='출고(2606)'!AH16 -> 0 | G12: ='생산량(2606)'!AH16 -> 0 | H12: =(C12+E12)-G12 -> 0 | I12: =(D12+G12)-F12 -> 0 | J12: =I12+H12 -> 0
B13: 100(250H) | C13: ='입고(2606)'!B17 -> 0 | D13: ='생산량(2606)'!B17 -> 0 | E13: ='입고(2606)'!AH17 -> 0 | F13: ='출고(2606)'!AH17 -> 0 | G13: ='생산량(2606)'!AH17 -> 0 | H13: =(C13+E13)-G13 -> 0 | I13: =(D13+G13)-F13 -> 0 | J13: =I13+H13 -> 0
B14: 100(260H) | C14: ='입고(2606)'!B18 -> 0 | D14: ='생산량(2606)'!B18 -> 0 | E14: ='입고(2606)'!AH18 -> 0 | F14: ='출고(2606)'!AH18 -> 0 | G14: ='생산량(2606)'!AH18 -> 0 | H14: =(C14+E14)-G14 -> 0 | I14: =(D14+G14)-F14 -> 0 | J14: =I14+H14 -> 0 | L14: 50 | M14: ='생산량(2606)'!B32 -> 300 | N14: ='생산량(2606)'!AH32 -> 970 | O14: =(N14+M14)-'생산량(2606)'!AH20 -> 10 | Q14: 스티커동봉 | R14: 최진영차장출력
B15: 75 | C15: ='입고(2606)'!B19 -> 0 | D15: ='생산량(2606)'!B19 -> 0 | E15: ='입고(2606)'!AH19 -> 960 | F15: ='출고(2606)'!AH19 -> 960 | G15: ='생산량(2606)'!AH19 -> 960 | H15: =(C15+E15)-G15 -> 0 | I15: =(D15+G15)-F15 -> 0 | J15: =I15+H15 -> 0 | Q15: 스티커동봉 | R15: 최진영차장출력
B16: 50 | C16: ='입고(2606)'!B20 -> 0 | D16: ='생산량(2606)'!B20 -> 0 | E16: ='입고(2606)'!AH20 -> 1260 | F16: ='출고(2606)'!AH20 -> 780 | G16: ='생산량(2606)'!AH20 -> 1260 | H16: =(C16+E16)-G16 -> 0 | I16: =(D16+G16)-F16 -> 480 | J16: =I16+H16 -> 480 | Q16: 스티커동봉 | R16: 최진영차장출력
B18: 보호철판(100) | C18: ='입고(2606)'!B21 -> 1139 | D18: ='생산량(2606)'!B21 -> 1000 | E18: ='입고(2606)'!AH21 -> 18840 | F18: =SUM(F5:F14) -> 18420 | G18: ='생산량(2606)'!AH21 -> 19220 | H18: =(C18+E18)-G18 -> 759 | I18: =SUM(I5:I14) -> 1800 | J18: =I18+H18 -> 2559 | Q18: 박스스티커동봉 | R18: 이윤호주임출력
B19: 보호철판(75) | C19: ='입고(2606)'!B22 -> 70 | D19: ='생산량(2606)'!B22 -> 0 | E19: ='입고(2606)'!AH22 -> 960 | F19: ='출고(2606)'!AH22 -> 0 | G19: ='생산량(2606)'!AH22 -> 960 | H19: =(C19+E19)-G19 -> 70 | I19: =I15 -> 0 | J19: =I19+H19 -> 70
B20: 보호철판(50) | C20: ='입고(2606)'!B23 -> 356 | D20: ='생산량(2606)'!B23 -> 0 | E20: ='입고(2606)'!AH23 -> 1260 | F20: ='출고(2606)'!AH23 -> 0 | G20: ='생산량(2606)'!AH23 -> 1260 | H20: =(C20+E20)-G20 -> 356 | I20: =I16 -> 480 | J20: =I20+H20 -> 836
B21: 볼트,너트,와샤 | C21: ='입고(2606)'!B24 -> 3060 | D21: ='생산량(2606)'!B24 -> 4000 | E21: ='입고(2606)'!AH24 -> 84000 | F21: ='출고(2606)'!AH24 -> 0 | G21: ='생산량(2606)'!AH24 -> 85760 | H21: =(C21+E21)-G21 -> 1300 | I21: =SUM(I18:I20)*4 -> 9120 | J21: =I21+H21 -> 10420
B22: 파렛트(한국,화창) | C22: ='입고(2606)'!B25 -> 8 | E22: ='입고(2606)'!AH25+'입고(2606)'!AH26 -> 78 | F22: ='출고(2606)'!AH25+'출고(2606)'!AH26 -> 77 | G22: ='생산량(2606)'!AH25 -> 0 | J22: =(C22+E22)-F22 -> 9
C24: 1BOX/1PALLET | D24: 출고수량 | E24: 출고LOT(06/29) | F24: 출고시트LOT | G24: 입고LOT | H24: 사용시트LOT | I24: 수량 | J24: 생산LOT | L24: 스티커 | M24: 출력여부 | N24: 조립일정
B25: 100(몸통) | C25: 12EA | G25: 20629U002/260629GI001 | H25: 260623-S02(658~1350)693 | I25: =I5 -> 600 | J25: 260629-FN-100(1201~2100) | L25: 스티커 O | M25: 부착중
C26: 300EA | H26: 260623-S04(1~207)207
B29: 100(150H) | C29: 12EA | I29: =I6 -> 0
C30: 300EA
B32: 100(170H) | C32: 12EA | I32: =I7 -> 0
C33: 300EA
B36: 100(180H) | C36: 12EA | I36: =I8-D36 -> 0
C37: 240EA
B38: 100(190H) | C38: 12EA | I38: =I9 -> 0
C39: 240EA
B40: 100(200H) | C40: 12EA | I40: =I10 -> 0 | L40: 스티커 O | M40: 부착중
C41: 240EA
B42: 100(210H) | C42: 12EA | D42: 1920(8P) | E42: 260623-FN-100(1441~1680) | F42: 260618-S12(238~477)240 | G42: 20629U001/260629GI001 | H42: 260623-S01(808~1350)543 | I42: =I11 -> 1200 | J42: 260629-FN-100(0001~1200) | L42: 스티커 O | M42: 부착 | N42: 재고
C43: 240EA | E43: 260623U001/260623GI001 | H43: 260623-S02(1~657)657
L44: 스티커 O | M44: 부착중
E45: 260625-FN-100(0001~1680) | F45: 260618-S12(478~1350)873
E46: 260625U001/260625GI001 | F46: 260623-S01(1~807)807
B47: 100(240H) | C47: 12EA | I47: =I12-D47 -> 0
C48: 240EA
...
