Workbook

Sheet 입고(2607)
F4: 재고정리
A6: 품명 | C6: 07월 | AH6: 합계
B7: 06월재고 | C7: 1일 | D7: 2일 | E7: 3일 | F7: 4일 | G7: 5일 | H7: 6일 | I7: 7일 | J7: 8일 | K7: 9일 | L7: 10일 | M7: 11일 | N7: 12일 | O7: 13일 | P7: 14일 | Q7: 15일 | R7: 16일 | S7: 17일 | T7: 18일 | U7: 19일 | V7: 20일 | W7: 21일 | X7: 22일 | Y7: 23일 | Z7: 24일 | AA7: 25일 | AB7: 26일 | AC7: 27일 | AD7: 28일 | AE7: 29일 | AF7: 30일 | AG7: 31일
B8: (반제품) | C8: 수 | D8: 목 | E8: 금 | F8: 토 | G8: 일 | H8: 월 | I8: 화 | J8: 수 | K8: 목 | L8: 금 | M8: 토 | N8: 일 | O8: 월 | P8: 화 | Q8: 수 | R8: 목 | S8: 금 | T8: 토 | U8: 일 | V8: 월 | W8: 화 | X8: 수 | Y8: 목 | Z8: 금 | AA8: 토 | AB8: 일 | AC8: 월 | AD8: 화 | AE8: 수 | AF8: 목 | AG8: 금
A9: 발포소켓 몸체(100)-몸통 | B9: 300 | C9: 900 | O9: 900 | AH9: =SUM(C9:AF9) -> 1800
A10: 발포소켓 몸체(100)(150H) | AH10: =SUM(C10:AF10) -> 0
A11: 발포소켓 몸체(100)(170H) | AH11: =SUM(C11:AF11) -> 0
A12: 발포소켓 몸체(100)(180H) | AH12: =SUM(C12:AF12) -> 0
A13: 발포소켓 몸체(100)(190H) | AH13: =SUM(C13:AF13) -> 0
A14: 발포소켓 몸체(100)(200H) | AH14: =SUM(C14:AF14) -> 0
A15: 발포소켓 몸체(100)(210H) | C15: 960 | E15: 1680 | O15: 998 | Q15: 1440 | V15: 1680 | AH15: =SUM(C15:AF15) -> 6758
A16: 발포소켓 몸체(100)(240H) | AH16: =SUM(C16:AF16) -> 0
A17: 발포소켓 몸체(100)(250H) | AH17: =SUM(C17:AF17) -> 0
A18: 발포소켓 몸체(100)(260H) | AH18: =SUM(C18:AF18) -> 0
A19: 발포소켓 몸체(75) | C19: 960 | Q19: 642 | AH19: =SUM(C19:AF19) -> 1602
A20: 발포소켓 몸체(50) | Q20: 447 | AH20: =SUM(C20:AF20) -> 447
A21: 보호철판 / 100 | B21: 759 | C21: 1860 | E21: 1680 | O21: 2100 | Q21: 1440 | V21: 1680 | AH21: =SUM(C21:AF21) -> 8760
A22: 보호철판 / 75 | B22: 70 | C22: 960 | Q22: 642 | AH22: =SUM(C22:AF22) -> 1602
A23: 보호철판 / 50 | B23: 356 | Q23: 447 | AH23: =SUM(C23:AF23) -> 447
A24: 볼트,너트,와샤 | B24: 1300 | C24: 11000 | E24: 8500 | O24: 8500 | Q24: 9500 | V24: 7000 | AH24: =SUM(C24:AF24) -> 44500
A25: 한국파렛트(총수량) | B25: 9 | C25: 8 | E25: 7 | O25: 7 | Q25: 7 | V25: 7 | AH25: =SUM(C25:AF25) -> 36
A26: 화창파렛트(검정) | C26: 1 | AH26: =SUM(C26:AF26) -> 1
A27: 박스/내화충전발포소켓(210) | AH27: =SUM(C27:AF27) -> 0
A28: ES박스 | AH28: =SUM(C28:AF28) -> 0
A29: 화창박스 | AH29: =SUM(C29:AF29) -> 0
A30: 시트(재단)100 | AH30: =SUM(C30:AF30) -> 0
A31: 시트(재단)75 | AH31: =SUM(C31:AF31) -> 0
A32: 시트(재단)50 | AH32: =SUM(C32:AF32) -> 0
A33: 시트(압출) | B33: 36 | C33: 37 | O33: 70 | P33: 73 | R33: 115 | AH33: =SUM(B33:AF33) -> 331
O34: =SUM(O9:O33) -> 12575 | S34: =SUM(S9:S33) -> 0 | T34: =SUM(T9:T33) -> 0 | V34: =SUM(V9:V33) -> 10367 | X34: =SUM(X9:X33) -> 0 | AB34: =SUM(AB9:AB33) -> 0 | AC34: =SUM(AC9:AC33) -> 0 | AE34: =SUM(AE9:AE33) -> 0 | AF34: =SUM(AF9:AF33) -> 0

Sheet 출고(2607)
A6: 품명 | C6: 07월 | AH6: 합계
B7: 06월재고 | C7: 1일 | D7: 2일 | E7: 3일 | F7: 4일 | G7: 5일 | H7: 6일 | I7: 7일 | J7: 8일 | K7: 9일 | L7: 10일 | M7: 11일 | N7: 12일 | O7: 13일 | P7: 14일 | Q7: 15일 | R7: 16일 | S7: 17일 | T7: 18일 | U7: 19일 | V7: 20일 | W7: 21일 | X7: 22일 | Y7: 23일 | Z7: 24일 | AA7: 25일 | AB7: 26일 | AC7: 27일 | AD7: 28일 | AE7: 29일 | AF7: 30일 | AG7: 31일
C8: 수 | D8: 목 | E8: 금 | F8: 토 | G8: 일 | H8: 월 | I8: 화 | J8: 수 | K8: 목 | L8: 금 | M8: 토 | N8: 일 | O8: 월 | P8: 화 | Q8: 수 | R8: 목 | S8: 금 | T8: 토 | U8: 일 | V8: 월 | W8: 화 | X8: 수 | Y8: 목 | Z8: 금 | AA8: 토 | AB8: 일 | AC8: 월 | AD8: 화 | AE8: 수 | AF8: 목 | AG8: 금
A9: 발포소켓 몸체(100)-몸통 | C9: 600 | E9: 300 | O9: 900 | Q9: 300 | V9: 600 | AH9: =SUM(C9:AF9) -> 2700
A10: 발포소켓 몸체(100)(150H) | AH10: =SUM(C10:AF10) -> 0
A11: 발포소켓 몸체(100)(170H) | AH11: =SUM(C11:AF11) -> 0
A12: 발포소켓 몸체(100)(180H) | AH12: =SUM(C12:AF12) -> 0
A13: 발포소켓 몸체(100)(190H) | AH13: =SUM(C13:AF13) -> 0
A14: 발포소켓 몸체(100)(200H) | AH14: =SUM(C14:AF14) -> 0
A15: 발포소켓 몸체(100)(210H) | C15: 1200 | E15: 960 | O15: 1200 | Q15: 1478 | V15: 1440 | AH15: =SUM(C15:AF15) -> 6278
A16: 발포소켓 몸체(100)(240H) | AH16: =SUM(C16:AF16) -> 0
A17: 발포소켓 몸체(100)(250H) | AH17: =SUM(C17:AF17) -> 0
A18: 발포소켓 몸체(100)(260H) | AH18: =SUM(C18:AF18) -> 0
A19: 발포소켓 몸체(75) | E19: 960 | AH19: =SUM(C19:AF19) -> 960
A20: 발포소켓 몸체(50) | C20: 480 | AH20: =SUM(C20:AF20) -> 480
A21: 보호철판 / 100 | AH21: =SUM(C21:AF21) -> 0
A22: 보호철판 / 75 | AH22: =SUM(C22:AF22) -> 0
A23: 보호철판 / 50 | AH23: =SUM(C23:AF23) -> 0
A24: 볼트,너트,와샤 | AH24: =SUM(C24:AF24) -> 0
A25: 한국파렛트 | C25: 8 | E25: 7 | O25: 7 | Q25: 8 | V25: 8 | AH25: =SUM(C25:AF25) -> 38
A26: 화창파렛트 | AH26: =SUM(C26:AF26) -> 0
A27: 박스/내화충전발포소켓(210) | AH27: =SUM(C27:AF27) -> 0
A28: ES박스 | AH28: =SUM(C28:AF28) -> 0
A29: 화창박스 | AH29: =SUM(C29:AF29) -> 0
A30: 시트(재단)100 | AH30: =SUM(C30:AF30) -> 0
A31: 시트(재단)75 | AH31: =SUM(C31:AF31) -> 0
A32: 시트(재단)50 | AH32: =SUM(C32:AF32) -> 0
A33: 시트(압출) | AH33: =SUM(C33:AF33) -> 0
O34: =SUM(O9:O33) -> 2107 | S34: =SUM(S9:S33) -> 0 | T34: =SUM(T9:T33) -> 0 | V34: =SUM(V9:V33) -> 2048 | X34: =SUM(X9:X33) -> 0 | AB34: =SUM(AB9:AB33) -> 0 | AC34: =SUM(AC9:AC33) -> 0 | AE34: =SUM(AE9:AE33) -> 0 | AF34: =SUM(AF9:AF33) -> 0

Sheet 생산량(2607)
F4: 재고정리
A6: 품명 | C6: 07월 | AH6: 합계
B7: 06월재고 | C7: 1일 | D7: 2일 | E7: 3일 | F7: 4일 | G7: 5일 | H7: 6일 | I7: 7일 | J7: 8일 | K7: 9일 | L7: 10일 | M7: 11일 | N7: 12일 | O7: 13일 | P7: 14일 | Q7: 15일 | R7: 16일 | S7: 17일 | T7: 18일 | U7: 19일 | V7: 20일 | W7: 21일 | X7: 22일 | Y7: 23일 | Z7: 24일 | AA7: 25일 | AB7: 26일 | AC7: 27일 | AD7: 28일 | AE7: 29일 | AF7: 30일 | AG7: 31일
B8: (완제품) | C8: 수 | D8: 목 | E8: 금 | F8: 토 | G8: 일 | H8: 월 | I8: 화 | J8: 수 | K8: 목 | L8: 금 | M8: 토 | N8: 일 | O8: 월 | P8: 화 | Q8: 수 | R8: 목 | S8: 금 | T8: 토 | U8: 일 | V8: 월 | W8: 화 | X8: 수 | Y8: 목 | Z8: 금 | AA8: 토 | AB8: 일 | AC8: 월 | AD8: 화 | AE8: 수 | AF8: 목 | AG8: 금
A9: 발포소켓 몸체(100)-몸통 | B9: 600 | C9: 300 | E9: 900 | P9: 900 | AH9: =SUM(C9:AF9) -> 2100
A10: 발포소켓 몸체(100)(150H) | AH10: =SUM(C10:AF10) -> 0
A11: 발포소켓 몸체(100)(170H) | AH11: =SUM(C11:AF11) -> 0
A12: 발포소켓 몸체(100)(180H) | AH12: =SUM(C12:AF12) -> 0
A13: 발포소켓 몸체(100)(190H) | AH13: =SUM(C13:AF13) -> 0
A14: 발포소켓 몸체(100)(200H) | AH14: =SUM(C14:AF14) -> 0
A15: 발포소켓 몸체(100)(210H) | B15: 1200 | D15: 960 | J15: 960 | K15: 720 | O15: 998 | Q15: 840 | R15: 600 | V15: 720 | W15: 960 | AH15: =SUM(C15:AF15) -> 6758
A16: 발포소켓 몸체(100)(240H) | AH16: =SUM(C16:AF16) -> 0
A17: 발포소켓 몸체(100)(250H) | AH17: =SUM(C17:AF17) -> 0
A18: 발포소켓 몸체(100)(260H) | AH18: =SUM(C18:AF18) -> 0
A19: 발포소켓 몸체(75) | C19: 760 | D19: 200 | R19: 342 | V19: 300 | AH19: =SUM(C19:AF19) -> 1602
A20: 발포소켓 몸체(50) | B20: 480 | X20: 447 | AH20: =SUM(C20:AF20) -> 447
A21: 보호철판 / 100 | B21: 1800 | C21: =SUM(C9:C18) -> 300 | D21: =SUM(D9:D18) -> 960 | E21: =SUM(E9:E18) -> 900 | F21: =SUM(F9:F18) -> 0 | G21: =SUM(G9:G18) -> 0 | H21: =SUM(H9:H18) -> 0 | I21: =SUM(I9:I18) -> 0 | J21: =SUM(J9:J18) -> 960 | ... AG21: =SUM(AG9:AG18) -> 0 | AH21: =SUM(C21:AF21) -> 8858
A22: 보호철판 / 75 | C22: =C19 -> 760 | D22: =D19 -> 200 | E22: =E19 -> 0 | F22: =F19 -> 0 | G22: =G19 -> 0 | H22: =H19 -> 0 | I22: =I19 -> 0 | J22: =J19 -> 0 | ... AG22: =AG19 -> 0 | AH22: =SUM(C22:AF22) -> 1602
A23: 보호철판 / 50 | B23: 480 | C23: =C20 -> 0 | D23: =D20 -> 0 | E23: =E20 -> 0 | F23: =F20 -> 0 | G23: =G20 -> 0 | H23: =H20 -> 0 | I23: =I20 -> 0 | J23: =J20 -> 0 | ... AG23: =AG20 -> 0 | AH23: =SUM(C23:AF23) -> 447
A24: 볼트,너트,와샤 | B24: 9120 | C24: =SUM(C21:C23)*4 -> 4240 | D24: =SUM(D21:D23)*4 -> 4640 | E24: =SUM(E21:E23)*4 -> 3600 | F24: =SUM(F21:F23)*4 -> 0 | G24: =SUM(G21:G23)*4 -> 0 | H24: =SUM(H21:H23)*4 -> 0 | I24: =SUM(I21:I23)*4 -> 0 | J24: =SUM(J21:J23)*4 -> 3840 | ... AG24: =SUM(AG21:AG23)*4 -> 0 | AH24: =SUM(C24:AF24) -> 43628
A25: 한국파렛트 | B25: 9 | AH25: =SUM(C25:AF25) -> 0
A26: 화창파렛트 | AH26: =SUM(C26:AF26) -> 0
AH27: =SUM(C27:AF27) -> 0
AH28: =SUM(C28:AF28) -> 0
AH29: =SUM(C29:AF29) -> 0
A30: 시트(재단)100 | B30: 1443 | C30: 500 | E30: 1910 | O30: 2800 | P30: 1550 | R30: 1450 | AH30: =SUM(C30:AF30) -> 8210
A31: 시트(재단)75 | B31: 13 | C31: 1050 | P31: 1000 | AH31: =SUM(C31:AF31) -> 2050
A32: 시트(재단)50 | B32: 10 | P32: 850 | AH32: =SUM(C32:AF32) -> 850
A33: 시트(압출) - 재단수량 | C33: 36 | E33: 37 | O33: 70 | P33: 73 | R33: 115 | AH33: =SUM(C33:AF33) -> 331
O34: =SUM(O9:O33) -> 8858 | S34: =SUM(S9:S33) -> 0 | T34: =SUM(T9:T33) -> 0 | V34: =SUM(V9:V33) -> 6120 | X34: =SUM(X9:X33) -> 2682 | AB34: =SUM(AB9:AB33) -> 0 | AC34: =SUM(AC9:AC33) -> 0 | AE34: =SUM(AE9:AE33) -> 0 | AF34: =SUM(AF9:AF33) -> 0

Sheet 통합현황
B2: 2026년 07월 FN테크 제품현황
B3: 반제품, 완제품 현황 | L3: 시트 재고현황
B4: 타입/현황 | C4: 전월재고(반제품) | D4: 전월재고(완제품) | E4: 06월입고 | F4: 06월출고 | G4: 생산수량(완제품) | H4: 반제품 계 | I4: 완제품 계 | J4: 총 합계 | L4: 타입/현황 | M4: 전월재고 | N4: 생산수량 | O4: 재단시트재고 | P4: 압출시트재고
B5: 100(몸통) | C5: ='입고(2607)'!B9 -> 300 | D5: ='생산량(2607)'!B9 -> 600 | E5: ='입고(2607)'!AH9 -> 1800 | F5: ='출고(2607)'!AH9 -> 2700 | G5: ='생산량(2607)'!AH9 -> 2100 | H5: =(C5+E5)-G5 -> 0 | I5: =(D5+G5)-F5 -> 0 | J5: =I5+H5 -> 0 | L5: 100 | M5: ='생산량(2607)'!B30 -> 1443 | N5: ='생산량(2607)'!AH30 -> 8210 | O5: =(N5+M5)-SUM('생산량(2607)'!AH9:AH18) -> 795 | P5: ='입고(2607)'!AH33-'생산량(2607)'!AH33 -> 0 | Q5: 스티커동봉 | R5: 최진영차장출력
B6: 100(150H) | C6: ='입고(2607)'!B10 -> 0 | D6: ='생산량(2607)'!B10 -> 0 | E6: ='입고(2607)'!AH10 -> 0 | F6: ='출고(2607)'!AH10 -> 0 | G6: ='생산량(2607)'!AH10 -> 0 | H6: =(C6+E6)-G6 -> 0 | I6: =(D6+G6)-F6 -> 0 | J6: =I6+H6 -> 0
B7: 100(170H) | C7: ='입고(2607)'!B11 -> 0 | D7: ='생산량(2607)'!B11 -> 0 | E7: ='입고(2607)'!AH11 -> 0 | F7: ='출고(2607)'!AH11 -> 0 | G7: ='생산량(2607)'!AH11 -> 0 | H7: =(C7+E7)-G7 -> 0 | I7: =(D7+G7)-F7 -> 0 | J7: =I7+H7 -> 0
B8: 100(180H) | C8: ='입고(2607)'!B12 -> 0 | D8: ='생산량(2607)'!B12 -> 0 | E8: ='입고(2607)'!AH12 -> 0 | F8: ='출고(2607)'!AH12 -> 0 | G8: ='생산량(2607)'!AH12 -> 0 | H8: =(C8+E8)-G8 -> 0 | I8: =(D8+G8)-F8 -> 0 | J8: =I8+H8 -> 0
B9: 100(190H) | C9: ='입고(2607)'!B13 -> 0 | D9: ='생산량(2607)'!B13 -> 0 | E9: ='입고(2607)'!AH13 -> 0 | F9: ='출고(2607)'!AH13 -> 0 | G9: ='생산량(2607)'!AH13 -> 0 | H9: =(C9+E9)-G9 -> 0 | I9: =(D9+G9)-F9 -> 0 | J9: =I9+H9 -> 0
B10: 100(200H) | C10: ='입고(2607)'!B14 -> 0 | D10: ='생산량(2607)'!B14 -> 0 | E10: ='입고(2607)'!AH14 -> 0 | F10: ='출고(2607)'!AH14 -> 0 | G10: ='생산량(2607)'!AH14 -> 0 | H10: =(C10+E10)-G10 -> 0 | I10: =(D10+G10)-F10 -> 0 | J10: =I10+H10 -> 0
B11: 100(210H) | C11: ='입고(2607)'!B15 -> 0 | D11: ='생산량(2607)'!B15 -> 1200 | E11: ='입고(2607)'!AH15 -> 6758 | F11: ='출고(2607)'!AH15 -> 6278 | G11: ='생산량(2607)'!AH15 -> 6758 | H11: =(C11+E11)-G11 -> 0 | I11: =(D11+G11)-F11 -> 1680 | J11: =I11+H11 -> 1680 | L11: 75 | M11: ='생산량(2607)'!B31 -> 13 | N11: ='생산량(2607)'!AH31 -> 2050 | O11: =(N11+M11)-'생산량(2607)'!AH19 -> 461 | Q11: 스티커부착작업 | R11: 최진영차장출력
B12: 100(240H) | C12: ='입고(2607)'!B16 -> 0 | D12: ='생산량(2607)'!B16 -> 0 | E12: ='입고(2607)'!AH16 -> 0 | F12: ='출고(2607)'!AH16 -> 0 | G12: ='생산량(2607)'!AH16 -> 0 | H12: =(C12+E12)-G12 -> 0 | I12: =(D12+G12)-F12 -> 0 | J12: =I12+H12 -> 0
B13: 100(250H) | C13: ='입고(2607)'!B17 -> 0 | D13: ='생산량(2607)'!B17 -> 0 | E13: ='입고(2607)'!AH17 -> 0 | F13: ='출고(2607)'!AH17 -> 0 | G13: ='생산량(2607)'!AH17 -> 0 | H13: =(C13+E13)-G13 -> 0 | I13: =(D13+G13)-F13 -> 0 | J13: =I13+H13 -> 0
B14: 100(260H) | C14: ='입고(2607)'!B18 -> 0 | D14: ='생산량(2607)'!B18 -> 0 | E14: ='입고(2607)'!AH18 -> 0 | F14: ='출고(2607)'!AH18 -> 0 | G14: ='생산량(2607)'!AH18 -> 0 | H14: =(C14+E14)-G14 -> 0 | I14: =(D14+G14)-F14 -> 0 | J14: =I14+H14 -> 0 | L14: 50 | M14: ='생산량(2607)'!B32 -> 10 | N14: ='생산량(2607)'!AH32 -> 850 | O14: =(N14+M14)-'생산량(2607)'!AH20 -> 413 | Q14: 스티커동봉 | R14: 최진영차장출력
B15: 75 | C15: ='입고(2607)'!B19 -> 0 | D15: ='생산량(2607)'!B19 -> 0 | E15: ='입고(2607)'!AH19 -> 1602 | F15: ='출고(2607)'!AH19 -> 960 | G15: ='생산량(2607)'!AH19 -> 1602 | H15: =(C15+E15)-G15 -> 0 | I15: =(D15+G15)-F15 -> 642 | J15: =I15+H15 -> 642 | Q15: 스티커동봉 | R15: 최진영차장출력
B16: 50 | C16: ='입고(2607)'!B20 -> 0 | D16: ='생산량(2607)'!B20 -> 480 | E16: ='입고(2607)'!AH20 -> 447 | F16: ='출고(2607)'!AH20 -> 480 | G16: ='생산량(2607)'!AH20 -> 447 | H16: =(C16+E16)-G16 -> 0 | I16: =(D16+G16)-F16 -> 447 | J16: =I16+H16 -> 447 | Q16: 스티커동봉 | R16: 최진영차장출력
B18: 보호철판(100) | C18: ='입고(2607)'!B21 -> 759 | D18: ='생산량(2607)'!B21 -> 1800 | E18: ='입고(2607)'!AH21 -> 8760 | F18: =SUM(F5:F14) -> 8978 | G18: ='생산량(2607)'!AH21 -> 8858 | H18: =(C18+E18)-G18 -> 661 | I18: =SUM(I5:I14) -> 1680 | J18: =I18+H18 -> 2341 | Q18: 박스스티커동봉 | R18: 이윤호주임출력
B19: 보호철판(75) | C19: ='입고(2607)'!B22 -> 70 | D19: ='생산량(2607)'!B22 -> 0 | E19: ='입고(2607)'!AH22 -> 1602 | F19: ='출고(2607)'!AH22 -> 0 | G19: ='생산량(2607)'!AH22 -> 1602 | H19: =(C19+E19)-G19 -> 70 | I19: =I15 -> 642 | J19: =I19+H19 -> 712
B20: 보호철판(50) | C20: ='입고(2607)'!B23 -> 356 | D20: ='생산량(2607)'!B23 -> 480 | E20: ='입고(2607)'!AH23 -> 447 | F20: ='출고(2607)'!AH23 -> 0 | G20: ='생산량(2607)'!AH23 -> 447 | H20: =(C20+E20)-G20 -> 356 | I20: =I16 -> 447 | J20: =I20+H20 -> 803
B21: 볼트,너트,와샤 | C21: ='입고(2607)'!B24 -> 1300 | D21: ='생산량(2607)'!B24 -> 9120 | E21: ='입고(2607)'!AH24 -> 44500 | F21: ='출고(2607)'!AH24 -> 0 | G21: ='생산량(2607)'!AH24 -> 43628 | H21: =(C21+E21)-G21 -> 2172 | I21: =SUM(I18:I20)*4 -> 11076 | J21: =I21+H21 -> 13248
B22: 파렛트(한국,화창) | C22: ='입고(2607)'!B25 -> 9 | E22: ='입고(2607)'!AH25+'입고(2607)'!AH26 -> 37 | F22: ='출고(2607)'!AH25+'출고(2607)'!AH26 -> 38 | G22: ='생산량(2607)'!AH25 -> 0 | J22: =(C22+E22)-F22 -> 8
C24: 1BOX/1PALLET | D24: 출고수량 | E24: 출고LOT(07/20) | F24: 출고시트LOT | G24: 입고LOT(07/20) | H24: 사용시트LOT | I24: 수량 | J24: 생산LOT | L24: 스티커 | M24: 출력여부 | N24: 조립일정
B25: 100(몸통) | C25: 12EA | D25: 600(2P) | E25: 260713-FN-100(1299~1898) | F25: 260709-S01(1286~1400)115 | I25: =I5 -> 0 | L25: 스티커 O | M25: 부착중
C26: 300EA | E26: 260713U002/260713GI001 | F26: 260709-S02(1~485)485
B30: 100(150H) | C30: 12EA | I30: =I6 -> 0
C31: 300EA
B33: 100(170H) | C33: 12EA | I33: =I7 -> 0
C34: 300EA
B37: 100(180H) | C37: 12EA | I37: =I8-D37 -> 0
C38: 240EA
B39: 100(190H) | C39: 12EA | I39: =I9 -> 0
C40: 240EA
B41: 100(200H) | C41: 12EA | I41: =I10 -> 0 | L41: 스티커 O | M41: 부착중
C42: 240EA
B43: 100(210H) | C43: 12EA | D43: 1440(6P) | E43: 260715-FN-100(0001~1440) | F43: 260709-S02(486~1400)915 | G43: 260720U001/260720GI001 | H43: 260709-S03(526~1550)1025 | I43: =I11 -> 1680 | J43: 260720-FN-100(0001~1680) | L43: 스티커 O | M43: 부착 | N43: 재고
C44: 240EA | E44: 260715U001/260715GI001 | F44: 260709-S03(1~525)525 | H44: 260709-S05(1~655)655
L45: 스티커 O | M45: 부착중
B48: 100(240H) | C48: 12EA | I48: =I12-D48 -> 0
C49: 240EA
B50: 100(250H) | C50: 12EA | I50: =I13-D50 -> 0
C51: 240EA
...
