Workbook

Sheet 인덱스
A1: 차열재 재고관리 시스템 - 대시보드
A3: =CONCATENATE("작성일: ",TEXT(TODAY(),"yyyy-mm-dd")," | 총 규격: 17종 | 입고/출고 시트에서 거래 입력") -> 작성일: 2026-05-21 | 총 규격: 17종 | 입고/출고 시트에서 거래 입력
A5: =HYPERLINK("#입고!A1","🟢 입고 시트로 (LOT 자유입력)") -> 🟢 입고 시트로 (LOT 자유입력) | E5: =HYPERLINK("#출고!A1","🔴 출고 시트로 (LOT 드롭다운)") -> 🔴 출고 시트로 (LOT 드롭다운) | I5: =HYPERLINK("#LOT조회!A1","🟣 LOT조회") -> 🟣 LOT조회 | K5: =HYPERLINK("#마스터!A1","⚙ 마스터(초기재고)") -> ⚙ 마스터(초기재고)
A7: ■ 17개 규격 현재고 대시보드 | K7: ■ Quick LOT 잔량 조회
A8: 현재고 = 초기재고 + 총입고 - 총출고. 음수=빨강, 5개 이하=주황. 규격 클릭 시 해당 시트로. | K8: 규격+LOT 입력 → 즉시 잔량
A9: No | B9: 제품군 | C9: 규격코드 | D9: 규격(통합ID) | E9: 단위 | F9: 초기재고 | G9: 총 입고 | H9: 총 출고 | I9: 현재고 | K9: 규격 | M9: 총 입고 | N9: =SUMIFS(입고!$F$8:$F$1013,입고!$C$8:$C$1013,$L$9,입고!$E$8:$E$1013,$L$10) -> 0
A10: 1 | B10: =마스터!D4 -> 세라믹울 96K 국산 | C10: =마스터!E4 -> 252007320 | D10: =HYPERLINK("#'96K국산 25T × 200W × 7320L'!A1",마스터!M4) -> 96K국산 25T × 200W × 7320L | E10: =마스터!J4 -> 매 | F10: =마스터!K4 -> 0 | G10: =SUMIFS(입고!$F$8:$F$1013,입고!$C$8:$C$1013,마스터!M4) -> 0 | H10: =SUMIFS(출고!$F$8:$F$1013,출고!$C$8:$C$1013,마스터!M4) -> 0 | I10: =F10+G10-H10 -> 0 | K10: LOT번호 | M10: 총 출고 | N10: =SUMIFS(출고!$F$8:$F$1013,출고!$C$8:$C$1013,$L$9,출고!$E$8:$E$1013,$L$10) -> 0
A11: 2 | B11: =마스터!D5 -> 세라믹울 96K 국산 | C11: =마스터!E5 -> 253007320 | D11: =HYPERLINK("#'96K국산 25T × 300W × 7320L'!A1",마스터!M5) -> 96K국산 25T × 300W × 7320L | E11: =마스터!J5 -> 매 | F11: =마스터!K5 -> 0 | G11: =SUMIFS(입고!$F$8:$F$1013,입고!$C$8:$C$1013,마스터!M5) -> 34 | H11: =SUMIFS(출고!$F$8:$F$1013,출고!$C$8:$C$1013,마스터!M5) -> 5 | I11: =F11+G11-H11 -> 29 | M11: LOT 잔량 | N11: =IF(OR($L$9="",$L$10=""),"입력 필요",M9-M10) -> 입력 필요
A12: 3 | B12: =마스터!D6 -> 세라믹울 96K 국산 | C12: =마스터!E6 -> 386004800 | D12: =HYPERLINK("#'96K국산 38T × 600W × 4800L'!A1",마스터!M6) -> 96K국산 38T × 600W × 4800L | E12: =마스터!J6 -> 매 | F12: =마스터!K6 -> 0 | G12: =SUMIFS(입고!$F$8:$F$1013,입고!$C$8:$C$1013,마스터!M6) -> 55 | H12: =SUMIFS(출고!$F$8:$F$1013,출고!$C$8:$C$1013,마스터!M6) -> 0 | I12: =F12+G12-H12 -> 55
A13: 4 | B13: =마스터!D7 -> 세라믹울 96K 국산 | C13: =마스터!E7 -> 504003800 | D13: =HYPERLINK("#'96K국산 50T × 400W × 3800L'!A1",마스터!M7) -> 96K국산 50T × 400W × 3800L | E13: =마스터!J7 -> 매 | F13: =마스터!K7 -> 0 | G13: =SUMIFS(입고!$F$8:$F$1013,입고!$C$8:$C$1013,마스터!M7) -> 0 | H13: =SUMIFS(출고!$F$8:$F$1013,출고!$C$8:$C$1013,마스터!M7) -> 0 | I13: =F13+G13-H13 -> 0
A14: 5 | B14: =마스터!D8 -> 세라믹울 96K 국산 | C14: =마스터!E8 -> 506103600 | D14: =HYPERLINK("#'96K국산 50T × 610W × 3600L'!A1",마스터!M8) -> 96K국산 50T × 610W × 3600L | E14: =마스터!J8 -> 매 | F14: =마스터!K8 -> 0 | G14: =SUMIFS(입고!$F$8:$F$1013,입고!$C$8:$C$1013,마스터!M8) -> 0 | H14: =SUMIFS(출고!$F$8:$F$1013,출고!$C$8:$C$1013,마스터!M8) -> 0 | I14: =F14+G14-H14 -> 0
A15: 6 | B15: =마스터!D9 -> 세라믹울 96K 수입 | C15: =마스터!E9 -> 251507400 | D15: =HYPERLINK("#'96K수입 25T × 150W × 7400L'!A1",마스터!M9) -> 96K수입 25T × 150W × 7400L | E15: =마스터!J9 -> 매 | F15: =마스터!K9 -> 0 | G15: =SUMIFS(입고!$F$8:$F$1013,입고!$C$8:$C$1013,마스터!M9) -> 40 | H15: =SUMIFS(출고!$F$8:$F$1013,출고!$C$8:$C$1013,마스터!M9) -> 0 | I15: =F15+G15-H15 -> 40
A16: 7 | B16: =마스터!D10 -> 세라믹울 96K 수입 | C16: =마스터!E10 -> 381504800 | D16: =HYPERLINK("#'96K수입 38T × 150W × 4800L'!A1",마스터!M10) -> 96K수입 38T × 150W × 4800L | E16: =마스터!J10 -> 매 | F16: =마스터!K10 -> 0 | G16: =SUMIFS(입고!$F$8:$F$1013,입고!$C$8:$C$1013,마스터!M10) -> 40 | H16: =SUMIFS(출고!$F$8:$F$1013,출고!$C$8:$C$1013,마스터!M10) -> 0 | I16: =F16+G16-H16 -> 40
A17: 8 | B17: =마스터!D11 -> 세라믹울 96K 수입 | C17: =마스터!E11 -> 501503600 | D17: =HYPERLINK("#'96K수입 50T × 150W × 3600L'!A1",마스터!M11) -> 96K수입 50T × 150W × 3600L | E17: =마스터!J11 -> 매 | F17: =마스터!K11 -> 0 | G17: =SUMIFS(입고!$F$8:$F$1013,입고!$C$8:$C$1013,마스터!M11) -> 60 | H17: =SUMIFS(출고!$F$8:$F$1013,출고!$C$8:$C$1013,마스터!M11) -> 0 | I17: =F17+G17-H17 -> 60
A18: 9 | B18: =마스터!D12 -> 세라믹울 96K 수입 | C18: =마스터!E12 -> 504003600 | D18: =HYPERLINK("#'96K수입 50T × 400W × 3600L'!A1",마스터!M12) -> 96K수입 50T × 400W × 3600L | E18: =마스터!J12 -> 매 | F18: =마스터!K12 -> 0 | G18: =SUMIFS(입고!$F$8:$F$1013,입고!$C$8:$C$1013,마스터!M12) -> 65 | H18: =SUMIFS(출고!$F$8:$F$1013,출고!$C$8:$C$1013,마스터!M12) -> 0 | I18: =F18+G18-H18 -> 65
A19: 10 | B19: =마스터!D13 -> 세라믹울 96K 수입 | C19: =마스터!E13 -> 506003600 | D19: =HYPERLINK("#'96K수입 50T × 600W × 3600L'!A1",마스터!M13) -> 96K수입 50T × 600W × 3600L | E19: =마스터!J13 -> 매 | F19: =마스터!K13 -> 0 | G19: =SUMIFS(입고!$F$8:$F$1013,입고!$C$8:$C$1013,마스터!M13) -> 172 | H19: =SUMIFS(출고!$F$8:$F$1013,출고!$C$8:$C$1013,마스터!M13) -> 0 | I19: =F19+G19-H19 -> 172
A20: 11 | B20: =마스터!D14 -> 세라믹울 96K 수입 | C20: =마스터!E14 -> 5010003600 | D20: =HYPERLINK("#'96K수입 50T × 1000W × 3600L'!A1",마스터!M14) -> 96K수입 50T × 1000W × 3600L | E20: =마스터!J14 -> 매 | F20: =마스터!K14 -> 0 | G20: =SUMIFS(입고!$F$8:$F$1013,입고!$C$8:$C$1013,마스터!M14) -> 10 | H20: =SUMIFS(출고!$F$8:$F$1013,출고!$C$8:$C$1013,마스터!M14) -> 0 | I20: =F20+G20-H20 -> 10
A21: 12 | B21: =마스터!D15 -> 세라믹울 100K 수입 | C21: =마스터!E15 -> 251507400 | D21: =HYPERLINK("#'100K수입 25T × 150W × 7400L'!A1",마스터!M15) -> 100K수입 25T × 150W × 7400L | E21: =마스터!J15 -> 매 | F21: =마스터!K15 -> 0 | G21: =SUMIFS(입고!$F$8:$F$1013,입고!$C$8:$C$1013,마스터!M15) -> 0 | H21: =SUMIFS(출고!$F$8:$F$1013,출고!$C$8:$C$1013,마스터!M15) -> 0 | I21: =F21+G21-H21 -> 0
A22: 13 | B22: =마스터!D16 -> 세라믹울 100K 수입 | C22: =마스터!E16 -> 252007400 | D22: =HYPERLINK("#'100K수입 25T × 200W × 7400L'!A1",마스터!M16) -> 100K수입 25T × 200W × 7400L | E22: =마스터!J16 -> 매 | F22: =마스터!K16 -> 0 | G22: =SUMIFS(입고!$F$8:$F$1013,입고!$C$8:$C$1013,마스터!M16) -> 12 | H22: =SUMIFS(출고!$F$8:$F$1013,출고!$C$8:$C$1013,마스터!M16) -> 0 | I22: =F22+G22-H22 -> 12
A23: 14 | B23: =마스터!D17 -> 세라믹울 100K 수입 | C23: =마스터!E17 -> 253007400 | D23: =HYPERLINK("#'100K수입 25T × 300W × 7400L'!A1",마스터!M17) -> 100K수입 25T × 300W × 7400L | E23: =마스터!J17 -> 매 | F23: =마스터!K17 -> 0 | G23: =SUMIFS(입고!$F$8:$F$1013,입고!$C$8:$C$1013,마스터!M17) -> 270 | H23: =SUMIFS(출고!$F$8:$F$1013,출고!$C$8:$C$1013,마스터!M17) -> 0 | I23: =F23+G23-H23 -> 270
A24: 15 | B24: =마스터!D18 -> 세라믹울 100K 수입 | C24: =마스터!E18 -> 386004800 | D24: =HYPERLINK("#'100K수입 38T × 600W × 4800L'!A1",마스터!M18) -> 100K수입 38T × 600W × 4800L | E24: =마스터!J18 -> 매 | F24: =마스터!K18 -> 0 | G24: =SUMIFS(입고!$F$8:$F$1013,입고!$C$8:$C$1013,마스터!M18) -> 192 | H24: =SUMIFS(출고!$F$8:$F$1013,출고!$C$8:$C$1013,마스터!M18) -> 0 | I24: =F24+G24-H24 -> 192
A25: 16 | B25: =마스터!D19 -> 세라믹울 100K 수입 | C25: =마스터!E19 -> 506003600 | D25: =HYPERLINK("#'100K수입 50T × 600W × 3600L'!A1",마스터!M19) -> 100K수입 50T × 600W × 3600L | E25: =마스터!J19 -> 매 | F25: =마스터!K19 -> 0 | G25: =SUMIFS(입고!$F$8:$F$1013,입고!$C$8:$C$1013,마스터!M19) -> 0 | H25: =SUMIFS(출고!$F$8:$F$1013,출고!$C$8:$C$1013,마스터!M19) -> 0 | I25: =F25+G25-H25 -> 0
A26: 17 | B26: =마스터!D20 -> 세라믹울 128K 수입 | C26: =마스터!E20 -> 252007400 | D26: =HYPERLINK("#'128K수입 25T × 200W × 7400L'!A1",마스터!M20) -> 128K수입 25T × 200W × 7400L | E26: =마스터!J20 -> 매 | F26: =마스터!K20 -> 0 | G26: =SUMIFS(입고!$F$8:$F$1013,입고!$C$8:$C$1013,마스터!M20) -> 318 | H26: =SUMIFS(출고!$F$8:$F$1013,출고!$C$8:$C$1013,마스터!M20) -> 79 | I26: =F26+G26-H26 -> 239
A27: 합계 | F27: =SUM(F10:F26) -> 0 | G27: =SUM(G10:G26) -> 1268 | H27: =SUM(H10:H26) -> 84 | I27: =SUM(I10:I26) -> 1184

Sheet 입고
A1: 입고 거래 입력
A3: ① 일자 ② 규격(드롭다운) ③ LOT번호 직접입력(새 LOT) ④ 수량 ⑤ 거래처 ⑥ 비고
A4: =HYPERLINK("#인덱스!A1","◀ 인덱스") -> ◀ 인덱스 | D4: =HYPERLINK("#출고!A1","▶ 출고 시트로") -> ▶ 출고 시트로 | F4: 총 입고건수 | G4: =COUNTA(B8:B1013) -> 15 | K4: 오늘 날짜: | L4: =TODAY() -> 46163
F5: 총 입고수량 | G5: =SUM(F8:F1013) -> 1268 | K5: 단축키: | L5: Ctrl + ; (오늘)
A7: No | B7: 일자 | C7: 규격 | D7: 규격설명 | E7: LOT번호 | F7: 수량 | G7: 단위 | H7: 거래처 | I7: 비고
A8: =IF(B8="","",ROW()-7) -> 1 | B8: 45947 | C8: 96K국산 38T × 600W × 4800L | E8: R251017CW002 | F8: 55 | H8: (초기재고) | I8: 2026-02-12 기준 | AC8: =IF(AND(E8<>"",C8<>"",COUNTIFS($C$8:C8,C8,$E$8:E8,E8)=1),1,0) -> 1
A9: =IF(B9="","",ROW()-7) -> 2 | B9: 46031 | C9: 96K국산 25T × 300W × 7320L | E9: 260109CW002 | F9: 34 | H9: (초기재고) | I9: 2026-02-12 기준 | AC9: =IF(AND(E9<>"",C9<>"",COUNTIFS($C$8:C9,C9,$E$8:E9,E9)=1),1,0) -> 1
A10: =IF(B10="","",ROW()-7) -> 3 | B10: 46056 | C10: 100K수입 25T × 300W × 7400L | E10: 260203CW001 | F10: 270 | H10: (초기재고) | I10: 2026-02-12 기준 | AC10: =IF(AND(E10<>"",C10<>"",COUNTIFS($C$8:C10,C10,$E$8:E10,E10)=1),1,0) -> 1
A11: =IF(B11="","",ROW()-7) -> 4 | B11: 46056 | C11: 100K수입 38T × 600W × 4800L | E11: 260203CW004 | F11: 192 | H11: (초기재고) | I11: 2026-02-12 기준 | AC11: =IF(AND(E11<>"",C11<>"",COUNTIFS($C$8:C11,C11,$E$8:E11,E11)=1),1,0) -> 1
A12: =IF(B12="","",ROW()-7) -> 5 | B12: 46056 | C12: 128K수입 25T × 200W × 7400L | E12: 260203CW002 | F12: 3 | H12: (초기재고) | I12: 2026-02-12 기준 | AC12: =IF(AND(E12<>"",C12<>"",COUNTIFS($C$8:C12,C12,$E$8:E12,E12)=1),1,0) -> 1
A13: =IF(B13="","",ROW()-7) -> 6 | B13: 46056 | C13: 96K수입 25T × 150W × 7400L | E13: 260203CW003 | F13: 40 | H13: (초기재고) | I13: 2026-02-12 기준 | AC13: =IF(AND(E13<>"",C13<>"",COUNTIFS($C$8:C13,C13,$E$8:E13,E13)=1),1,0) -> 1
A14: =IF(B14="","",ROW()-7) -> 7 | B14: 46056 | C14: 96K수입 38T × 150W × 4800L | E14: 260203CW005 | F14: 40 | H14: (초기재고) | I14: 2026-02-12 기준 | AC14: =IF(AND(E14<>"",C14<>"",COUNTIFS($C$8:C14,C14,$E$8:E14,E14)=1),1,0) -> 1
A15: =IF(B15="","",ROW()-7) -> 8 | B15: 46056 | C15: 96K수입 50T × 1000W × 3600L | E15: 260203CW006 | F15: 10 | H15: (초기재고) | I15: 2026-02-12 기준 | AC15: =IF(AND(E15<>"",C15<>"",COUNTIFS($C$8:C15,C15,$E$8:E15,E15)=1),1,0) -> 1
A16: =IF(B16="","",ROW()-7) -> 9 | B16: 46056 | C16: 96K수입 50T × 150W × 3600L | E16: 260203CW008 | F16: 60 | H16: (초기재고) | I16: 2026-02-12 기준 | AC16: =IF(AND(E16<>"",C16<>"",COUNTIFS($C$8:C16,C16,$E$8:E16,E16)=1),1,0) -> 1
A17: =IF(B17="","",ROW()-7) -> 10 | B17: 46056 | C17: 96K수입 50T × 400W × 3600L | E17: 260203CW007 | F17: 50 | H17: (초기재고) | I17: 2026-02-12 기준 | AC17: =IF(AND(E17<>"",C17<>"",COUNTIFS($C$8:C17,C17,$E$8:E17,E17)=1),1,0) -> 1
A18: =IF(B18="","",ROW()-7) -> 11 | B18: 46056 | C18: 96K수입 50T × 400W × 3600L | E18: R260203CW007 | F18: 15 | H18: (초기재고) | I18: 2026-02-12 기준 | AC18: =IF(AND(E18<>"",C18<>"",COUNTIFS($C$8:C18,C18,$E$8:E18,E18)=1),1,0) -> 1
A19: =IF(B19="","",ROW()-7) -> 12 | B19: 46080 | C19: 100K수입 25T × 200W × 7400L | E19: 260227CW004 | F19: 12 | H19: (초기재고) | I19: 2026-02-12 기준 | AC19: =IF(AND(E19<>"",C19<>"",COUNTIFS($C$8:C19,C19,$E$8:E19,E19)=1),1,0) -> 1
... A22: =IF(B22="","",ROW()-7) -> 15 | B22: 46156 | C22: 96K수입 50T × 600W × 3600L | E22: 260514CW001 | F22: 74 | H22: (초기재고) | I22: 2026-02-12 기준 | AC22: =IF(AND(E22<>"",C22<>"",COUNTIFS($C$8:C22,C22,$E$8:E22,E22)=1),1,0) -> 1
A23: =IF(B23="","",ROW()-7) | AC23: =IF(AND(E23<>"",C23<>"",COUNTIFS($C$8:C23,C23,$E$8:E23,E23)=1),1,0) -> 0
A24: =IF(B24="","",ROW()-7) | AC24: =IF(AND(E24<>"",C24<>"",COUNTIFS($C$8:C24,C24,$E$8:E24,E24)=1),1,0) -> 0
A25: =IF(B25="","",ROW()-7) | AC25: =IF(AND(E25<>"",C25<>"",COUNTIFS($C$8:C25,C25,$E$8:E25,E25)=1),1,0) -> 0
A26: =IF(B26="","",ROW()-7) | AC26: =IF(AND(E26<>"",C26<>"",COUNTIFS($C$8:C26,C26,$E$8:E26,E26)=1),1,0) -> 0
A27: =IF(B27="","",ROW()-7) | AC27: =IF(AND(E27<>"",C27<>"",COUNTIFS($C$8:C27,C27,$E$8:E27,E27)=1),1,0) -> 0
A28: =IF(B28="","",ROW()-7) | AC28: =IF(AND(E28<>"",C28<>"",COUNTIFS($C$8:C28,C28,$E$8:E28,E28)=1),1,0) -> 0
A29: =IF(B29="","",ROW()-7) | AC29: =IF(AND(E29<>"",C29<>"",COUNTIFS($C$8:C29,C29,$E$8:E29,E29)=1),1,0) -> 0
A30: =IF(B30="","",ROW()-7) | AC30: =IF(AND(E30<>"",C30<>"",COUNTIFS($C$8:C30,C30,$E$8:E30,E30)=1),1,0) -> 0
A31: =IF(B31="","",ROW()-7) | AC31: =IF(AND(E31<>"",C31<>"",COUNTIFS($C$8:C31,C31,$E$8:E31,E31)=1),1,0) -> 0
A32: =IF(B32="","",ROW()-7) | AC32: =IF(AND(E32<>"",C32<>"",COUNTIFS($C$8:C32,C32,$E$8:E32,E32)=1),1,0) -> 0
A33: =IF(B33="","",ROW()-7) | AC33: =IF(AND(E33<>"",C33<>"",COUNTIFS($C$8:C33,C33,$E$8:E33,E33)=1),1,0) -> 0
A34: =IF(B34="","",ROW()-7) | AC34: =IF(AND(E34<>"",C34<>"",COUNTIFS($C$8:C34,C34,$E$8:E34,E34)=1),1,0) -> 0
... A49: =IF(B49="","",ROW()-7) | AC49: =IF(AND(E49<>"",C49<>"",COUNTIFS($C$8:C49,C49,$E$8:E49,E49)=1),1,0) -> 0
A50: =IF(B50="","",ROW()-7) | D50: =IFERROR(IF(C50="","",INDEX(마스터!$F$4:$F$20,MATCH(C50,마스터!$M$4:$M$20,0))),"") | G50: =IFERROR(IF(C50="","",INDEX(마스터!$J$4:$J$20,MATCH(C50,마스터!$M$4:$M$20,0))),"") | AC50: =IF(AND(E50<>"",C50<>"",COUNTIFS($C$8:C50,C50,$E$8:E50,E50)=1),1,0) -> 0
A51: =IF(B51="","",ROW()-7) | D51: =IFERROR(IF(C51="","",INDEX(마스터!$F$4:$F$20,MATCH(C51,마스터!$M$4:$M$20,0))),"") | G51: =IFERROR(IF(C51="","",INDEX(마스터!$J$4:$J$20,MATCH(C51,마스터!$M$4:$M$20,0))),"") | AC51: =IF(AND(E51<>"",C51<>"",COUNTIFS($C$8:C51,C51,$E$8:E51,E51)=1),1,0) -> 0
A52: =IF(B52="","",ROW()-7) | D52: =IFERROR(IF(C52="","",INDEX(마스터!$F$4:$F$20,MATCH(C52,마스터!$M$4:$M$20,0))),"") | G52: =IFERROR(IF(C52="","",INDEX(마스터!$J$4:$J$20,MATCH(C52,마스터!$M$4:$M$20,0))),"") | AC52: =IF(AND(E52<>"",C52<>"",COUNTIFS($C$8:C52,C52,$E$8:E52,E52)=1),1,0) -> 0
A53: =IF(B53="","",ROW()-7) | D53: =IFERROR(IF(C53="","",INDEX(마스터!$F$4:$F$20,MATCH(C53,마스터!$M$4:$M$20,0))),"") | G53: =IFERROR(IF(C53="","",INDEX(마스터!$J$4:$J$20,MATCH(C53,마스터!$M$4:$M$20,0))),"") | AC53: =IF(AND(E53<>"",C53<>"",COUNTIFS($C$8:C53,C53,$E$8:E53,E53)=1),1,0) -> 0
A54: =IF(B54="","",ROW()-7) | D54: =IFERROR(IF(C54="","",INDEX(마스터!$F$4:$F$20,MATCH(C54,마스터!$M$4:$M$20,0))),"") | G54: =IFERROR(IF(C54="","",INDEX(마스터!$J$4:$J$20,MATCH(C54,마스터!$M$4:$M$20,0))),"") | AC54: =IF(AND(E54<>"",C54<>"",COUNTIFS($C$8:C54,C54,$E$8:E54,E54)=1),1,0) -> 0
A55: =IF(B55="","",ROW()-7) | D55: =IFERROR(IF(C55="","",INDEX(마스터!$F$4:$F$20,MATCH(C55,마스터!$M$4:$M$20,0))),"") | G55: =IFERROR(IF(C55="","",INDEX(마스터!$J$4:$J$20,MATCH(C55,마스터!$M$4:$M$20,0))),"") | AC55: =IF(AND(E55<>"",C55<>"",COUNTIFS($C$8:C55,C55,$E$8:E55,E55)=1),1,0) -> 0
A56: =IF(B56="","",ROW()-7) | D56: =IFERROR(IF(C56="","",INDEX(마스터!$F$4:$F$20,MATCH(C56,마스터!$M$4:$M$20,0))),"") | G56: =IFERROR(IF(C56="","",INDEX(마스터!$J$4:$J$20,MATCH(C56,마스터!$M$4:$M$20,0))),"") | AC56: =IF(AND(E56<>"",C56<>"",COUNTIFS($C$8:C56,C56,$E$8:E56,E56)=1),1,0) -> 0
A57: =IF(B57="","",ROW()-7) | D57: =IFERROR(IF(C57="","",INDEX(마스터!$F$4:$F$20,MATCH(C57,마스터!$M$4:$M$20,0))),"") | G57: =IFERROR(IF(C57="","",INDEX(마스터!$J$4:$J$20,MATCH(C57,마스터!$M$4:$M$20,0))),"") | AC57: =IF(AND(E57<>"",C57<>"",COUNTIFS($C$8:C57,C57,$E$8:E57,E57)=1),1,0) -> 0
A58: =IF(B58="","",ROW()-7) | D58: =IFERROR(IF(C58="","",INDEX(마스터!$F$4:$F$20,MATCH(C58,마스터!$M$4:$M$20,0))),"") | G58: =IFERROR(IF(C58="","",INDEX(마스터!$J$4:$J$20,MATCH(C58,마스터!$M$4:$M$20,0))),"") | AC58: =IF(AND(E58<>"",C58<>"",COUNTIFS($C$8:C58,C58,$E$8:E58,E58)=1),1,0) -> 0
...

Sheet 출고
A1: 출고 거래 입력
A3: ① 일자 ② 규격(드롭다운) → ③ LOT(드롭다운, 그 규격의 LOT만) ④ 수량 ⑤ 현장 ⑥ 비고
A4: =HYPERLINK("#인덱스!A1","◀ 인덱스") -> ◀ 인덱스 | D4: =HYPERLINK("#입고!A1","▶ 입고 시트로") -> ▶ 입고 시트로 | F4: 총 출고건수 | G4: =COUNTA(B8:B1013) -> 5 | K4: 오늘 날짜: | L4: =TODAY() -> 46163
F5: 총 출고수량 | G5: =SUM(F8:F1013) -> 84 | K5: 단축키: | L5: Ctrl + ; (오늘)
A7: No | B7: 일자 | C7: 규격 | D7: 규격설명 | E7: LOT번호 | F7: 수량 | G7: 단위 | H7: 현장 | I7: 비고
A8: =IF(B8="","",ROW()-7) -> 1 | B8: 46160 | C8: 128K수입 25T × 200W × 7400L | D8: =IFERROR(IF(C8="","",INDEX(마스터!$F$4:$F$20,MATCH(C8,마스터!$M$4:$M$20,0))),"") -> 25T × 200W × 7400L | E8: 260203CW002 | F8: 3 | G8: =IFERROR(IF(C8="","",INDEX(마스터!$J$4:$J$20,MATCH(C8,마스터!$M$4:$M$20,0))),"") -> 매 | H8: 아산탐정자이
A9: =IF(B9="","",ROW()-7) -> 2 | B9: 46160 | C9: 128K수입 25T × 200W × 7400L | D9: =IFERROR(IF(C9="","",INDEX(마스터!$F$4:$F$20,MATCH(C9,마스터!$M$4:$M$20,0))),"") -> 25T × 200W × 7400L | E9: 260514CW002 | F9: 33 | G9: =IFERROR(IF(C9="","",INDEX(마스터!$J$4:$J$20,MATCH(C9,마스터!$M$4:$M$20,0))),"") -> 매 | H9: 아산탐정자이
A10: =IF(B10="","",ROW()-7) -> 3 | B10: 46161 | C10: 128K수입 25T × 200W × 7400L | D10: =IFERROR(IF(C10="","",INDEX(마스터!$F$4:$F$20,MATCH(C10,마스터!$M$4:$M$20,0))),"") -> 25T × 200W × 7400L | E10: 260514CW002 | F10: 30 | G10: =IFERROR(IF(C10="","",INDEX(마스터!$J$4:$J$20,MATCH(C10,마스터!$M$4:$M$20,0))),"") -> 매 | H10: 아산탐정자이
A11: =IF(B11="","",ROW()-7) -> 4 | B11: 46162 | C11: 128K수입 25T × 200W × 7400L | D11: =IFERROR(IF(C11="","",INDEX(마스터!$F$4:$F$20,MATCH(C11,마스터!$M$4:$M$20,0))),"") -> 25T × 200W × 7400L | E11: 260514CW002 | F11: 13 | G11: =IFERROR(IF(C11="","",INDEX(마스터!$J$4:$J$20,MATCH(C11,마스터!$M$4:$M$20,0))),"") -> 매 | H11: 아산탐정자이,조선대 감염병원
A12: =IF(B12="","",ROW()-7) -> 5 | B12: 46162 | C12: 96K국산 25T × 300W × 7320L | D12: =IFERROR(IF(C12="","",INDEX(마스터!$F$4:$F$20,MATCH(C12,마스터!$M$4:$M$20,0))),"") -> 25T × 300W × 7320L | E12: 260109CW002 | F12: 5 | G12: =IFERROR(IF(C12="","",INDEX(마스터!$J$4:$J$20,MATCH(C12,마스터!$M$4:$M$20,0))),"") -> 매 | H12: 조선대 감염병원
A13: =IF(B13="","",ROW()-7) | D13: =IFERROR(IF(C13="","",INDEX(마스터!$F$4:$F$20,MATCH(C13,마스터!$M$4:$M$20,0))),"") | G13: =IFERROR(IF(C13="","",INDEX(마스터!$J$4:$J$20,MATCH(C13,마스터!$M$4:$M$20,0))),"")
A14: =IF(B14="","",ROW()-7) | D14: =IFERROR(IF(C14="","",INDEX(마스터!$F$4:$F$20,MATCH(C14,마스터!$M$4:$M$20,0))),"") | G14: =IFERROR(IF(C14="","",INDEX(마스터!$J$4:$J$20,MATCH(C14,마스터!$M$4:$M$20,0))),"")
A15: =IF(B15="","",ROW()-7) | D15: =IFERROR(IF(C15="","",INDEX(마스터!$F$4:$F$20,MATCH(C15,마스터!$M$4:$M$20,0))),"") | G15: =IFERROR(IF(C15="","",INDEX(마스터!$J$4:$J$20,MATCH(C15,마스터!$M$4:$M$20,0))),"")
A16: =IF(B16="","",ROW()-7) | D16: =IFERROR(IF(C16="","",INDEX(마스터!$F$4:$F$20,MATCH(C16,마스터!$M$4:$M$20,0))),"") | G16: =IFERROR(IF(C16="","",INDEX(마스터!$J$4:$J$20,MATCH(C16,마스터!$M$4:$M$20,0))),"")
A17: =IF(B17="","",ROW()-7) | D17: =IFERROR(IF(C17="","",INDEX(마스터!$F$4:$F$20,MATCH(C17,마스터!$M$4:$M$20,0))),"") | G17: =IFERROR(IF(C17="","",INDEX(마스터!$J$4:$J$20,MATCH(C17,마스터!$M$4:$M$20,0))),"")
A18: =IF(B18="","",ROW()-7) | D18: =IFERROR(IF(C18="","",INDEX(마스터!$F$4:$F$20,MATCH(C18,마스터!$M$4:$M$20,0))),"") | G18: =IFERROR(IF(C18="","",INDEX(마스터!$J$4:$J$20,MATCH(C18,마스터!$M$4:$M$20,0))),"")
A19: =IF(B19="","",ROW()-7) | D19: =IFERROR(IF(C19="","",INDEX(마스터!$F$4:$F$20,MATCH(C19,마스터!$M$4:$M$20,0))),"") | G19: =IFERROR(IF(C19="","",INDEX(마스터!$J$4:$J$20,MATCH(C19,마스터!$M$4:$M$20,0))),"")
A20: =IF(B20="","",ROW()-7) | D20: =IFERROR(IF(C20="","",INDEX(마스터!$F$4:$F$20,MATCH(C20,마스터!$M$4:$M$20,0))),"") | G20: =IFERROR(IF(C20="","",INDEX(마스터!$J$4:$J$20,MATCH(C20,마스터!$M$4:$M$20,0))),"")
A21: =IF(B21="","",ROW()-7) | D21: =IFERROR(IF(C21="","",INDEX(마스터!$F$4:$F$20,MATCH(C21,마스터!$M$4:$M$20,0))),"") | G21: =IFERROR(IF(C21="","",INDEX(마스터!$J$4:$J$20,MATCH(C21,마스터!$M$4:$M$20,0))),"")
A22: =IF(B22="","",ROW()-7) | D22: =IFERROR(IF(C22="","",INDEX(마스터!$F$4:$F$20,MATCH(C22,마스터!$M$4:$M$20,0))),"") | G22: =IFERROR(IF(C22="","",INDEX(마스터!$J$4:$J$20,MATCH(C22,마스터!$M$4:$M$20,0))),"")
A23: =IF(B23="","",ROW()-7) | D23: =IFERROR(IF(C23="","",INDEX(마스터!$F$4:$F$20,MATCH(C23,마스터!$M$4:$M$20,0))),"") | G23: =IFERROR(IF(C23="","",INDEX(마스터!$J$4:$J$20,MATCH(C23,마스터!$M$4:$M$20,0))),"")
A24: =IF(B24="","",ROW()-7) | D24: =IFERROR(IF(C24="","",INDEX(마스터!$F$4:$F$20,MATCH(C24,마스터!$M$4:$M$20,0))),"") | G24: =IFERROR(IF(C24="","",INDEX(마스터!$J$4:$J$20,MATCH(C24,마스터!$M$4:$M$20,0))),"")
... A1013: =IF(B1013="","",ROW()-7) | D1013: =IFERROR(IF(C1013="","",INDEX(마스터!$F$4:$F$20,MATCH(C1013,마스터!$M$4:$M$20,0))),"") | G1013: =IFERROR(IF(C1013="","",INDEX(마스터!$J$4:$J$20,MATCH(C1013,마스터!$M$4:$M$20,0))),"")

Sheet LOT조회
A1: LOT조회 - 규격별 LOT 잔량 자동집계
A3: 규격을 선택하면 그 규격의 모든 LOT 잔량이 자동 표시됩니다. | H3: =HYPERLINK("#인덱스!A1","◀ 인덱스") -> ◀ 인덱스
A5: 규격(통합ID) | D5: 초기재고 | E5: =IFERROR(IF(B5="","",INDEX(마스터!$K$4:$K$20,MATCH(B5,마스터!$M$4:$M$20,0))),"") | F5: 총 출고 | G5: =IF(B5="","",SUMIFS(출고!$F$8:$F$1013,출고!$C$8:$C$1013,$B$5))
D6: 총 입고 | E6: =IF(B5="","",SUMIFS(입고!$F$8:$F$1013,입고!$C$8:$C$1013,$B$5)) | F6: 현재고 합계 | G6: =IF(B5="","",IFERROR(E5,0)+E6-G5)
A9: ■ 선택 규격의 LOT별 잔량
A10: No | B10: LOT 번호 | C10: 총 입고 | D10: 총 출고 | E10: LOT 잔량
A11: =IF(B11="","",ROW()-10) | B11: {=IFERROR(INDEX(입고!$E$8:$E$1013,SMALL(IF((입고!$C$8:$C$1013=$B$5)*(입고!$AC$8:$AC$1013=1),ROW(입고!$C$8:$C$1013)-7),1)),"")} | C11: =IF(B11="","",SUMIFS(입고!$F$8:$F$1013,입고!$C$8:$C$1013,$B$5,입고!$E$8:$E$1013,B11)) | D11: =IF(B11="","",SUMIFS(출고!$F$8:$F$1013,출고!$C$8:$C$1013,$B$5,출고!$E$8:$E$1013,B11)) | E11: =IF(B11="","",C11-D11)
A12: =IF(B12="","",ROW()-10) | B12: {=IFERROR(INDEX(입고!$E$8:$E$1013,SMALL(IF((입고!$C$8:$C$1013=$B$5)*(입고!$AC$8:$AC$1013=1),ROW(입고!$C$8:$C$1013)-7),2)),"")} | C12: =IF(B12="","",SUMIFS(입고!$F$8:$F$1013,입고!$C$8:$C$1013,$B$5,입고!$E$8:$E$1013,B12)) | D12: =IF(B12="","",SUMIFS(출고!$F$8:$F$1013,출고!$C$8:$C$1013,$B$5,출고!$E$8:$E$1013,B12)) | E12: =IF(B12="","",C12-D12)
A13: =IF(B13="","",ROW()-10) | B13: {=IFERROR(INDEX(입고!$E$8:$E$1013,SMALL(IF((입고!$C$8:$C$1013=$B$5)*(입고!$AC$8:$AC$1013=1),ROW(입고!$C$8:$C$1013)-7),3)),"")} | C13: =IF(B13="","",SUMIFS(입고!$F$8:$F$1013,입고!$C$8:$C$1013,$B$5,입고!$E$8:$E$1013,B13)) | D13: =IF(B13="","",SUMIFS(출고!$F$8:$F$1013,출고!$C$8:$C$1013,$B$5,출고!$E$8:$E$1013,B13)) | E13: =IF(B13="","",C13-D13)
A14: =IF(B14="","",ROW()-10) | B14: {=IFERROR(INDEX(입고!$E$8:$E$1013,SMALL(IF((입고!$C$8:$C$1013=$B$5)*(입고!$AC$8:$AC$1013=1),ROW(입고!$C$8:$C$1013)-7),4)),"")} | C14: =IF(B14="","",SUMIFS(입고!$F$8:$F$1013,입고!$C$8:$C$1013,$B$5,입고!$E$8:$E$1013,B14)) | D14: =IF(B14="","",SUMIFS(출고!$F$8:$F$1013,출고!$C$8:$C$1013,$B$5,출고!$E$8:$E$1013,B14)) | E14: =IF(B14="","",C14-D14)
A15: =IF(B15="","",ROW()-10) | B15: {=IFERROR(INDEX(입고!$E$8:$E$1013,SMALL(IF((입고!$C$8:$C$1013=$B$5)*(입고!$AC$8:$AC$1013=1),ROW(입고!$C$8:$C$1013)-7),5)),"")} | C15: =IF(B15="","",SUMIFS(입고!$F$8:$F$1013,입고!$C$8:$C$1013,$B$5,입고!$E$8:$E$1013,B15)) | D15: =IF(B15="","",SUMIFS(출고!$F$8:$F$1013,출고!$C$8:$C$1013,$B$5,출고!$E$8:$E$1013,B15)) | E15: =IF(B15="","",C15-D15)
A16: =IF(B16="","",ROW()-10) | B16: {=IFERROR(INDEX(입고!$E$8:$E$1013,SMALL(IF((입고!$C$8:$C$1013=$B$5)*(입고!$AC$8:$AC$1013=1),ROW(입고!$C$8:$C$1013)-7),6)),"")} | C16: =IF(B16="","",SUMIFS(입고!$F$8:$F$1013,입고!$C$8:$C$1013,$B$5,입고!$E$8:$E$1013,B16)) | D16: =IF(B16="","",SUMIFS(출고!$F$8:$F$1013,출고!$C$8:$C$1013,$B$5,출고!$E$8:$E$1013,B16)) | E16: =IF(B16="","",C16-D16)
A17: =IF(B17="","",ROW()-10) | B17: {=IFERROR(INDEX(입고!$E$8:$E$1013,SMALL(IF((입고!$C$8:$C$1013=$B$5)*(입고!$AC$8:$AC$1013=1),ROW(입고!$C$8:$C$1013)-7),7)),"")} | C17: =IF(B17="","",SUMIFS(입고!$F$8:$F$1013,입고!$C$8:$C$1013,$B$5,입고!$E$8:$E$1013,B17)) | D17: =IF(B17="","",SUMIFS(출고!$F$8:$F$1013,출고!$C$8:$C$1013,$B$5,출고!$E$8:$E$1013,B17)) | E17: =IF(B17="","",C17-D17)
A18: =IF(B18="","",ROW()-10) | B18: {=IFERROR(INDEX(입고!$E$8:$E$1013,SMALL(IF((입고!$C$8:$C$1013=$B$5)*(입고!$AC$8:$AC$1013=1),ROW(입고!$C$8:$C$1013)-7),8)),"")} | C18: =IF(B18="","",SUMIFS(입고!$F$8:$F$1013,입고!$C$8:$C$1013,$B$5,입고!$E$8:$E$1013,B18)) | D18: =IF(B18="","",SUMIFS(출고!$F$8:$F$1013,출고!$C$8:$C$1013,$B$5,출고!$E$8:$E$1013,B18)) | E18: =IF(B18="","",C18-D18)
A19: =IF(B19="","",ROW()-10) | B19: {=IFERROR(INDEX(입고!$E$8:$E$1013,SMALL(IF((입고!$C$8:$C$1013=$B$5)*(입고!$AC$8:$AC$1013=1),ROW(입고!$C$8:$C$1013)-7),9)),"")} | C19: =IF(B19="","",SUMIFS(입고!$F$8:$F$1013,입고!$C$8:$C$1013,$B$5,입고!$E$8:$E$1013,B19)) | D19: =IF(B19="","",SUMIFS(출고!$F$8:$F$1013,출고!$C$8:$C$1013,$B$5,출고!$E$8:$E$1013,B19)) | E19: =IF(B19="","",C19-D19)
A20: =IF(B20="","",ROW()-10) | B20: {=IFERROR(INDEX(입고!$E$8:$E$1013,SMALL(IF((입고!$C$8:$C$1013=$B$5)*(입고!$AC$8:$AC$1013=1),ROW(입고!$C$8:$C$1013)-7),10)),"")} | C20: =IF(B20="","",SUMIFS(입고!$F$8:$F$1013,입고!$C$8:$C$1013,$B$5,입고!$E$8:$E$1013,B20)) | D20: =IF(B20="","",SUMIFS(출고!$F$8:$F$1013,출고!$C$8:$C$1013,$B$5,출고!$E$8:$E$1013,B20)) | E20: =IF(B20="","",C20-D20)
A21: =IF(B21="","",ROW()-10) | B21: {=IFERROR(INDEX(입고!$E$8:$E$1013,SMALL(IF((입고!$C$8:$C$1013=$B$5)*(입고!$AC$8:$AC$1013=1),ROW(입고!$C$8:$C$1013)-7),11)),"")} | C21: =IF(B21="","",SUMIFS(입고!$F$8:$F$1013,입고!$C$8:$C$1013,$B$5,입고!$E$8:$E$1013,B21)) | D21: =IF(B21="","",SUMIFS(출고!$F$8:$F$1013,출고!$C$8:$C$1013,$B$5,출고!$E$8:$E$1013,B21)) | E21: =IF(B21="","",C21-D21)
A22: =IF(B22="","",ROW()-10) | B22: {=IFERROR(INDEX(입고!$E$8:$E$1013,SMALL(IF((입고!$C$8:$C$1013=$B$5)*(입고!$AC$8:$AC$1013=1),ROW(입고!$C$8:$C$1013)-7),12)),"")} | C22: =IF(B22="","",SUMIFS(입고!$F$8:$F$1013,입고!$C$8:$C$1013,$B$5,입고!$E$8:$E$1013,B22)) | D22: =IF(B22="","",SUMIFS(출고!$F$8:$F$1013,출고!$C$8:$C$1013,$B$5,출고!$E$8:$E$1013,B22)) | E22: =IF(B22="","",C22-D22)
A23: =IF(B23="","",ROW()-10) | B23: {=IFERROR(INDEX(입고!$E$8:$E$1013,SMALL(IF((입고!$C$8:$C$1013=$B$5)*(입고!$AC$8:$AC$1013=1),ROW(입고!$C$8:$C$1013)-7),13)),"")} | C23: =IF(B23="","",SUMIFS(입고!$F$8:$F$1013,입고!$C$8:$C$1013,$B$5,입고!$E$8:$E$1013,B23)) | D23: =IF(B23="","",SUMIFS(출고!$F$8:$F$1013,출고!$C$8:$C$1013,$B$5,출고!$E$8:$E$1013,B23)) | E23: =IF(B23="","",C23-D23)
A24: =IF(B24="","",ROW()-10) | B24: {=IFERROR(INDEX(입고!$E$8:$E$1013,SMALL(IF((입고!$C$8:$C$1013=$B$5)*(입고!$AC$8:$AC$1013=1),ROW(입고!$C$8:$C$1013)-7),14)),"")} | C24: =IF(B24="","",SUMIFS(입고!$F$8:$F$1013,입고!$C$8:$C$1013,$B$5,입고!$E$8:$E$1013,B24)) | D24: =IF(B24="","",SUMIFS(출고!$F$8:$F$1013,출고!$C$8:$C$1013,$B$5,출고!$E$8:$E$1013,B24)) | E24: =IF(B24="","",C24-D24)
A25: =IF(B25="","",ROW()-10) | B25: {=IFERROR(INDEX(입고!$E$8:$E$1013,SMALL(IF((입고!$C$8:$C$1013=$B$5)*(입고!$AC$8:$AC$1013=1),ROW(입고!$C$8:$C$1013)-7),15)),"")} | C25: =IF(B25="","",SUMIFS(입고!$F$8:$F$1013,입고!$C$8:$C$1013,$B$5,입고!$E$8:$E$1013,B25)) | D25: =IF(B25="","",SUMIFS(출고!$F$8:$F$1013,출고!$C$8:$C$1013,$B$5,출고!$E$8:$E$1013,B25)) | E25: =IF(B25="","",C25-D25)
A26: =IF(B26="","",ROW()-10) | B26: {=IFERROR(INDEX(입고!$E$8:$E$1013,SMALL(IF((입고!$C$8:$C$1013=$B$5)*(입고!$AC$8:$AC$1013=1),ROW(입고!$C$8:$C$1013)-7),16)),"")} | C26: =IF(B26="","",SUMIFS(입고!$F$8:$F$1013,입고!$C$8:$C$1013,$B$5,입고!$E$8:$E$1013,B26)) | D26: =IF(B26="","",SUMIFS(출고!$F$8:$F$1013,출고!$C$8:$C$1013,$B$5,출고!$E$8:$E$1013,B26)) | E26: =IF(B26="","",C26-D26)
A27: =IF(B27="","",ROW()-10) | B27: {=IFERROR(INDEX(입고!$E$8:$E$1013,SMALL(IF((입고!$C$8:$C$1013=$B$5)*(입고!$AC$8:$AC$1013=1),ROW(입고!$C$8:$C$1013)-7),17)),"")} | C27: =IF(B27="","",SUMIFS(입고!$F$8:$F$1013,입고!$C$8:$C$1013,$B$5,입고!$E$8:$E$1013,B27)) | D27: =IF(B27="","",SUMIFS(출고!$F$8:$F$1013,출고!$C$8:$C$1013,$B$5,출고!$E$8:$E$1013,B27)) | E27: =IF(B27="","",C27-D27)
A28: =IF(B28="","",ROW()-10) | B28: {=IFERROR(INDEX(입고!$E$8:$E$1013,SMALL(IF((입고!$C$8:$C$1013=$B$5)*(입고!$AC$8:$AC$1013=1),ROW(입고!$C$8:$C$1013)-7),18)),"")} | C28: =IF(B28="","",SUMIFS(입고!$F$8:$F$1013,입고!$C$8:$C$1013,$B$5,입고!$E$8:$E$1013,B28)) | D28: =IF(B28="","",SUMIFS(출고!$F$8:$F$1013,출고!$C$8:$C$1013,$B$5,출고!$E$8:$E$1013,B28)) | E28: =IF(B28="","",C28-D28)
A29: =IF(B29="","",ROW()-10) | B29: {=IFERROR(INDEX(입고!$E$8:$E$1013,SMALL(IF((입고!$C$8:$C$1013=$B$5)*(입고!$AC$8:$AC$1013=1),ROW(입고!$C$8:$C$1013)-7),19)),"")} | C29: =IF(B29="","",SUMIFS(입고!$F$8:$F$1013,입고!$C$8:$C$1013,$B$5,입고!$E$8:$E$1013,B29)) | D29: =IF(B29="","",SUMIFS(출고!$F$8:$F$1013,출고!$C$8:$C$1013,$B$5,출고!$E$8:$E$1013,B29)) | E29: =IF(B29="","",C29-D29)
A30: =IF(B30="","",ROW()-10) | B30: {=IFERROR(INDEX(입고!$E$8:$E$1013,SMALL(IF((입고!$C$8:$C$1013=$B$5)*(입고!$AC$8:$AC$1013=1),ROW(입고!$C$8:$C$1013)-7),20)),"")} | C30: =IF(B30="","",SUMIFS(입고!$F$8:$F$1013,입고!$C$8:$C$1013,$B$5,입고!$E$8:$E$1013,B30)) | D30: =IF(B30="","",SUMIFS(출고!$F$8:$F$1013,출고!$C$8:$C$1013,$B$5,출고!$E$8:$E$1013,B30)) | E30: =IF(B30="","",C30-D30)
A31: =IF(B31="","",ROW()-10) | B31: {=IFERROR(INDEX(입고!$E$8:$E$1013,SMALL(IF((입고!$C$8:$C$1013=$B$5)*(입고!$AC$8:$AC$1013=1),ROW(입고!$C$8:$C$1013)-7),21)),"")} | C31: =IF(B31="","",SUMIFS(입고!$F$8:$F$1013,입고!$C$8:$C$1013,$B$5,입고!$E$8:$E$1013,B31)) | D31: =IF(B31="","",SUMIFS(출고!$F$8:$F$1013,출고!$C$8:$C$1013,$B$5,출고!$E$8:$E$1013,B31)) | E31: =IF(B31="","",C31-D31)
A32: =IF(B32="","",ROW()-10) | B32: {=IFERROR(INDEX(입고!$E$8:$E$1013,SMALL(IF((입고!$C$8:$C$1013=$B$5)*(입고!$AC$8:$AC$1013=1),ROW(입고!$C$8:$C$1013)-7),22)),"")} | C32: =IF(B32="","",SUMIFS(입고!$F$8:$F$1013,입고!$C$8:$C$1013,$B$5,입고!$E$8:$E$1013,B32)) | D32: =IF(B32="","",SUMIFS(출고!$F$8:$F$1013,출고!$C$8:$C$1013,$B$5,출고!$E$8:$E$1013,B32)) | E32: =IF(B32="","",C32-D32)
A33: =IF(B33="","",ROW()-10) | B33: {=IFERROR(INDEX(입고!$E$8:$E$1013,SMALL(IF((입고!$C$8:$C$1013=$B$5)*(입고!$AC$8:$AC$1013=1),ROW(입고!$C$8:$C$1013)-7),23)),"")} | C33: =IF(B33="","",SUMIFS(입고!$F$8:$F$1013,입고!$C$8:$C$1013,$B$5,입고!$E$8:$E$1013,B33)) | D33: =IF(B33="","",SUMIFS(출고!$F$8:$F$1013,출고!$C$8:$C$1013,$B$5,출고!$E$8:$E$1013,B33)) | E33: =IF(B33="","",C33-D33)
A34: =IF(B34="","",ROW()-10) | B34: {=IFERROR(INDEX(입고!$E$8:$E$1013,SMALL(IF((입고!$C$8:$C$1013=$B$5)*(입고!$AC$8:$AC$1013=1),ROW(입고!$C$8:$C$1013)-7),24)),"")} | C34: =IF(B34="","",SUMIFS(입고!$F$8:$F$1013,입고!$C$8:$C$1013,$B$5,입고!$E$8:$E$1013,B34)) | D34: =IF(B34="","",SUMIFS(출고!$F$8:$F$1013,출고!$C$8:$C$1013,$B$5,출고!$E$8:$E$1013,B34)) | E34: =IF(B34="","",C34-D34)
A35: =IF(B35="","",ROW()-10) | B35: {=IFERROR(INDEX(입고!$E$8:$E$1013,SMALL(IF((입고!$C$8:$C$1013=$B$5)*(입고!$AC$8:$AC$1013=1),ROW(입고!$C$8:$C$1013)-7),25)),"")} | C35: =IF(B35="","",SUMIFS(입고!$F$8:$F$1013,입고!$C$8:$C$1013,$B$5,입고!$E$8:$E$1013,B35)) | D35: =IF(B35="","",SUMIFS(출고!$F$8:$F$1013,출고!$C$8:$C$1013,$B$5,출고!$E$8:$E$1013,B35)) | E35: =IF(B35="","",C35-D35)
A36: =IF(B36="","",ROW()-10) | B36: {=IFERROR(INDEX(입고!$E$8:$E$1013,SMALL(IF((입고!$C$8:$C$1013=$B$5)*(입고!$AC$8:$AC$1013=1),ROW(입고!$C$8:$C$1013)-7),26)),"")} | C36: =IF(B36="","",SUMIFS(입고!$F$8:$F$1013,입고!$C$8:$C$1013,$B$5,입고!$E$8:$E$1013,B36)) | D36: =IF(B36="","",SUMIFS(출고!$F$8:$F$1013,출고!$C$8:$C$1013,$B$5,출고!$E$8:$E$1013,B36)) | E36: =IF(B36="","",C36-D36)
A37: =IF(B37="","",ROW()-10) | B37: {=IFERROR(INDEX(입고!$E$8:$E$1013,SMALL(IF((입고!$C$8:$C$1013=$B$5)*(입고!$AC$8:$AC$1013=1),ROW(입고!$C$8:$C$1013)-7),27)),"")} | C37: =IF(B37="","",SUMIFS(입고!$F$8:$F$1013,입고!$C$8:$C$1013,$B$5,입고!$E$8:$E$1013,B37)) | D37: =IF(B37="","",SUMIFS(출고!$F$8:$F$1013,출고!$C$8:$C$1013,$B$5,출고!$E$8:$E$1013,B37)) | E37: =IF(B37="","",C37-D37)
A38: =IF(B38="","",ROW()-10) | B38: {=IFERROR(INDEX(입고!$E$8:$E$1013,SMALL(IF((입고!$C$8:$C$1013=$B$5)*(입고!$AC$8:$AC$1013=1),ROW(입고!$C$8:$C$1013)-7),28)),"")} | C38: =IF(B38="","",SUMIFS(입고!$F$8:$F$1013,입고!$C$8:$C$1013,$B$5,입고!$E$8:$E$1013,B38)) | D38: =IF(B38="","",SUMIFS(출고!$F$8:$F$1013,출고!$C$8:$C$1013,$B$5,출고!$E$8:$E$1013,B38)) | E38: =IF(B38="","",C38-D38)
A39: =IF(B39="","",ROW()-10) | B39: {=IFERROR(INDEX(입고!$E$8:$E$1013,SMALL(IF((입고!$C$8:$C$1013=$B$5)*(입고!$AC$8:$AC$1013=1),ROW(입고!$C$8:$C$1013)-7),29)),"")} | C39: =IF(B39="","",SUMIFS(입고!$F$8:$F$1013,입고!$C$8:$C$1013,$B$5,입고!$E$8:$E$1013,B39)) | D39: =IF(B39="","",SUMIFS(출고!$F$8:$F$1013,출고!$C$8:$C$1013,$B$5,출고!$E$8:$E$1013,B39)) | E39: =IF(B39="","",C39-D39)
A40: =IF(B40="","",ROW()-10) | B40: {=IFERROR(INDEX(입고!$E$8:$E$1013,SMALL(IF((입고!$C$8:$C$1013=$B$5)*(입고!$AC$8:$AC$1013=1),ROW(입고!$C$8:$C$1013)-7),30)),"")} | C40: =IF(B40="","",SUMIFS(입고!$F$8:$F$1013,입고!$C$8:$C$1013,$B$5,입고!$E$8:$E$1013,B40)) | D40: =IF(B40="","",SUMIFS(출고!$F$8:$F$1013,출고!$C$8:$C$1013,$B$5,출고!$E$8:$E$1013,B40)) | E40: =IF(B40="","",C40-D40)
A41: =IF(B41="","",ROW()-10) | B41: {=IFERROR(INDEX(입고!$E$8:$E$1013,SMALL(IF((입고!$C$8:$C$1013=$B$5)*(입고!$AC$8:$AC$1013=1),ROW(입고!$C$8:$C$1013)-7),31)),"")} | C41: =IF(B41="","",SUMIFS(입고!$F$8:$F$1013,입고!$C$8:$C$1013,$B$5,입고!$E$8:$E$1013,B41)) | D41: =IF(B41="","",SUMIFS(출고!$F$8:$F$1013,출고!$C$8:$C$1013,$B$5,출고!$E$8:$E$1013,B41)) | E41: =IF(B41="","",C41-D41)
A42: =IF(B42="","",ROW()-10) | B42: {=IFERROR(INDEX(입고!$E$8:$E$1013,SMALL(IF((입고!$C$8:$C$1013=$B$5)*(입고!$AC$8:$AC$1013=1),ROW(입고!$C$8:$C$1013)-7),32)),"")} | C42: =IF(B42="","",SUMIFS(입고!$F$8:$F$1013,입고!$C$8:$C$1013,$B$5,입고!$E$8:$E$1013,B42)) | D42: =IF(B42="","",SUMIFS(출고!$F$8:$F$1013,출고!$C$8:$C$1013,$B$5,출고!$E$8:$E$1013,B42)) | E42: =IF(B42="","",C42-D42)
A43: =IF(B43="","",ROW()-10) | B43: {=IFERROR(INDEX(입고!$E$8:$E$1013,SMALL(IF((입고!$C$8:$C$1013=$B$5)*(입고!$AC$8:$AC$1013=1),ROW(입고!$C$8:$C$1013)-7),33)),"")} | C43: =IF(B43="","",SUMIFS(입고!$F$8:$F$1013,입고!$C$8:$C$1013,$B$5,입고!$E$8:$E$1013,B43)) | D43: =IF(B43="","",SUMIFS(출고!$F$8:$F$1013,출고!$C$8:$C$1013,$B$5,출고!$E$8:$E$1013,B43)) | E43: =IF(B43="","",C43-D43)
A44: =IF(B44="","",ROW()-10) | B44: {=IFERROR(INDEX(입고!$E$8:$E$1013,SMALL(IF((입고!$C$8:$C$1013=$B$5)*(입고!$AC$8:$AC$1013=1),ROW(입고!$C$8:$C$1013)-7),34)),"")} | C44: =IF(B44="","",SUMIFS(입고!$F$8:$F$1013,입고!$C$8:$C$1013,$B$5,입고!$E$8:$E$1013,B44)) | D44: =IF(B44="","",SUMIFS(출고!$F$8:$F$1013,출고!$C$8:$C$1013,$B$5,출고!$E$8:$E$1013,B44)) | E44: =IF(B44="","",C44-D44)
...

Sheet 마스터
A1: 제품군 (참고용) | C1: 차열재 규격 마스터 (초기재고 K열에 직접 입력)
A2: 세라믹울 96K 국산 | P2: LOT 풀 (입고시트에서 자동 추출, 출고 드롭다운용)
A3: 세라믹울 96K 수입 | C3: No | D3: 제품군 | E3: 규격코드 | F3: 규격설명 | G3: 두께(T) | H3: 폭(W) | I3: 길이(L) | J3: 단위 | K3: 초기재고 | L3: 시트명 | M3: 통합규격ID | P3: 통합규격ID | Q3: LOT번호
A4: 세라믹울 100K 수입 | C4: 1 | D4: 세라믹울 96K 국산 | E4: 252007320 | F4: 25T × 200W × 7320L | G4: 25 | H4: 200 | I4: 7320 | J4: 매 | K4: 0 | L4: 96K국산 25T × 200W × 7320L | M4: 96K국산 25T × 200W × 7320L | P4: =IF(Q4="","",$M$4) | Q4: {=IFERROR(INDEX(입고!$E$8:$E$1013,SMALL(IF((입고!$AC$8:$AC$1013=1)*(입고!$C$8:$C$1013=$M$4),ROW(입고!$C$8:$C$1013)-7),1)),"")}
A5: 세라믹울 128K 수입 | C5: 2 | D5: 세라믹울 96K 국산 | E5: 253007320 | F5: 25T × 300W × 7320L | G5: 25 | H5: 300 | I5: 7320 | J5: 매 | K5: 0 | L5: 96K국산 25T × 300W × 7320L | M5: 96K국산 25T × 300W × 7320L | P5: =IF(Q5="","",$M$4) | Q5: {=IFERROR(INDEX(입고!$E$8:$E$1013,SMALL(IF((입고!$AC$8:$AC$1013=1)*(입고!$C$8:$C$1013=$M$4),ROW(입고!$C$8:$C$1013)-7),2)),"")}
C6: 3 | D6: 세라믹울 96K 국산 | E6: 386004800 | F6: 38T × 600W × 4800L | G6: 38 | H6: 600 | I6: 4800 | J6: 매 | K6: 0 | L6: 96K국산 38T × 600W × 4800L | M6: 96K국산 38T × 600W × 4800L | P6: =IF(Q6="","",$M$4) | Q6: {=IFERROR(INDEX(입고!$E$8:$E$1013,SMALL(IF((입고!$AC$8:$AC$1013=1)*(입고!$C$8:$C$1013=$M$4),ROW(입고!$C$8:$C$1013)-7),3)),"")}
C7: 4 | D7: 세라믹울 96K 국산 | E7: 504003800 | F7: 50T × 400W × 3800L | G7: 50 | H7: 400 | I7: 3800 | J7: 매 | K7: 0 | L7: 96K국산 50T × 400W × 3800L | M7: 96K국산 50T × 400W × 3800L | P7: =IF(Q7="","",$M$4) | Q7: {=IFERROR(INDEX(입고!$E$8:$E$1013,SMALL(IF((입고!$AC$8:$AC$1013=1)*(입고!$C$8:$C$1013=$M$4),ROW(입고!$C$8:$C$1013)-7),4)),"")}
C8: 5 | D8: 세라믹울 96K 국산 | E8: 506103600 | F8: 50T × 610W × 3600L | G8: 50 | H8: 610 | I8: 3600 | J8: 매 | K8: 0 | L8: 96K국산 50T × 610W × 3600L | M8: 96K국산 50T × 610W × 3600L | P8: =IF(Q8="","",$M$4) | Q8: {=IFERROR(INDEX(입고!$E$8:$E$1013,SMALL(IF((입고!$AC$8:$AC$1013=1)*(입고!$C$8:$C$1013=$M$4),ROW(입고!$C$8:$C$1013)-7),5)),"")}
C9: 6 | D9: 세라믹울 96K 수입 | E9: 251507400 | F9: 25T × 150W × 7400L | G9: 25 | H9: 150 | I9: 7400 | J9: 매 | K9: 0 | L9: 96K수입 25T × 150W × 7400L | M9: 96K수입 25T × 150W × 7400L | P9: =IF(Q9="","",$M$4) | Q9: {=IFERROR(INDEX(입고!$E$8:$E$1013,SMALL(IF((입고!$AC$8:$AC$1013=1)*(입고!$C$8:$C$1013=$M$4),ROW(입고!$C$8:$C$1013)-7),6)),"")}
C10: 7 | D10: 세라믹울 96K 수입 | E10: 381504800 | F10: 38T × 150W × 4800L | G10: 38 | H10: 150 | I10: 4800 | J10: 매 | K10: 0 | L10: 96K수입 38T × 150W × 4800L | M10: 96K수입 38T × 150W × 4800L | P10: =IF(Q10="","",$M$4) | Q10: {=IFERROR(INDEX(입고!$E$8:$E$1013,SMALL(IF((입고!$AC$8:$AC$1013=1)*(입고!$C$8:$C$1013=$M$4),ROW(입고!$C$8:$C$1013)-7),7)),"")}
C11: 8 | D11: 세라믹울 96K 수입 | E11: 501503600 | F11: 50T × 150W × 3600L | G11: 50 | H11: 150 | I11: 3600 | J11: 매 | K11: 0 | L11: 96K수입 50T × 150W × 3600L | M11: 96K수입 50T × 150W × 3600L | P11: =IF(Q11="","",$M$4) | Q11: {=IFERROR(INDEX(입고!$E$8:$E$1013,SMALL(IF((입고!$AC$8:$AC$1013=1)*(입고!$C$8:$C$1013=$M$4),ROW(입고!$C$8:$C$1013)-7),8)),"")}
C12: 9 | D12: 세라믹울 96K 수입 | E12: 504003600 | F12: 50T × 400W × 3600L | G12: 50 | H12: 400 | I12: 3600 | J12: 매 | K12: 0 | L12: 96K수입 50T × 400W × 3600L | M12: 96K수입 50T × 400W × 3600L | P12: =IF(Q12="","",$M$4) | Q12: {=IFERROR(INDEX(입고!$E$8:$E$1013,SMALL(IF((입고!$AC$8:$AC$1013=1)*(입고!$C$8:$C$1013=$M$4),ROW(입고!$C$8:$C$1013)-7),9)),"")}
C13: 10 | D13: 세라믹울 96K 수입 | E13: 506003600 | F13: 50T × 600W × 3600L | G13: 50 | H13: 600 | I13: 3600 | J13: 매 | K13: 0 | L13: 96K수입 50T × 600W × 3600L | M13: 96K수입 50T × 600W × 3600L | P13: =IF(Q13="","",$M$4) | Q13: {=IFERROR(INDEX(입고!$E$8:$E$1013,SMALL(IF((입고!$AC$8:$AC$1013=1)*(입고!$C$8:$C$1013=$M$4),ROW(입고!$C$8:$C$1013)-7),10)),"")}
C14: 11 | D14: 세라믹울 96K 수입 | E14: 5010003600 | F14: 50T × 1000W × 3600L | G14: 50 | H14: 1000 | I14: 3600 | J14: 매 | K14: 0 | L14: 96K수입 50T × 1000W × 3600L | M14: 96K수입 50T × 1000W × 3600L | P14: =IF(Q14="","",$M$5) -> 96K국산 25T × 300W × 7320L | Q14: {=IFERROR(INDEX(입고!$E$8:$E$1013,SMALL(IF((입고!$AC$8:$AC$1013=1)*(입고!$C$8:$C$1013=$M$5),ROW(입고!$C$8:$C$1013)-7),1)),"")} -> 260109CW002
C15: 12 | D15: 세라믹울 100K 수입 | E15: 251507400 | F15: 25T × 150W × 7400L | G15: 25 | H15: 150 | I15: 7400 | J15: 매 | K15: 0 | L15: 100K수입 25T × 150W × 7400L | M15: 100K수입 25T × 150W × 7400L | P15: =IF(Q15="","",$M$5) | Q15: {=IFERROR(INDEX(입고!$E$8:$E$1013,SMALL(IF((입고!$AC$8:$AC$1013=1)*(입고!$C$8:$C$1013=$M$5),ROW(입고!$C$8:$C$1013)-7),2)),"")}
C16: 13 | D16: 세라믹울 100K 수입 | E16: 252007400 | F16: 25T × 200W × 7400L | G16: 25 | H16: 200 | I16: 7400 | J16: 매 | K16: 0 | L16: 100K수입 25T × 200W × 7400L | M16: 100K수입 25T × 200W × 7400L | P16: =IF(Q16="","",$M$5) | Q16: {=IFERROR(INDEX(입고!$E$8:$E$1013,SMALL(IF((입고!$AC$8:$AC$1013=1)*(입고!$C$8:$C$1013=$M$5),ROW(입고!$C$8:$C$1013)-7),3)),"")}
C17: 14 | D17: 세라믹울 100K 수입 | E17: 253007400 | F17: 25T × 300W × 7400L | G17: 25 | H17: 300 | I17: 7400 | J17: 매 | K17: 0 | L17: 100K수입 25T × 300W × 7400L | M17: 100K수입 25T × 300W × 7400L | P17: =IF(Q17="","",$M$5) | Q17: {=IFERROR(INDEX(입고!$E$8:$E$1013,SMALL(IF((입고!$AC$8:$AC$1013=1)*(입고!$C$8:$C$1013=$M$5),ROW(입고!$C$8:$C$1013)-7),4)),"")}
C18: 15 | D18: 세라믹울 100K 수입 | E18: 386004800 | F18: 38T × 600W × 4800L | G18: 38 | H18: 600 | I18: 4800 | J18: 매 | K18: 0 | L18: 100K수입 38T × 600W × 4800L | M18: 100K수입 38T × 600W × 4800L | P18: =IF(Q18="","",$M$5) | Q18: {=IFERROR(INDEX(입고!$E$8:$E$1013,SMALL(IF((입고!$AC$8:$AC$1013=1)*(입고!$C$8:$C$1013=$M$5),ROW(입고!$C$8:$C$1013)-7),5)),"")}
C19: 16 | D19: 세라믹울 100K 수입 | E19: 506003600 | F19: 50T × 600W × 3600L | G19: 50 | H19: 600 | I19: 3600 | J19: 매 | K19: 0 | L19: 100K수입 50T × 600W × 3600L | M19: 100K수입 50T × 600W × 3600L | P19: =IF(Q19="","",$M$5) | Q19: {=IFERROR(INDEX(입고!$E$8:$E$1013,SMALL(IF((입고!$AC$8:$AC$1013=1)*(입고!$C$8:$C$1013=$M$5),ROW(입고!$C$8:$C$1013)-7),6)),"")}
C20: 17 | D20: 세라믹울 128K 수입 | E20: 252007400 | F20: 25T × 200W × 7400L | G20: 25 | H20: 200 | I20: 7400 | J20: 매 | K20: 0 | L20: 128K수입 25T × 200W × 7400L | M20: 128K수입 25T × 200W × 7400L | P20: =IF(Q20="","",$M$5) | Q20: {=IFERROR(INDEX(입고!$E$8:$E$1013,SMALL(IF((입고!$AC$8:$AC$1013=1)*(입고!$C$8:$C$1013=$M$5),ROW(입고!$C$8:$C$1013)-7),7)),"")}
P21: =IF(Q21="","",$M$5) | Q21: {=IFERROR(INDEX(입고!$E$8:$E$1013,SMALL(IF((입고!$AC$8:$AC$1013=1)*(입고!$C$8:$C$1013=$M$5),ROW(입고!$C$8:$C$1013)-7),8)),"")}
C22: ※ K열에 초기재고 입력 → 모든 시트 자동 반영 | P22: =IF(Q22="","",$M$5) | Q22: {=IFERROR(INDEX(입고!$E$8:$E$1013,SMALL(IF((입고!$AC$8:$AC$1013=1)*(입고!$C$8:$C$1013=$M$5),ROW(입고!$C$8:$C$1013)-7),9)),"")}
P23: =IF(Q23="","",$M$5) | Q23: {=IFERROR(INDEX(입고!$E$8:$E$1013,SMALL(IF((입고!$AC$8:$AC$1013=1)*(입고!$C$8:$C$1013=$M$5),ROW(입고!$C$8:$C$1013)-7),10)),"")}
P24: =IF(Q24="","",$M$6) -> 96K국산 38T × 600W × 4800L | Q24: {=IFERROR(INDEX(입고!$E$8:$E$1013,SMALL(IF((입고!$AC$8:$AC$1013=1)*(입고!$C$8:$C$1013=$M$6),ROW(입고!$C$8:$C$1013)-7),1)),"")} -> R251017CW002
P25: =IF(Q25="","",$M$6) | Q25: {=IFERROR(INDEX(입고!$E$8:$E$1013,SMALL(IF((입고!$AC$8:$AC$1013=1)*(입고!$C$8:$C$1013=$M$6),ROW(입고!$C$8:$C$1013)-7),2)),"")}
P26: =IF(Q26="","",$M$6) | Q26: {=IFERROR(INDEX(입고!$E$8:$E$1013,SMALL(IF((입고!$AC$8:$AC$1013=1)*(입고!$C$8:$C$1013=$M$6),ROW(입고!$C$8:$C$1013)-7),3)),"")}
P27: =IF(Q27="","",$M$6) | Q27: {=IFERROR(INDEX(입고!$E$8:$E$1013,SMALL(IF((입고!$AC$8:$AC$1013=1)*(입고!$C$8:$C$1013=$M$6),ROW(입고!$C$8:$C$1013)-7),4)),"")}
P28: =IF(Q28="","",$M$6) | Q28: {=IFERROR(INDEX(입고!$E$8:$E$1013,SMALL(IF((입고!$AC$8:$AC$1013=1)*(입고!$C$8:$C$1013=$M$6),ROW(입고!$C$8:$C$1013)-7),5)),"")}
P29: =IF(Q29="","",$M$6) | Q29: {=IFERROR(INDEX(입고!$E$8:$E$1013,SMALL(IF((입고!$AC$8:$AC$1013=1)*(입고!$C$8:$C$1013=$M$6),ROW(입고!$C$8:$C$1013)-7),6)),"")}
P30: =IF(Q30="","",$M$6) | Q30: {=IFERROR(INDEX(입고!$E$8:$E$1013,SMALL(IF((입고!$AC$8:$AC$1013=1)*(입고!$C$8:$C$1013=$M$6),ROW(입고!$C$8:$C$1013)-7),7)),"")}
P31: =IF(Q31="","",$M$6) | Q31: {=IFERROR(INDEX(입고!$E$8:$E$1013,SMALL(IF((입고!$AC$8:$AC$1013=1)*(입고!$C$8:$C$1013=$M$6),ROW(입고!$C$8:$C$1013)-7),8)),"")}
P32: =IF(Q32="","",$M$6) | Q32: {=IFERROR(INDEX(입고!$E$8:$E$1013,SMALL(IF((입고!$AC$8:$AC$1013=1)*(입고!$C$8:$C$1013=$M$6),ROW(입고!$C$8:$C$1013)-7),9)),"")}
P33: =IF(Q33="","",$M$6) | Q33: {=IFERROR(INDEX(입고!$E$8:$E$1013,SMALL(IF((입고!$AC$8:$AC$1013=1)*(입고!$C$8:$C$1013=$M$6),ROW(입고!$C$8:$C$1013)-7),10)),"")}
P34: =IF(Q34="","",$M$7) | Q34: {=IFERROR(INDEX(입고!$E$8:$E$1013,SMALL(IF((입고!$AC$8:$AC$1013=1)*(입고!$C$8:$C$1013=$M$7),ROW(입고!$C$8:$C$1013)-7),1)),"")}
P35: =IF(Q35="","",$M$7) | Q35: {=IFERROR(INDEX(입고!$E$8:$E$1013,SMALL(IF((입고!$AC$8:$AC$1013=1)*(입고!$C$8:$C$1013=$M$7),ROW(입고!$C$8:$C$1013)-7),2)),"")}
P36: =IF(Q36="","",$M$7) | Q36: {=IFERROR(INDEX(입고!$E$8:$E$1013,SMALL(IF((입고!$AC$8:$AC$1013=1)*(입고!$C$8:$C$1013=$M$7),ROW(입고!$C$8:$C$1013)-7),3)),"")}
P37: =IF(Q37="","",$M$7) | Q37: {=IFERROR(INDEX(입고!$E$8:$E$1013,SMALL(IF((입고!$AC$8:$AC$1013=1)*(입고!$C$8:$C$1013=$M$7),ROW(입고!$C$8:$C$1013)-7),4)),"")}
P38: =IF(Q38="","",$M$7) | Q38: {=IFERROR(INDEX(입고!$E$8:$E$1013,SMALL(IF((입고!$AC$8:$AC$1013=1)*(입고!$C$8:$C$1013=$M$7),ROW(입고!$C$8:$C$1013)-7),5)),"")}
P39: =IF(Q39="","",$M$7) | Q39: {=IFERROR(INDEX(입고!$E$8:$E$1013,SMALL(IF((입고!$AC$8:$AC$1013=1)*(입고!$C$8:$C$1013=$M$7),ROW(입고!$C$8:$C$1013)-7),6)),"")}
P40: =IF(Q40="","",$M$7) | Q40: {=IFERROR(INDEX(입고!$E$8:$E$1013,SMALL(IF((입고!$AC$8:$AC$1013=1)*(입고!$C$8:$C$1013=$M$7),ROW(입고!$C$8:$C$1013)-7),7)),"")}
...

Sheet 96K국산 25T × 200W × 7320L
A1: =CONCATENATE("[01] ", 마스터!D4, " | ", 마스터!F4) -> [01] 세라믹울 96K 국산 | 25T × 200W × 7320L
I3: =HYPERLINK("#인덱스!A1","◀ 인덱스") -> ◀ 인덱스
A4: 제품군 | B4: =마스터!D4 -> 세라믹울 96K 국산 | D4: 총 입고 | E4: =SUMIFS(입고!$F$8:$F$1013,입고!$C$8:$C$1013,마스터!$M$4) -> 0
A5: 규격코드 | B5: =마스터!E4 -> 252007320 | D5: 총 출고 | E5: =SUMIFS(출고!$F$8:$F$1013,출고!$C$8:$C$1013,마스터!$M$4) -> 0
A6: 규격설명 | B6: =마스터!F4 -> 25T × 200W × 7320L | D6: 사용량 합계 | E6: =E5 -> 0
A7: 통합규격ID | B7: =마스터!M4 -> 96K국산 25T × 200W × 7320L | D7: 현재고 | E7: =마스터!$K$4+E4-E5 -> 0
A8: 초기재고 | B8: =마스터!K4 -> 0 | D8: 최근거래일 | E8: {=IFERROR(MAX(MAX(IF(입고!$C$8:$C$1013=마스터!$M$4,입고!$B$8:$B$1013)),MAX(IF(출고!$C$8:$C$1013=마스터!$M$4,출고!$B$8:$B$1013))),"-")} -> 0
A10: ■ 입고 이력 (일자, LOT, 수량, 거래처, 비고, 누적입고)
A11: No | B11: 일자 | C11: LOT 번호 | D11: 수량 | E11: 거래처 | F11: 비고 | G11: 누적입고
A12: =IF(B12="","",ROW()-11) | B12: {=IFERROR(INDEX(입고!$B$8:$B$1013,SMALL(IF(입고!$C$8:$C$1013=마스터!$M$4,ROW(입고!$C$8:$C$1013)-7),1)),"")} | C12: {=IFERROR(INDEX(입고!$E$8:$E$1013,SMALL(IF(입고!$C$8:$C$1013=마스터!$M$4,ROW(입고!$C$8:$C$1013)-7),1)),"")} | D12: {=IFERROR(INDEX(입고!$F$8:$F$1013,SMALL(IF(입고!$C$8:$C$1013=마스터!$M$4,ROW(입고!$C$8:$C$1013)-7),1)),"")} | E12: {=IFERROR(INDEX(입고!$H$8:$H$1013,SMALL(IF(입고!$C$8:$C$1013=마스터!$M$4,ROW(입고!$C$8:$C$1013)-7),1)),"")} | F12: {=IFERROR(INDEX(입고!$I$8:$I$1013,SMALL(IF(입고!$C$8:$C$1013=마스터!$M$4,ROW(입고!$C$8:$C$1013)-7),1)),"")} | G12: =IF(B12="","",IFERROR(D12,0))
A13: =IF(B13="","",ROW()-11) | B13: {=IFERROR(INDEX(입고!$B$8:$B$1013,SMALL(IF(입고!$C$8:$C$1013=마스터!$M$4,ROW(입고!$C$8:$C$1013)-7),2)),"")} | C13: {=IFERROR(INDEX(입고!$E$8:$E$1013,SMALL(IF(입고!$C$8:$C$1013=마스터!$M$4,ROW(입고!$C$8:$C$1013)-7),2)),"")} | D13: {=IFERROR(INDEX(입고!$F$8:$F$1013,SMALL(IF(입고!$C$8:$C$1013=마스터!$M$4,ROW(입고!$C$8:$C$1013)-7),2)),"")} | E13: {=IFERROR(INDEX(입고!$H$8:$H$1013,SMALL(IF(입고!$C$8:$C$1013=마스터!$M$4,ROW(입고!$C$8:$C$1013)-7),2)),"")} | F13: {=IFERROR(INDEX(입고!$I$8:$I$1013,SMALL(IF(입고!$C$8:$C$1013=마스터!$M$4,ROW(입고!$C$8:$C$1013)-7),2)),"")} | G13: =IF(B13="","",IFERROR(G12,0)+IFERROR(D13,0))
A14: =IF(B14="","",ROW()-11) | B14: {=IFERROR(INDEX(입고!$B$8:$B$1013,SMALL(IF(입고!$C$8:$C$1013=마스터!$M$4,ROW(입고!$C$8:$C$1013)-7),3)),"")} | C14: {=IFERROR(INDEX(입고!$E$8:$E$1013,SMALL(IF(입고!$C$8:$C$1013=마스터!$M$4,ROW(입고!$C$8:$C$1013)-7),3)),"")} | D14: {=IFERROR(INDEX(입고!$F$8:$F$1013,SMALL(IF(입고!$C$8:$C$1013=마스터!$M$4,ROW(입고!$C$8:$C$1013)-7),3)),"")} | E14: {=IFERROR(INDEX(입고!$H$8:$H$1013,SMALL(IF(입고!$C$8:$C$1013=마스터!$M$4,ROW(입고!$C$8:$C$1013)-7),3)),"")} | F14: {=IFERROR(INDEX(입고!$I$8:$I$1013,SMALL(IF(입고!$C$8:$C$1013=마스터!$M$4,ROW(입고!$C$8:$C$1013)-7),3)),"")} | G14: =IF(B14="","",IFERROR(G13,0)+IFERROR(D14,0))
A15: =IF(B15="","",ROW()-11) | B15: {=IFERROR(INDEX(입고!$B$8:$B$1013,SMALL(IF(입고!$C$8:$C$1013=마스터!$M$4,ROW(입고!$C$8:$C$1013)-7),4)),"")} | C15: {=IFERROR(INDEX(입고!$E$8:$E$1013,SMALL(IF(입고!$C$8:$C$1013=마스터!$M$4,ROW(입고!$C$8:$C$1013)-7),4)),"")} | D15: {=IFERROR(INDEX(입고!$F$8:$F$1013,SMALL(IF(입고!$C$8:$C$1013=마스터!$M$4,ROW(입고!$C$8:$C$1013)-7),4)),"")} | E15: {=IFERROR(INDEX(입고!$H$8:$H$1013,SMALL(IF(입고!$C$8:$C$1013=마스터!$M$4,ROW(입고!$C$8:$C$1013)-7),4)),"")} | F15: {=IFERROR(INDEX(입고!$I$8:$I$1013,SMALL(IF(입고!$C$8:$C$1013=마스터!$M$4,ROW(입고!$C$8:$C$1013)-7),4)),"")} | G15: =IF(B15="","",IFERROR(G14,0)+IFERROR(D15,0))
A16: =IF(B16="","",ROW()-11) | B16: {=IFERROR(INDEX(입고!$B$8:$B$1013,SMALL(IF(입고!$C$8:$C$1013=마스터!$M$4,ROW(입고!$C$8:$C$1013)-7),5)),"")} | C16: {=IFERROR(INDEX(입고!$E$8:$E$1013,SMALL(IF(입고!$C$8:$C$1013=마스터!$M$4,ROW(입고!$C$8:$C$1013)-7),5)),"")} | D16: {=IFERROR(INDEX(입고!$F$8:$F$1013,SMALL(IF(입고!$C$8:$C$1013=마스터!$M$4,ROW(입고!$C$8:$C$1013)-7),5)),"")} | E16: {=IFERROR(INDEX(입고!$H$8:$H$1013,SMALL(IF(입고!$C$8:$C$1013=마스터!$M$4,ROW(입고!$C$8:$C$1013)-7),5)),"")} | F16: {=IFERROR(INDEX(입고!$I$8:$I$1013,SMALL(IF(입고!$C$8:$C$1013=마스터!$M$4,ROW(입고!$C$8:$C$1013)-7),5)),"")} | G16: =IF(B16="","",IFERROR(G15,0)+IFERROR(D16,0))
A17: =IF(B17="","",ROW()-11) | B17: {=IFERROR(INDEX(입고!$B$8:$B$1013,SMALL(IF(입고!$C$8:$C$1013=마스터!$M$4,ROW(입고!$C$8:$C$1013)-7),6)),"")} | C17: {=IFERROR(INDEX(입고!$E$8:$E$1013,SMALL(IF(입고!$C$8:$C$1013=마스터!$M$4,ROW(입고!$C$8:$C$1013)-7),6)),"")} | D17: {=IFERROR(INDEX(입고!$F$8:$F$1013,SMALL(IF(입고!$C$8:$C$1013=마스터!$M$4,ROW(입고!$C$8:$C$1013)-7),6)),"")} | E17: {=IFERROR(INDEX(입고!$H$8:$H$1013,SMALL(IF(입고!$C$8:$C$1013=마스터!$M$4,ROW(입고!$C$8:$C$1013)-7),6)),"")} | F17: {=IFERROR(INDEX(입고!$I$8:$I$1013,SMALL(IF(입고!$C$8:$C$1013=마스터!$M$4,ROW(입고!$C$8:$C$1013)-7),6)),"")} | G17: =IF(B17="","",IFERROR(G16,0)+IFERROR(D17,0))
A18: =IF(B18="","",ROW()-11) | B18: {=IFERROR(INDEX(입고!$B$8:$B$1013,SMALL(IF(입고!$C$8:$C$1013=마스터!$M$4,ROW(입고!$C$8:$C$1013)-7),7)),"")} | C18: {=IFERROR(INDEX(입고!$E$8:$E$1013,SMALL(IF(입고!$C$8:$C$1013=마스터!$M$4,ROW(입고!$C$8:$C$1013)-7),7)),"")} | D18: {=IFERROR(INDEX(입고!$F$8:$F$1013,SMALL(IF(입고!$C$8:$C$1013=마스터!$M$4,ROW(입고!$C$8:$C$1013)-7),7)),"")} | E18: {=IFERROR(INDEX(입고!$H$8:$H$1013,SMALL(IF(입고!$C$8:$C$1013=마스터!$M$4,ROW(입고!$C$8:$C$1013)-7),7)),"")} | F18: {=IFERROR(INDEX(입고!$I$8:$I$1013,SMALL(IF(입고!$C$8:$C$1013=마스터!$M$4,ROW(입고!$C$8:$C$1013)-7),7)),"")} | G18: =IF(B18="","",IFERROR(G17,0)+IFERROR(D18,0))
A19: =IF(B19="","",ROW()-11) | B19: {=IFERROR(INDEX(입고!$B$8:$B$1013,SMALL(IF(입고!$C$8:$C$1013=마스터!$M$4,ROW(입고!$C$8:$C$1013)-7),8)),"")} | C19: {=IFERROR(INDEX(입고!$E$8:$E$1013,SMALL(IF(입고!$C$8:$C$1013=마스터!$M$4,ROW(입고!$C$8:$C$1013)-7),8)),"")} | D19: {=IFERROR(INDEX(입고!$F$8:$F$1013,SMALL(IF(입고!$C$8:$C$1013=마스터!$M$4,ROW(입고!$C$8:$C$1013)-7),8)),"")} | E19: {=IFERROR(INDEX(입고!$H$8:$H$1013,SMALL(IF(입고!$C$8:$C$1013=마스터!$M$4,ROW(입고!$C$8:$C$1013)-7),8)),"")} | F19: {=IFERROR(INDEX(입고!$I$8:$I$1013,SMALL(IF(입고!$C$8:$C$1013=마스터!$M$4,ROW(입고!$C$8:$C$1013)-7),8)),"")} | G19: =IF(B19="","",IFERROR(G18,0)+IFERROR(D19,0))
A20: =IF(B20="","",ROW()-11) | B20: {=IFERROR(INDEX(입고!$B$8:$B$1013,SMALL(IF(입고!$C$8:$C$1013=마스터!$M$4,ROW(입고!$C$8:$C$1013)-7),9)),"")} | C20: {=IFERROR(INDEX(입고!$E$8:$E$1013,SMALL(IF(입고!$C$8:$C$1013=마스터!$M$4,ROW(입고!$C$8:$C$1013)-7),9)),"")} | D20: {=IFERROR(INDEX(입고!$F$8:$F$1013,SMALL(IF(입고!$C$8:$C$1013=마스터!$M$4,ROW(입고!$C$8:$C$1013)-7),9)),"")} | E20: {=IFERROR(INDEX(입고!$H$8:$H$1013,SMALL(IF(입고!$C$8:$C$1013=마스터!$M$4,ROW(입고!$C$8:$C$1013)-7),9)),"")} | F20: {=IFERROR(INDEX(입고!$I$8:$I$1013,SMALL(IF(입고!$C$8:$C$1013=마스터!$M$4,ROW(입고!$C$8:$C$1013)-7),9)),"")} | G20: =IF(B20="","",IFERROR(G19,0)+IFERROR(D20,0))
A21: =IF(B21="","",ROW()-11) | B21: {=IFERROR(INDEX(입고!$B$8:$B$1013,SMALL(IF(입고!$C$8:$C$1013=마스터!$M$4,ROW(입고!$C$8:$C$1013)-7),10)),"")} | C21: {=IFERROR(INDEX(입고!$E$8:$E$1013,SMALL(IF(입고!$C$8:$C$1013=마스터!$M$4,ROW(입고!$C$8:$C$1013)-7),10)),"")} | D21: {=IFERROR(INDEX(입고!$F$8:$F$1013,SMALL(IF(입고!$C$8:$C$1013=마스터!$M$4,ROW(입고!$C$8:$C$1013)-7),10)),"")} | E21: {=IFERROR(INDEX(입고!$H$8:$H$1013,SMALL(IF(입고!$C$8:$C$1013=마스터!$M$4,ROW(입고!$C$8:$C$1013)-7),10)),"")} | F21: {=IFERROR(INDEX(입고!$I$8:$I$1013,SMALL(IF(입고!$C$8:$C$1013=마스터!$M$4,ROW(입고!$C$8:$C$1013)-7),10)),"")} | G21: =IF(B21="","",IFERROR(G20,0)+IFERROR(D21,0))
A22: =IF(B22="","",ROW()-11) | B22: {=IFERROR(INDEX(입고!$B$8:$B$1013,SMALL(IF(입고!$C$8:$C$1013=마스터!$M$4,ROW(입고!$C$8:$C$1013)-7),11)),"")} | C22: {=IFERROR(INDEX(입고!$E$8:$E$1013,SMALL(IF(입고!$C$8:$C$1013=마스터!$M$4,ROW(입고!$C$8:$C$1013)-7),11)),"")} | D22: {=IFERROR(INDEX(입고!$F$8:$F$1013,SMALL(IF(입고!$C$8:$C$1013=마스터!$M$4,ROW(입고!$C$8:$C$1013)-7),11)),"")} | E22: {=IFERROR(INDEX(입고!$H$8:$H$1013,SMALL(IF(입고!$C$8:$C$1013=마스터!$M$4,ROW(입고!$C$8:$C$1013)-7),11)),"")} | F22: {=IFERROR(INDEX(입고!$I$8:$I$1013,SMALL(IF(입고!$C$8:$C$1013=마스터!$M$4,ROW(입고!$C$8:$C$1013)-7),11)),"")} | G22: =IF(B22="","",IFERROR(G21,0)+IFERROR(D22,0))
A23: =IF(B23="","",ROW()-11) | B23: {=IFERROR(INDEX(입고!$B$8:$B$1013,SMALL(IF(입고!$C$8:$C$1013=마스터!$M$4,ROW(입고!$C$8:$C$1013)-7),12)),"")} | C23: {=IFERROR(INDEX(입고!$E$8:$E$1013,SMALL(IF(입고!$C$8:$C$1013=마스터!$M$4,ROW(입고!$C$8:$C$1013)-7),12)),"")} | D23: {=IFERROR(INDEX(입고!$F$8:$F$1013,SMALL(IF(입고!$C$8:$C$1013=마스터!$M$4,ROW(입고!$C$8:$C$1013)-7),12)),"")} | E23: {=IFERROR(INDEX(입고!$H$8:$H$1013,SMALL(IF(입고!$C$8:$C$1013=마스터!$M$4,ROW(입고!$C$8:$C$1013)-7),12)),"")} | F23: {=IFERROR(INDEX(입고!$I$8:$I$1013,SMALL(IF(입고!$C$8:$C$1013=마스터!$M$4,ROW(입고!$C$8:$C$1013)-7),12)),"")} | G23: =IF(B23="","",IFERROR(G22,0)+IFERROR(D23,0))
A24: =IF(B24="","",ROW()-11) | B24: {=IFERROR(INDEX(입고!$B$8:$B$1013,SMALL(IF(입고!$C$8:$C$1013=마스터!$M$4,ROW(입고!$C$8:$C$1013)-7),13)),"")} | C24: {=IFERROR(INDEX(입고!$E$8:$E$1013,SMALL(IF(입고!$C$8:$C$1013=마스터!$M$4,ROW(입고!$C$8:$C$1013)-7),13)),"")} | D24: {=IFERROR(INDEX(입고!$F$8:$F$1013,SMALL(IF(입고!$C$8:$C$1013=마스터!$M$4,ROW(입고!$C$8:$C$1013)-7),13)),"")} | E24: {=IFERROR(INDEX(입고!$H$8:$H$1013,SMALL(IF(입고!$C$8:$C$1013=마스터!$M$4,ROW(입고!$C$8:$C$1013)-7),13)),"")} | F24: {=IFERROR(INDEX(입고!$I$8:$I$1013,SMALL(IF(입고!$C$8:$C$1013=마스터!$M$4,ROW(입고!$C$8:$C$1013)-7),13)),"")} | G24: =IF(B24="","",IFERROR(G23,0)+IFERROR(D24,0))
A25: =IF(B25="","",ROW()-11) | B25: {=IFERROR(INDEX(입고!$B$8:$B$1013,SMALL(IF(입고!$C$8:$C$1013=마스터!$M$4,ROW(입고!$C$8:$C$1013)-7),14)),"")} | C25: {=IFERROR(INDEX(입고!$E$8:$E$1013,SMALL(IF(입고!$C$8:$C$1013=마스터!$M$4,ROW(입고!$C$8:$C$1013)-7),14)),"")} | D25: {=IFERROR(INDEX(입고!$F$8:$F$1013,SMALL(IF(입고!$C$8:$C$1013=마스터!$M$4,ROW(입고!$C$8:$C$1013)-7),14)),"")} | E25: {=IFERROR(INDEX(입고!$H$8:$H$1013,SMALL(IF(입고!$C$8:$C$1013=마스터!$M$4,ROW(입고!$C$8:$C$1013)-7),14)),"")} | F25: {=IFERROR(INDEX(입고!$I$8:$I$1013,SMALL(IF(입고!$C$8:$C$1013=마스터!$M$4,ROW(입고!$C$8:$C$1013)-7),14)),"")} | G25: =IF(B25="","",IFERROR(G24,0)+IFERROR(D25,0))
A26: =IF(B26="","",ROW()-11) | B26: {=IFERROR(INDEX(입고!$B$8:$B$1013,SMALL(IF(입고!$C$8:$C$1013=마스터!$M$4,ROW(입고!$C$8:$C$1013)-7),15)),"")} | C26: {=IFERROR(INDEX(입고!$E$8:$E$1013,SMALL(IF(입고!$C$8:$C$1013=마스터!$M$4,ROW(입고!$C$8:$C$1013)-7),15)),"")} | D26: {=IFERROR(INDEX(입고!$F$8:$F$1013,SMALL(IF(입고!$C$8:$C$1013=마스터!$M$4,ROW(입고!$C$8:$C$1013)-7),15)),"")} | E26: {=IFERROR(INDEX(입고!$H$8:$H$1013,SMALL(IF(입고!$C$8:$C$1013=마스터!$M$4,ROW(입고!$C$8:$C$1013)-7),15)),"")} | F26: {=IFERROR(INDEX(입고!$I$8:$I$1013,SMALL(IF(입고!$C$8:$C$1013=마스터!$M$4,ROW(입고!$C$8:$C$1013)-7),15)),"")} | G26: =IF(B26="","",IFERROR(G25,0)+IFERROR(D26,0))
A27: =IF(B27="","",ROW()-11) | B27: {=IFERROR(INDEX(입고!$B$8:$B$1013,SMALL(IF(입고!$C$8:$C$1013=마스터!$M$4,ROW(입고!$C$8:$C$1013)-7),16)),"")} | C27: {=IFERROR(INDEX(입고!$E$8:$E$1013,SMALL(IF(입고!$C$8:$C$1013=마스터!$M$4,ROW(입고!$C$8:$C$1013)-7),16)),"")} | D27: {=IFERROR(INDEX(입고!$F$8:$F$1013,SMALL(IF(입고!$C$8:$C$1013=마스터!$M$4,ROW(입고!$C$8:$C$1013)-7),16)),"")} | E27: {=IFERROR(INDEX(입고!$H$8:$H$1013,SMALL(IF(입고!$C$8:$C$1013=마스터!$M$4,ROW(입고!$C$8:$C$1013)-7),16)),"")} | F27: {=IFERROR(INDEX(입고!$I$8:$I$1013,SMALL(IF(입고!$C$8:$C$1013=마스터!$M$4,ROW(입고!$C$8:$C$1013)-7),16)),"")} | G27: =IF(B27="","",IFERROR(G26,0)+IFERROR(D27,0))
A28: =IF(B28="","",ROW()-11) | B28: {=IFERROR(INDEX(입고!$B$8:$B$1013,SMALL(IF(입고!$C$8:$C$1013=마스터!$M$4,ROW(입고!$C$8:$C$1013)-7),17)),"")} | C28: {=IFERROR(INDEX(입고!$E$8:$E$1013,SMALL(IF(입고!$C$8:$C$1013=마스터!$M$4,ROW(입고!$C$8:$C$1013)-7),17)),"")} | D28: {=IFERROR(INDEX(입고!$F$8:$F$1013,SMALL(IF(입고!$C$8:$C$1013=마스터!$M$4,ROW(입고!$C$8:$C$1013)-7),17)),"")} | E28: {=IFERROR(INDEX(입고!$H$8:$H$1013,SMALL(IF(입고!$C$8:$C$1013=마스터!$M$4,ROW(입고!$C$8:$C$1013)-7),17)),"")} | F28: {=IFERROR(INDEX(입고!$I$8:$I$1013,SMALL(IF(입고!$C$8:$C$1013=마스터!$M$4,ROW(입고!$C$8:$C$1013)-7),17)),"")} | G28: =IF(B28="","",IFERROR(G27,0)+IFERROR(D28,0))
A29: =IF(B29="","",ROW()-11) | B29: {=IFERROR(INDEX(입고!$B$8:$B$1013,SMALL(IF(입고!$C$8:$C$1013=마스터!$M$4,ROW(입고!$C$8:$C$1013)-7),18)),"")} | C29: {=IFERROR(INDEX(입고!$E$8:$E$1013,SMALL(IF(입고!$C$8:$C$1013=마스터!$M$4,ROW(입고!$C$8:$C$1013)-7),18)),"")} | D29: {=IFERROR(INDEX(입고!$F$8:$F$1013,SMALL(IF(입고!$C$8:$C$1013=마스터!$M$4,ROW(입고!$C$8:$C$1013)-7),18)),"")} | E29: {=IFERROR(INDEX(입고!$H$8:$H$1013,SMALL(IF(입고!$C$8:$C$1013=마스터!$M$4,ROW(입고!$C$8:$C$1013)-7),18)),"")} | F29: {=IFERROR(INDEX(입고!$I$8:$I$1013,SMALL(IF(입고!$C$8:$C$1013=마스터!$M$4,ROW(입고!$C$8:$C$1013)-7),18)),"")} | G29: =IF(B29="","",IFERROR(G28,0)+IFERROR(D29,0))
A30: =IF(B30="","",ROW()-11) | B30: {=IFERROR(INDEX(입고!$B$8:$B$1013,SMALL(IF(입고!$C$8:$C$1013=마스터!$M$4,ROW(입고!$C$8:$C$1013)-7),19)),"")} | C30: {=IFERROR(INDEX(입고!$E$8:$E$1013,SMALL(IF(입고!$C$8:$C$1013=마스터!$M$4,ROW(입고!$C$8:$C$1013)-7),19)),"")} | D30: {=IFERROR(INDEX(입고!$F$8:$F$1013,SMALL(IF(입고!$C$8:$C$1013=마스터!$M$4,ROW(입고!$C$8:$C$1013)-7),19)),"")} | E30: {=IFERROR(INDEX(입고!$H$8:$H$1013,SMALL(IF(입고!$C$8:$C$1013=마스터!$M$4,ROW(입고!$C$8:$C$1013)-7),19)),"")} | F30: {=IFERROR(INDEX(입고!$I$8:$I$1013,SMALL(IF(입고!$C$8:$C$1013=마스터!$M$4,ROW(입고!$C$8:$C$1013)-7),19)),"")} | G30: =IF(B30="","",IFERROR(G29,0)+IFERROR(D30,0))
A31: =IF(B31="","",ROW()-11) | B31: {=IFERROR(INDEX(입고!$B$8:$B$1013,SMALL(IF(입고!$C$8:$C$1013=마스터!$M$4,ROW(입고!$C$8:$C$1013)-7),20)),"")} | C31: {=IFERROR(INDEX(입고!$E$8:$E$1013,SMALL(IF(입고!$C$8:$C$1013=마스터!$M$4,ROW(입고!$C$8:$C$1013)-7),20)),"")} | D31: {=IFERROR(INDEX(입고!$F$8:$F$1013,SMALL(IF(입고!$C$8:$C$1013=마스터!$M$4,ROW(입고!$C$8:$C$1013)-7),20)),"")} | E31: {=IFERROR(INDEX(입고!$H$8:$H$1013,SMALL(IF(입고!$C$8:$C$1013=마스터!$M$4,ROW(입고!$C$8:$C$1013)-7),20)),"")} | F31: {=IFERROR(INDEX(입고!$I$8:$I$1013,SMALL(IF(입고!$C$8:$C$1013=마스터!$M$4,ROW(입고!$C$8:$C$1013)-7),20)),"")} | G31: =IF(B31="","",IFERROR(G30,0)+IFERROR(D31,0))
A32: =IF(B32="","",ROW()-11) | B32: {=IFERROR(INDEX(입고!$B$8:$B$1013,SMALL(IF(입고!$C$8:$C$1013=마스터!$M$4,ROW(입고!$C$8:$C$1013)-7),21)),"")} | C32: {=IFERROR(INDEX(입고!$E$8:$E$1013,SMALL(IF(입고!$C$8:$C$1013=마스터!$M$4,ROW(입고!$C$8:$C$1013)-7),21)),"")} | D32: {=IFERROR(INDEX(입고!$F$8:$F$1013,SMALL(IF(입고!$C$8:$C$1013=마스터!$M$4,ROW(입고!$C$8:$C$1013)-7),21)),"")} | E32: {=IFERROR(INDEX(입고!$H$8:$H$1013,SMALL(IF(입고!$C$8:$C$1013=마스터!$M$4,ROW(입고!$C$8:$C$1013)-7),21)),"")} | F32: {=IFERROR(INDEX(입고!$I$8:$I$1013,SMALL(IF(입고!$C$8:$C$1013=마스터!$M$4,ROW(입고!$C$8:$C$1013)-7),21)),"")} | G32: =IF(B32="","",IFERROR(G31,0)+IFERROR(D32,0))
A33: =IF(B33="","",ROW()-11) | B33: {=IFERROR(INDEX(입고!$B$8:$B$1013,SMALL(IF(입고!$C$8:$C$1013=마스터!$M$4,ROW(입고!$C$8:$C$1013)-7),22)),"")} | C33: {=IFERROR(INDEX(입고!$E$8:$E$1013,SMALL(IF(입고!$C$8:$C$1013=마스터!$M$4,ROW(입고!$C$8:$C$1013)-7),22)),"")} | D33: {=IFERROR(INDEX(입고!$F$8:$F$1013,SMALL(IF(입고!$C$8:$C$1013=마스터!$M$4,ROW(입고!$C$8:$C$1013)-7),22)),"")} | E33: {=IFERROR(INDEX(입고!$H$8:$H$1013,SMALL(IF(입고!$C$8:$C$1013=마스터!$M$4,ROW(입고!$C$8:$C$1013)-7),22)),"")} | F33: {=IFERROR(INDEX(입고!$I$8:$I$1013,SMALL(IF(입고!$C$8:$C$1013=마스터!$M$4,ROW(입고!$C$8:$C$1013)-7),22)),"")} | G33: =IF(B33="","",IFERROR(G32,0)+IFERROR(D33,0))
A34: =IF(B34="","",ROW()-11) | B34: {=IFERROR(INDEX(입고!$B$8:$B$1013,SMALL(IF(입고!$C$8:$C$1013=마스터!$M$4,ROW(입고!$C$8:$C$1013)-7),23)),"")} | C34: {=IFERROR(INDEX(입고!$E$8:$E$1013,SMALL(IF(입고!$C$8:$C$1013=마스터!$M$4,ROW(입고!$C$8:$C$1013)-7),23)),"")} | D34: {=IFERROR(INDEX(입고!$F$8:$F$1013,SMALL(IF(입고!$C$8:$C$1013=마스터!$M$4,ROW(입고!$C$8:$C$1013)-7),23)),"")} | E34: {=IFERROR(INDEX(입고!$H$8:$H$1013,SMALL(IF(입고!$C$8:$C$1013=마스터!$M$4,ROW(입고!$C$8:$C$1013)-7),23)),"")} | F34: {=IFERROR(INDEX(입고!$I$8:$I$1013,SMALL(IF(입고!$C$8:$C$1013=마스터!$M$4,ROW(입고!$C$8:$C$1013)-7),23)),"")} | G34: =IF(B34="","",IFERROR(G33,0)+IFERROR(D34,0))
A35: =IF(B35="","",ROW()-11) | B35: {=IFERROR(INDEX(입고!$B$8:$B$1013,SMALL(IF(입고!$C$8:$C$1013=마스터!$M$4,ROW(입고!$C$8:$C$1013)-7),24)),"")} | C35: {=IFERROR(INDEX(입고!$E$8:$E$1013,SMALL(IF(입고!$C$8:$C$1013=마스터!$M$4,ROW(입고!$C$8:$C$1013)-7),24)),"")} | D35: {=IFERROR(INDEX(입고!$F$8:$F$1013,SMALL(IF(입고!$C$8:$C$1013=마스터!$M$4,ROW(입고!$C$8:$C$1013)-7),24)),"")} | E35: {=IFERROR(INDEX(입고!$H$8:$H$1013,SMALL(IF(입고!$C$8:$C$1013=마스터!$M$4,ROW(입고!$C$8:$C$1013)-7),24)),"")} | F35: {=IFERROR(INDEX(입고!$I$8:$I$1013,SMALL(IF(입고!$C$8:$C$1013=마스터!$M$4,ROW(입고!$C$8:$C$1013)-7),24)),"")} | G35: =IF(B35="","",IFERROR(G34,0)+IFERROR(D35,0))
A36: =IF(B36="","",ROW()-11) | B36: {=IFERROR(INDEX(입고!$B$8:$B$1013,SMALL(IF(입고!$C$8:$C$1013=마스터!$M$4,ROW(입고!$C$8:$C$1013)-7),25)),"")} | C36: {=IFERROR(INDEX(입고!$E$8:$E$1013,SMALL(IF(입고!$C$8:$C$1013=마스터!$M$4,ROW(입고!$C$8:$C$1013)-7),25)),"")} | D36: {=IFERROR(INDEX(입고!$F$8:$F$1013,SMALL(IF(입고!$C$8:$C$1013=마스터!$M$4,ROW(입고!$C$8:$C$1013)-7),25)),"")} | E36: {=IFERROR(INDEX(입고!$H$8:$H$1013,SMALL(IF(입고!$C$8:$C$1013=마스터!$M$4,ROW(입고!$C$8:$C$1013)-7),25)),"")} | F36: {=IFERROR(INDEX(입고!$I$8:$I$1013,SMALL(IF(입고!$C$8:$C$1013=마스터!$M$4,ROW(입고!$C$8:$C$1013)-7),25)),"")} | G36: =IF(B36="","",IFERROR(G35,0)+IFERROR(D36,0))
A37: =IF(B37="","",ROW()-11) | B37: {=IFERROR(INDEX(입고!$B$8:$B$1013,SMALL(IF(입고!$C$8:$C$1013=마스터!$M$4,ROW(입고!$C$8:$C$1013)-7),26)),"")} | C37: {=IFERROR(INDEX(입고!$E$8:$E$1013,SMALL(IF(입고!$C$8:$C$1013=마스터!$M$4,ROW(입고!$C$8:$C$1013)-7),26)),"")} | D37: {=IFERROR(INDEX(입고!$F$8:$F$1013,SMALL(IF(입고!$C$8:$C$1013=마스터!$M$4,ROW(입고!$C$8:$C$1013)-7),26)),"")} | E37: {=IFERROR(INDEX(입고!$H$8:$H$1013,SMALL(IF(입고!$C$8:$C$1013=마스터!$M$4,ROW(입고!$C$8:$C$1013)-7),26)),"")} | F37: {=IFERROR(INDEX(입고!$I$8:$I$1013,SMALL(IF(입고!$C$8:$C$1013=마스터!$M$4,ROW(입고!$C$8:$C$1013)-7),26)),"")} | G37: =IF(B37="","",IFERROR(G36,0)+IFERROR(D37,0))
A38: =IF(B38="","",ROW()-11) | B38: {=IFERROR(INDEX(입고!$B$8:$B$1013,SMALL(IF(입고!$C$8:$C$1013=마스터!$M$4,ROW(입고!$C$8:$C$1013)-7),27)),"")} | C38: {=IFERROR(INDEX(입고!$E$8:$E$1013,SMALL(IF(입고!$C$8:$C$1013=마스터!$M$4,ROW(입고!$C$8:$C$1013)-7),27)),"")} | D38: {=IFERROR(INDEX(입고!$F$8:$F$1013,SMALL(IF(입고!$C$8:$C$1013=마스터!$M$4,ROW(입고!$C$8:$C$1013)-7),27)),"")} | E38: {=IFERROR(INDEX(입고!$H$8:$H$1013,SMALL(IF(입고!$C$8:$C$1013=마스터!$M$4,ROW(입고!$C$8:$C$1013)-7),27)),"")} | F38: {=IFERROR(INDEX(입고!$I$8:$I$1013,SMALL(IF(입고!$C$8:$C$1013=마스터!$M$4,ROW(입고!$C$8:$C$1013)-7),27)),"")} | G38: =IF(B38="","",IFERROR(G37,0)+IFERROR(D38,0))
A39: =IF(B39="","",ROW()-11) | B39: {=IFERROR(INDEX(입고!$B$8:$B$1013,SMALL(IF(입고!$C$8:$C$1013=마스터!$M$4,ROW(입고!$C$8:$C$1013)-7),28)),"")} | C39: {=IFERROR(INDEX(입고!$E$8:$E$1013,SMALL(IF(입고!$C$8:$C$1013=마스터!$M$4,ROW(입고!$C$8:$C$1013)-7),28)),"")} | D39: {=IFERROR(INDEX(입고!$F$8:$F$1013,SMALL(IF(입고!$C$8:$C$1013=마스터!$M$4,ROW(입고!$C$8:$C$1013)-7),28)),"")} | E39: {=IFERROR(INDEX(입고!$H$8:$H$1013,SMALL(IF(입고!$C$8:$C$1013=마스터!$M$4,ROW(입고!$C$8:$C$1013)-7),28)),"")} | F39: {=IFERROR(INDEX(입고!$I$8:$I$1013,SMALL(IF(입고!$C$8:$C$1013=마스터!$M$4,ROW(입고!$C$8:$C$1013)-7),28)),"")} | G39: =IF(B39="","",IFERROR(G38,0)+IFERROR(D39,0))
A40: =IF(B40="","",ROW()-11) | B40: {=IFERROR(INDEX(입고!$B$8:$B$1013,SMALL(IF(입고!$C$8:$C$1013=마스터!$M$4,ROW(입고!$C$8:$C$1013)-7),29)),"")} | C40: {=IFERROR(INDEX(입고!$E$8:$E$1013,SMALL(IF(입고!$C$8:$C$1013=마스터!$M$4,ROW(입고!$C$8:$C$1013)-7),29)),"")} | D40: {=IFERROR(INDEX(입고!$F$8:$F$1013,SMALL(IF(입고!$C$8:$C$1013=마스터!$M$4,ROW(입고!$C$8:$C$1013)-7),29)),"")} | E40: {=IFERROR(INDEX(입고!$H$8:$H$1013,SMALL(IF(입고!$C$8:$C$1013=마스터!$M$4,ROW(입고!$C$8:$C$1013)-7),29)),"")} | F40: {=IFERROR(INDEX(입고!$I$8:$I$1013,SMALL(IF(입고!$C$8:$C$1013=마스터!$M$4,ROW(입고!$C$8:$C$1013)-7),29)),"")} | G40: =IF(B40="","",IFERROR(G39,0)+IFERROR(D40,0))
A41: =IF(B41="","",ROW()-11) | B41: {=IFERROR(INDEX(입고!$B$8:$B$1013,SMALL(IF(입고!$C$8:$C$1013=마스터!$M$4,ROW(입고!$C$8:$C$1013)-7),30)),"")} | C41: {=IFERROR(INDEX(입고!$E$8:$E$1013,SMALL(IF(입고!$C$8:$C$1013=마스터!$M$4,ROW(입고!$C$8:$C$1013)-7),30)),"")} | D41: {=IFERROR(INDEX(입고!$F$8:$F$1013,SMALL(IF(입고!$C$8:$C$1013=마스터!$M$4,ROW(입고!$C$8:$C$1013)-7),30)),"")} | E41: {=IFERROR(INDEX(입고!$H$8:$H$1013,SMALL(IF(입고!$C$8:$C$1013=마스터!$M$4,ROW(입고!$C$8:$C$1013)-7),30)),"")} | F41: {=IFERROR(INDEX(입고!$I$8:$I$1013,SMALL(IF(입고!$C$8:$C$1013=마스터!$M$4,ROW(입고!$C$8:$C$1013)-7),30)),"")} | G41: =IF(B41="","",IFERROR(G40,0)+IFERROR(D41,0))
A43: ■ 출고 이력 (일자, LOT, 수량, 현장, 비고, 누적출고)
...

Sheet 96K국산 25T × 300W × 7320L
A1: =CONCATENATE("[02] ", 마스터!D5, " | ", 마스터!F5) -> [02] 세라믹울 96K 국산 | 25T × 300W × 7320L
