Workbook

Sheet 1. 소켓인수검사
A1: 구조체작업지시서 | D1: =R2 -> 26.06.04 씨에스_우진아이엔에스_포스코건설_양평동삼화인쇄 | R1: 현장명
R2: 26.06.04 씨에스_우진아이엔에스_포스코건설_양평동삼화인쇄
A6: No | B6: 구조 | C6: 규격 | E6: 분할구조 | F6: 재고여부 | G6: 설치위치 | I6: *VM 200(1000*1000)기준
C7: 가로 | D7: 세로
A9: 01 | B9: VT-049 | C9: 150 | D9: 150 | G9: B1F | Q9: P347
A10: 02 | B10: VT-049 | C10: 150 | D10: 150 | G10: B1F | Q10: P348
A11: 03 | B11: VT-049 | C11: 150 | D11: 150 | G11: B2F | Q11: P349
A12: 04 | B12: VT-049 | C12: 200 | D12: 150 | G12: B1F | Q12: P350
A13: 05 | B13: VT-049 | C13: 200 | D13: 150 | G13: B1F | Q13: P351
A14: 06 | B14: VT-049 | C14: 200 | D14: 150 | G14: B3F | Q14: P352
A15: 07 | B15: VT-049 | C15: 200 | D15: 150 | G15: B3F | Q15: P353
A16: 08 | B16: VT-049 | C16: 200 | D16: 200 | G16: B1F | Q16: P354
A17: 09 | B17: VT-049 | C17: 200 | D17: 200 | G17: B1F | Q17: P355
A18: 10 | B18: VT-049 | C18: 200 | D18: 200 | G18: B1F | Q18: P356
A19: 11 | B19: VT-049 | C19: 200 | D19: 200 | G19: B1F | Q19: P357
A20: 12 | B20: VT-049 | C20: 200 | D20: 200 | G20: B2F | Q20: P358
... A53: 45 | B53: VA-064 | C53: 1000 | D53: 350 | G53: 제연B2F | Q53: P391

Sheet 2.재단(VM)작업
E1: 재단작업지시서(VM) | H1: ='1. 소켓인수검사'!R2 -> 26.06.04 씨에스_우진아이엔에스_포스코건설_양평동삼화인쇄
A5: No. | B5: 구조 | C5: 규격 | E5: 소켓 Lot | F5: 수량 | G5: 소켓내부용 | K5: 소켓외부용 | O5: 비고
C6: 가로 | D6: 세로 | G6: 가로 | I6: 세로 | K6: 상하 | M6: 좌우
G7: 규격 | H7: 수량(EA) | I7: 규격 | J7: 수량(EA) | K7: 규격 | L7: 수량 | M7: 규격 | N7: 수량
A8: ='1. 소켓인수검사'!A9 -> 01 | B8: VT-049 | C8: ='1. 소켓인수검사'!C9 -> 150 | D8: ='1. 소켓인수검사'!D9 -> 150 | F8: 1 | G8: =C8-5 -> 145 | H8: =F8*4 -> 4 | I8: =D8-30 -> 120 | J8: =F8*4 -> 4 | K8: =C8+60 -> 210 | L8: 2 | M8: =D8 -> 150 | N8: 2
A9: ='1. 소켓인수검사'!A10 -> 02 | B9: VT-049 | C9: ='1. 소켓인수검사'!C10 -> 150 | D9: ='1. 소켓인수검사'!D10 -> 150 | F9: 1 | G9: =C9-5 -> 145 | H9: =F9*4 -> 4 | I9: =D9-30 -> 120 | J9: =F9*4 -> 4 | K9: =C9+60 -> 210 | L9: 2 | M9: =D9 -> 150 | N9: 2
A10: ='1. 소켓인수검사'!A11 -> 03 | B10: VT-049 | C10: ='1. 소켓인수검사'!C11 -> 150 | D10: ='1. 소켓인수검사'!D11 -> 150 | F10: 1 | G10: =C10-5 -> 145 | H10: =F10*4 -> 4 | I10: =D10-30 -> 120 | J10: =F10*4 -> 4 | K10: =C10+60 -> 210 | L10: 2 | M10: =D10 -> 150 | N10: 2
A11: ='1. 소켓인수검사'!A12 -> 04 | B11: VT-049 | C11: ='1. 소켓인수검사'!C12 -> 200 | D11: ='1. 소켓인수검사'!D12 -> 150 | F11: 1 | G11: =C11-5 -> 195 | H11: =F11*4 -> 4 | I11: =D11-30 -> 120 | J11: =F11*4 -> 4 | K11: =C11+60 -> 260 | L11: 2 | M11: =D11 -> 150 | N11: 2
A12: ='1. 소켓인수검사'!A13 -> 05 | B12: VT-049 | C12: ='1. 소켓인수검사'!C13 -> 200 | D12: ='1. 소켓인수검사'!D13 -> 150 | F12: 1 | G12: =C12-5 -> 195 | H12: =F12*4 -> 4 | I12: =D12-30 -> 120 | J12: =F12*4 -> 4 | K12: =C12+60 -> 260 | L12: 2 | M12: =D12 -> 150 | N12: 2
A13: ='1. 소켓인수검사'!A14 -> 06 | B13: VT-049 | C13: ='1. 소켓인수검사'!C14 -> 200 | D13: ='1. 소켓인수검사'!D14 -> 150 | F13: 1 | G13: =C13-5 -> 195 | H13: =F13*4 -> 4 | I13: =D13-30 -> 120 | J13: =F13*4 -> 4 | K13: =C13+60 -> 260 | L13: 2 | M13: =D13 -> 150 | N13: 2
A14: ='1. 소켓인수검사'!A15 -> 07 | B14: VT-049 | C14: ='1. 소켓인수검사'!C15 -> 200 | D14: ='1. 소켓인수검사'!D15 -> 150 | F14: 1 | G14: =C14-5 -> 195 | H14: =F14*4 -> 4 | I14: =D14-30 -> 120 | J14: =F14*4 -> 4 | K14: =C14+60 -> 260 | L14: 2 | M14: =D14 -> 150 | N14: 2
A15: ='1. 소켓인수검사'!A16 -> 08 | B15: VT-049 | C15: ='1. 소켓인수검사'!C16 -> 200 | D15: ='1. 소켓인수검사'!D16 -> 200 | F15: 1 | G15: =C15-5 -> 195 | H15: =F15*4 -> 4 | I15: =D15-30 -> 170 | J15: =F15*4 -> 4 | K15: =C15+60 -> 260 | L15: 2 | M15: =D15 -> 200 | N15: 2
A16: ='1. 소켓인수검사'!A17 -> 09 | B16: VT-049 | C16: ='1. 소켓인수검사'!C17 -> 200 | D16: ='1. 소켓인수검사'!D17 -> 200 | F16: 1 | G16: =C16-5 -> 195 | H16: =F16*4 -> 4 | I16: =D16-30 -> 170 | J16: =F16*4 -> 4 | K16: =C16+60 -> 260 | L16: 2 | M16: =D16 -> 200 | N16: 2
A17: ='1. 소켓인수검사'!A18 -> 10 | B17: VT-049 | C17: ='1. 소켓인수검사'!C18 -> 200 | D17: ='1. 소켓인수검사'!D18 -> 200 | F17: 1 | G17: =C17-5 -> 195 | H17: =F17*4 -> 4 | I17: =D17-30 -> 170 | J17: =F17*4 -> 4 | K17: =C17+60 -> 260 | L17: 2 | M17: =D17 -> 200 | N17: 2
A18: ='1. 소켓인수검사'!A19 -> 11 | B18: VT-049 | C18: ='1. 소켓인수검사'!C19 -> 200 | D18: ='1. 소켓인수검사'!D19 -> 200 | F18: 1 | G18: =C18-5 -> 195 | H18: =F18*4 -> 4 | I18: =D18-30 -> 170 | J18: =F18*4 -> 4 | K18: =C18+60 -> 260 | L18: 2 | M18: =D18 -> 200 | N18: 2
A19: ='1. 소켓인수검사'!A20 -> 12 | B19: VT-049 | C19: ='1. 소켓인수검사'!C20 -> 200 | D19: ='1. 소켓인수검사'!D20 -> 200 | F19: 1 | G19: =C19-5 -> 195 | H19: =F19*4 -> 4 | I19: =D19-30 -> 170 | J19: =F19*4 -> 4 | K19: =C19+60 -> 260 | L19: 2 | M19: =D19 -> 200 | N19: 2
... A52: ='1. 소켓인수검사'!A53 -> 45 | B52: VA-064 | C52: ='1. 소켓인수검사'!C53 -> 1000 | D52: ='1. 소켓인수검사'!D53 -> 350 | F52: 1 | G52: =C52-5 -> 995 | H52: =F52*4 -> 4 | I52: =D52-30 -> 320 | J52: =F52*4 -> 4 | K52: =C52+60 -> 1060 | L52: 2 | M52: =D52 -> 350 | N52: 2
A54: 특이사항 및 조치사항

Sheet 차열재 재단(VM,VT)
E1: 재단작업지시서차열재 | G1: ='1. 소켓인수검사'!R2 -> 26.06.04 씨에스_우진아이엔에스_포스코건설_양평동삼화인쇄
A5: No. | B5: 구조 | C5: 규격 | E5: 소켓 Lot | F5: 수량 | G5: 소켓외부용 | K5: 비고
C6: 가로 | D6: 세로 | G6: 상하 | I6: 좌우
G7: 규격 | H7: 수량 | I7: 규격 | J7: 수량
A8: ='1. 소켓인수검사'!A9 -> 01 | B8: VT-049 | C8: ='1. 소켓인수검사'!C9 -> 150 | D8: ='1. 소켓인수검사'!D9 -> 150 | F8: 1 | G8: =C8+60 -> 210 | H8: 2 | I8: =D8 -> 150 | J8: 2
A9: ='1. 소켓인수검사'!A10 -> 02 | B9: VT-049 | C9: ='1. 소켓인수검사'!C10 -> 150 | D9: ='1. 소켓인수검사'!D10 -> 150 | F9: 1 | G9: =C9+60 -> 210 | H9: 2 | I9: =D9 -> 150 | J9: 2
A10: ='1. 소켓인수검사'!A11 -> 03 | B10: VT-049 | C10: ='1. 소켓인수검사'!C11 -> 150 | D10: ='1. 소켓인수검사'!D11 -> 150 | F10: 1 | G10: =C10+60 -> 210 | H10: 2 | I10: =D10 -> 150 | J10: 2
A11: ='1. 소켓인수검사'!A12 -> 04 | B11: VT-049 | C11: ='1. 소켓인수검사'!C12 -> 200 | D11: ='1. 소켓인수검사'!D12 -> 150 | F11: 1 | G11: =C11+60 -> 260 | H11: 2 | I11: =D11 -> 150 | J11: 2
A12: ='1. 소켓인수검사'!A13 -> 05 | B12: VT-049 | C12: ='1. 소켓인수검사'!C13 -> 200 | D12: ='1. 소켓인수검사'!D13 -> 150 | F12: 1 | G12: =C12+60 -> 260 | H12: 2 | I12: =D12 -> 150 | J12: 2
A13: ='1. 소켓인수검사'!A14 -> 06 | B13: VT-049 | C13: ='1. 소켓인수검사'!C14 -> 200 | D13: ='1. 소켓인수검사'!D14 -> 150 | F13: 1 | G13: =C13+60 -> 260 | H13: 2 | I13: =D13 -> 150 | J13: 2
A14: ='1. 소켓인수검사'!A15 -> 07 | B14: VT-049 | C14: ='1. 소켓인수검사'!C15 -> 200 | D14: ='1. 소켓인수검사'!D15 -> 150 | F14: 1 | G14: =C14+60 -> 260 | H14: 2 | I14: =D14 -> 150 | J14: 2
A15: ='1. 소켓인수검사'!A16 -> 08 | B15: VT-049 | C15: ='1. 소켓인수검사'!C16 -> 200 | D15: ='1. 소켓인수검사'!D16 -> 200 | F15: 1 | G15: =C15+60 -> 260 | H15: 2 | I15: =D15 -> 200 | J15: 2
A16: ='1. 소켓인수검사'!A17 -> 09 | B16: VT-049 | C16: ='1. 소켓인수검사'!C17 -> 200 | D16: ='1. 소켓인수검사'!D17 -> 200 | F16: 1 | G16: =C16+60 -> 260 | H16: 2 | I16: =D16 -> 200 | J16: 2
A17: ='1. 소켓인수검사'!A18 -> 10 | B17: VT-049 | C17: ='1. 소켓인수검사'!C18 -> 200 | D17: ='1. 소켓인수검사'!D18 -> 200 | F17: 1 | G17: =C17+60 -> 260 | H17: 2 | I17: =D17 -> 200 | J17: 2
A18: ='1. 소켓인수검사'!A19 -> 11 | B18: VT-049 | C18: ='1. 소켓인수검사'!C19 -> 200 | D18: ='1. 소켓인수검사'!D19 -> 200 | F18: 1 | G18: =C18+60 -> 260 | H18: 2 | I18: =D18 -> 200 | J18: 2
A19: ='1. 소켓인수검사'!A20 -> 12 | B19: VT-049 | C19: ='1. 소켓인수검사'!C20 -> 200 | D19: ='1. 소켓인수검사'!D20 -> 200 | F19: 1 | G19: =C19+60 -> 260 | H19: 2 | I19: =D19 -> 200 | J19: 2
... A52: ='1. 소켓인수검사'!A53 -> 45 | B52: VA-064 | C52: ='1. 소켓인수검사'!C53 -> 1000 | D52: ='1. 소켓인수검사'!D53 -> 350 | F52: 1 | G52: =C52+60 -> 1060 | H52: 2 | I52: =D52 -> 350 | J52: 2
A53: 특이사항 및 조치사항

Sheet 3. 1절곡(VM)
E1: 절 곡 생 산 일 지(VM)
A4: 설비번호
A5: 생산일자 | E5: 생산 시작 | H5: 작업자 | K5: 품명 | N5: ='1. 소켓인수검사'!R2 -> 26.06.04 씨에스_우진아이엔에스_포스코건설_양평동삼화인쇄
E6: 생산 종료
A8: No. | B8: 규격 | D8: 수량 (EA) | E8: 소켓 Lot | F8: 두께 | G8: 평철(mm) | P8: 비고
B9: 가로 | C9: 세로 | G9: 폭 | H9: 가로 | J9: 수량 확인 | K9: 세로 | O9: 수량 확인
H10: 규격 | I10: 수량(EA) | K10: 규격 | N10: 수량(EA)
A11: ='1. 소켓인수검사'!A9 -> 01 | B11: ='1. 소켓인수검사'!C9 -> 150 | C11: ='1. 소켓인수검사'!D9 -> 150 | D11: 1 | F11: 1.6 | H11: =B11-1 -> 149 | I11: =D11*4 -> 4 | K11: =C11-30 -> 120 | N11: =D11*4 -> 4
A12: ='1. 소켓인수검사'!A10 -> 02 | B12: ='1. 소켓인수검사'!C10 -> 150 | C12: ='1. 소켓인수검사'!D10 -> 150 | D12: 1 | F12: 1.6 | H12: =B12-1 -> 149 | I12: =D12*4 -> 4 | K12: =C12-30 -> 120 | N12: =D12*4 -> 4
A13: ='1. 소켓인수검사'!A11 -> 03 | B13: ='1. 소켓인수검사'!C11 -> 150 | C13: ='1. 소켓인수검사'!D11 -> 150 | D13: 1 | F13: 1.6 | H13: =B13-1 -> 149 | I13: =D13*4 -> 4 | K13: =C13-30 -> 120 | N13: =D13*4 -> 4
A14: ='1. 소켓인수검사'!A12 -> 04 | B14: ='1. 소켓인수검사'!C12 -> 200 | C14: ='1. 소켓인수검사'!D12 -> 150 | D14: 1 | F14: 1.6 | H14: =B14-1 -> 199 | I14: =D14*4 -> 4 | K14: =C14-30 -> 120 | N14: =D14*4 -> 4
A15: ='1. 소켓인수검사'!A13 -> 05 | B15: ='1. 소켓인수검사'!C13 -> 200 | C15: ='1. 소켓인수검사'!D13 -> 150 | D15: 1 | F15: 1.6 | H15: =B15-1 -> 199 | I15: =D15*4 -> 4 | K15: =C15-30 -> 120 | N15: =D15*4 -> 4
A16: ='1. 소켓인수검사'!A14 -> 06 | B16: ='1. 소켓인수검사'!C14 -> 200 | C16: ='1. 소켓인수검사'!D14 -> 150 | D16: 1 | F16: 1.6 | H16: =B16-1 -> 199 | I16: =D16*4 -> 4 | K16: =C16-30 -> 120 | N16: =D16*4 -> 4
A17: ='1. 소켓인수검사'!A15 -> 07 | B17: ='1. 소켓인수검사'!C15 -> 200 | C17: ='1. 소켓인수검사'!D15 -> 150 | D17: 1 | F17: 1.6 | H17: =B17-1 -> 199 | I17: =D17*4 -> 4 | K17: =C17-30 -> 120 | N17: =D17*4 -> 4
A18: ='1. 소켓인수검사'!A16 -> 08 | B18: ='1. 소켓인수검사'!C16 -> 200 | C18: ='1. 소켓인수검사'!D16 -> 200 | D18: 1 | F18: 1.6 | H18: =B18-1 -> 199 | I18: =D18*4 -> 4 | K18: =C18-30 -> 170 | N18: =D18*4 -> 4
A19: ='1. 소켓인수검사'!A17 -> 09 | B19: ='1. 소켓인수검사'!C17 -> 200 | C19: ='1. 소켓인수검사'!D17 -> 200 | D19: 1 | F19: 1.6 | H19: =B19-1 -> 199 | I19: =D19*4 -> 4 | K19: =C19-30 -> 170 | N19: =D19*4 -> 4
A20: ='1. 소켓인수검사'!A18 -> 10 | B20: ='1. 소켓인수검사'!C18 -> 200 | C20: ='1. 소켓인수검사'!D18 -> 200 | D20: 1 | F20: 1.6 | H20: =B20-1 -> 199 | I20: =D20*4 -> 4 | K20: =C20-30 -> 170 | N20: =D20*4 -> 4
A21: ='1. 소켓인수검사'!A19 -> 11 | B21: ='1. 소켓인수검사'!C19 -> 200 | C21: ='1. 소켓인수검사'!D19 -> 200 | D21: 1 | F21: 1.6 | H21: =B21-1 -> 199 | I21: =D21*4 -> 4 | K21: =C21-30 -> 170 | N21: =D21*4 -> 4
A22: ='1. 소켓인수검사'!A20 -> 12 | B22: ='1. 소켓인수검사'!C20 -> 200 | C22: ='1. 소켓인수검사'!D20 -> 200 | D22: 1 | F22: 1.6 | H22: =B22-1 -> 199 | I22: =D22*4 -> 4 | K22: =C22-30 -> 170 | N22: =D22*4 -> 4
... A55: ='1. 소켓인수검사'!A53 -> 45 | B55: ='1. 소켓인수검사'!C53 -> 1000 | C55: ='1. 소켓인수검사'!D53 -> 350 | D55: 1 | F55: 1.6 | H55: =B55-1 -> 999 | I55: =D55*4 -> 4 | K55: =C55-30 -> 320 | N55: =D55*4 -> 4
A57: 특이사항 및 조치사항

Sheet 5. 차열재 출하용(VM,VT,VAG)
D1: 차열재생산일지(출하용)
A4: 설비번호
A5: 생산일자 | D5: 생산 시작 | G5: 작업자 | L5: 업 체 | O5: 업 체 | P5: ='1. 소켓인수검사'!R2 -> 26.06.04 씨에스_우진아이엔에스_포스코건설_양평동삼화인쇄
D6: 생산 종료
A8: No. | B8: 가로 | C8: 세로 | D8: 구조 | E8: 면적 | F8: 둘레 | G8: 글라스울 | J8: 차열재 | M8: 차열재 | P8: 차열재
G9: 25*1400 | H9: 수량 | I9: 소요량 | J9: 50*400 | K9: 수량 | L9: 소요량 | M9: 25*200 | N9: 수량 | O9: 소요량 | P9: 50*600 | Q9: 수량 | R9: 소요량
A10: ='1. 소켓인수검사'!A9 -> 01 | B10: ='1. 소켓인수검사'!C9 -> 150 | C10: ='1. 소켓인수검사'!D9 -> 150 | D10: VT-049 | E10: =B10*C10/1000000 -> 0.0225 | F10: =(B10+C10)*2/1000 -> 0.6 | G10: =(F10+0.4) -> 1 | H10: 4 | I10: =G10*H10 -> 4
A11: ='1. 소켓인수검사'!A10 -> 02 | B11: ='1. 소켓인수검사'!C10 -> 150 | C11: ='1. 소켓인수검사'!D10 -> 150 | D11: VT-049 | E11: =B11*C11/1000000 -> 0.0225 | F11: =(B11+C11)*2/1000 -> 0.6 | G11: =(F11+0.4) -> 1 | H11: 4 | I11: =G11*H11 -> 4
A12: ='1. 소켓인수검사'!A11 -> 03 | B12: ='1. 소켓인수검사'!C11 -> 150 | C12: ='1. 소켓인수검사'!D11 -> 150 | D12: VT-049 | E12: =B12*C12/1000000 -> 0.0225 | F12: =(B12+C12)*2/1000 -> 0.6 | G12: =(F12+0.4) -> 1 | H12: 4 | I12: =G12*H12 -> 4
A13: ='1. 소켓인수검사'!A12 -> 04 | B13: ='1. 소켓인수검사'!C12 -> 200 | C13: ='1. 소켓인수검사'!D12 -> 150 | D13: VT-049 | E13: =B13*C13/1000000 -> 0.03 | F13: =(B13+C13)*2/1000 -> 0.7 | G13: =(F13+0.4) -> 1.1 | H13: 4 | I13: =G13*H13 -> 4.4
A14: ='1. 소켓인수검사'!A13 -> 05 | B14: ='1. 소켓인수검사'!C13 -> 200 | C14: ='1. 소켓인수검사'!D13 -> 150 | D14: VT-049 | E14: =B14*C14/1000000 -> 0.03 | F14: =(B14+C14)*2/1000 -> 0.7 | G14: =(F14+0.4) -> 1.1 | H14: 4 | I14: =G14*H14 -> 4.4
A15: ='1. 소켓인수검사'!A14 -> 06 | B15: ='1. 소켓인수검사'!C14 -> 200 | C15: ='1. 소켓인수검사'!D14 -> 150 | D15: VT-049 | E15: =B15*C15/1000000 -> 0.03 | F15: =(B15+C15)*2/1000 -> 0.7 | G15: =(F15+0.4) -> 1.1 | H15: 4 | I15: =G15*H15 -> 4.4
A16: ='1. 소켓인수검사'!A15 -> 07 | B16: ='1. 소켓인수검사'!C15 -> 200 | C16: ='1. 소켓인수검사'!D15 -> 150 | D16: VT-049 | E16: =B16*C16/1000000 -> 0.03 | F16: =(B16+C16)*2/1000 -> 0.7 | G16: =(F16+0.4) -> 1.1 | H16: 4 | I16: =G16*H16 -> 4.4
A17: ='1. 소켓인수검사'!A16 -> 08 | B17: ='1. 소켓인수검사'!C16 -> 200 | C17: ='1. 소켓인수검사'!D16 -> 200 | D17: VT-049 | E17: =B17*C17/1000000 -> 0.04 | F17: =(B17+C17)*2/1000 -> 0.8 | G17: =(F17+0.4) -> 1.2 | H17: 4 | I17: =G17*H17 -> 4.8
A18: ='1. 소켓인수검사'!A17 -> 09 | B18: ='1. 소켓인수검사'!C17 -> 200 | C18: ='1. 소켓인수검사'!D17 -> 200 | D18: VT-049 | E18: =B18*C18/1000000 -> 0.04 | F18: =(B18+C18)*2/1000 -> 0.8 | G18: =(F18+0.4) -> 1.2 | H18: 4 | I18: =G18*H18 -> 4.8
A19: ='1. 소켓인수검사'!A18 -> 10 | B19: ='1. 소켓인수검사'!C18 -> 200 | C19: ='1. 소켓인수검사'!D18 -> 200 | D19: VT-049 | E19: =B19*C19/1000000 -> 0.04 | F19: =(B19+C19)*2/1000 -> 0.8 | G19: =(F19+0.4) -> 1.2 | H19: 4 | I19: =G19*H19 -> 4.8
A20: ='1. 소켓인수검사'!A19 -> 11 | B20: ='1. 소켓인수검사'!C19 -> 200 | C20: ='1. 소켓인수검사'!D19 -> 200 | D20: VT-049 | E20: =B20*C20/1000000 -> 0.04 | F20: =(B20+C20)*2/1000 -> 0.8 | G20: =(F20+0.4) -> 1.2 | H20: 4 | I20: =G20*H20 -> 4.8
A21: ='1. 소켓인수검사'!A20 -> 12 | B21: ='1. 소켓인수검사'!C20 -> 200 | C21: ='1. 소켓인수검사'!D20 -> 200 | D21: VT-049 | E21: =B21*C21/1000000 -> 0.04 | F21: =(B21+C21)*2/1000 -> 0.8 | G21: =(F21+0.4) -> 1.2 | H21: 4 | I21: =G21*H21 -> 4.8
A22: ='1. 소켓인수검사'!A21 -> 13 | B22: ='1. 소켓인수검사'!C21 -> 200 | C22: ='1. 소켓인수검사'!D21 -> 200 | D22: VT-049 | E22: =B22*C22/1000000 -> 0.04 | F22: =(B22+C22)*2/1000 -> 0.8 | G22: =(F22+0.4) -> 1.2 | H22: 4 | I22: =G22*H22 -> 4.8
A23: ='1. 소켓인수검사'!A22 -> 14 | B23: ='1. 소켓인수검사'!C22 -> 200 | C23: ='1. 소켓인수검사'!D22 -> 200 | D23: VT-049 | E23: =B23*C23/1000000 -> 0.04 | F23: =(B23+C23)*2/1000 -> 0.8 | G23: =(F23+0.4) -> 1.2 | H23: =2*2 -> 4 | I23: =G23*H23 -> 4.8
A24: ='1. 소켓인수검사'!A23 -> 15 | B24: ='1. 소켓인수검사'!C23 -> 250 | C24: ='1. 소켓인수검사'!D23 -> 150 | D24: VT-049 | E24: =B24*C24/1000000 -> 0.0375 | F24: =(B24+C24)*2/1000 -> 0.8 | G24: =(F24+0.4) -> 1.2 | H24: =2*2 -> 4 | I24: =G24*H24 -> 4.8
A25: ='1. 소켓인수검사'!A24 -> 16 | B25: ='1. 소켓인수검사'!C24 -> 250 | C25: ='1. 소켓인수검사'!D24 -> 150 | D25: VT-049 | E25: =B25*C25/1000000 -> 0.0375 | F25: =(B25+C25)*2/1000 -> 0.8 | G25: =(F25+0.4) -> 1.2 | H25: =2*2 -> 4 | I25: =G25*H25 -> 4.8
A26: ='1. 소켓인수검사'!A25 -> 17 | B26: ='1. 소켓인수검사'!C25 -> 250 | C26: ='1. 소켓인수검사'!D25 -> 150 | D26: VT-049 | E26: =B26*C26/1000000 -> 0.0375 | F26: =(B26+C26)*2/1000 -> 0.8 | G26: =(F26+0.4) -> 1.2 | H26: =2*2 -> 4 | I26: =G26*H26 -> 4.8
A27: ='1. 소켓인수검사'!A26 -> 18 | B27: ='1. 소켓인수검사'!C26 -> 250 | C27: ='1. 소켓인수검사'!D26 -> 250 | D27: VT-049 | E27: =B27*C27/1000000 -> 0.0625 | F27: =(B27+C27)*2/1000 -> 1 | G27: =(F27+0.4) -> 1.4 | H27: =2*2 -> 4 | I27: =G27*H27 -> 5.6
A28: ='1. 소켓인수검사'!A27 -> 19 | B28: ='1. 소켓인수검사'!C27 -> 250 | C28: ='1. 소켓인수검사'!D27 -> 250 | D28: VT-049 | E28: =B28*C28/1000000 -> 0.0625 | F28: =(B28+C28)*2/1000 -> 1 | G28: =(F28+0.4) -> 1.4 | H28: =2*2 -> 4 | I28: =G28*H28 -> 5.6
A29: ='1. 소켓인수검사'!A28 -> 20 | B29: ='1. 소켓인수검사'!C28 -> 250 | C29: ='1. 소켓인수검사'!D28 -> 250 | D29: VT-049 | E29: =B29*C29/1000000 -> 0.0625 | F29: =(B29+C29)*2/1000 -> 1 | G29: =(F29+0.4) -> 1.4 | H29: =2*2 -> 4 | I29: =G29*H29 -> 5.6
A30: ='1. 소켓인수검사'!A29 -> 21 | B30: ='1. 소켓인수검사'!C29 -> 250 | C30: ='1. 소켓인수검사'!D29 -> 250 | D30: VT-049 | E30: =B30*C30/1000000 -> 0.0625 | F30: =(B30+C30)*2/1000 -> 1 | G30: =(F30+0.4) -> 1.4 | H30: =2*2 -> 4 | I30: =G30*H30 -> 5.6
A31: ='1. 소켓인수검사'!A30 -> 22 | B31: ='1. 소켓인수검사'!C30 -> 250 | C31: ='1. 소켓인수검사'!D30 -> 250 | D31: VT-049 | E31: =B31*C31/1000000 -> 0.0625 | F31: =(B31+C31)*2/1000 -> 1 | G31: =(F31+0.4) -> 1.4 | H31: =2*2 -> 4 | I31: =G31*H31 -> 5.6
A32: ='1. 소켓인수검사'!A31 -> 23 | B32: ='1. 소켓인수검사'!C31 -> 300 | C32: ='1. 소켓인수검사'!D31 -> 200 | D32: VT-049 | E32: =B32*C32/1000000 -> 0.06 | F32: =(B32+C32)*2/1000 -> 1 | G32: =(F32+0.4) -> 1.4 | H32: =2*2 -> 4 | I32: =G32*H32 -> 5.6
A33: ='1. 소켓인수검사'!A32 -> 24 | B33: ='1. 소켓인수검사'!C32 -> 300 | C33: ='1. 소켓인수검사'!D32 -> 200 | D33: VT-049 | E33: =B33*C33/1000000 -> 0.06 | F33: =(B33+C33)*2/1000 -> 1 | G33: =(F33+0.4) -> 1.4 | H33: =2*2 -> 4 | I33: =G33*H33 -> 5.6
A34: ='1. 소켓인수검사'!A33 -> 25 | B34: ='1. 소켓인수검사'!C33 -> 300 | C34: ='1. 소켓인수검사'!D33 -> 200 | D34: VT-049 | E34: =B34*C34/1000000 -> 0.06 | F34: =(B34+C34)*2/1000 -> 1 | G34: =(F34+0.4) -> 1.4 | H34: =2*2 -> 4 | I34: =G34*H34 -> 5.6
... A42: ='1. 소켓인수검사'!A41 -> 33 | B42: ='1. 소켓인수검사'!C41 -> 400 | C42: ='1. 소켓인수검사'!D41 -> 300 | D42: VT-049 | E42: =B42*C42/1000000 -> 0.12 | F42: =(B42+C42)*2/1000 -> 1.4 | G42: =(F42+0.4) -> 1.8 | H42: =2*2 -> 4 | I42: =G42*H42 -> 7.2
A43: ='1. 소켓인수검사'!A42 -> 34 | B43: ='1. 소켓인수검사'!C42 -> 400 | C43: ='1. 소켓인수검사'!D42 -> 300 | D43: VT-049 | E43: =B43*C43/1000000 -> 0.12 | F43: =(B43+C43)*2/1000 -> 1.4 | G43: =(F43+0.4) -> 1.8 | H43: 4 | I43: =G43*H43 -> 7.2
A44: ='1. 소켓인수검사'!A43 -> 35 | B44: ='1. 소켓인수검사'!C43 -> 450 | C44: ='1. 소켓인수검사'!D43 -> 350 | D44: VT-049 | E44: =B44*C44/1000000 -> 0.1575 | F44: =(B44+C44)*2/1000 -> 1.6 | G44: =(F44+0.4) -> 2 | H44: 4 | I44: =G44*H44 -> 8
A45: ='1. 소켓인수검사'!A44 -> 36 | B45: ='1. 소켓인수검사'!C44 -> 450 | C45: ='1. 소켓인수검사'!D44 -> 350 | D45: VT-049 | E45: =B45*C45/1000000 -> 0.1575 | F45: =(B45+C45)*2/1000 -> 1.6 | G45: =(F45+0.4) -> 2 | H45: 4 | I45: =G45*H45 -> 8
A46: ='1. 소켓인수검사'!A45 -> 37 | B46: ='1. 소켓인수검사'!C45 -> 500 | C46: ='1. 소켓인수검사'!D45 -> 300 | D46: VT-049 | E46: =B46*C46/1000000 -> 0.15 | F46: =(B46+C46)*2/1000 -> 1.6 | G46: =(F46+0.4) -> 2 | H46: 4 | I46: =G46*H46 -> 8
A47: ='1. 소켓인수검사'!A46 -> 38 | B47: ='1. 소켓인수검사'!C46 -> 600 | C47: ='1. 소켓인수검사'!D46 -> 250 | D47: VT-049 | E47: =B47*C47/1000000 -> 0.15 | F47: =(B47+C47)*2/1000 -> 1.7 | G47: =(F47+0.4) -> 2.1 | H47: 4 | I47: =G47*H47 -> 8.4
A48: ='1. 소켓인수검사'!A47 -> 39 | B48: ='1. 소켓인수검사'!C47 -> 900 | C48: ='1. 소켓인수검사'!D47 -> 400 | D48: VT-049 | E48: =B48*C48/1000000 -> 0.36 | F48: =(B48+C48)*2/1000 -> 2.6 | G48: =(F48+0.4) -> 3 | H48: 4 | I48: =G48*H48 -> 12
A49: ='1. 소켓인수검사'!A48 -> 40 | B49: ='1. 소켓인수검사'!C48 -> 1000 | C49: ='1. 소켓인수검사'!D48 -> 400 | D49: VT-049 | E49: =B49*C49/1000000 -> 0.4 | F49: =(B49+C49)*2/1000 -> 2.8 | G49: =(F49+0.4) -> 3.2 | H49: 4 | I49: =G49*H49 -> 12.8
A50: ='1. 소켓인수검사'!A49 -> 41 | B50: ='1. 소켓인수검사'!C49 -> 500 | C50: ='1. 소켓인수검사'!D49 -> 300 | D50: VA-064 | E50: =B50*C50/1000000 -> 0.15 | F50: =(B50+C50)*2/1000 -> 1.6 | M50: =F50+0.5 -> 2.1 | N50: 4 | O50: =+N50*M50 -> 8.4
...

Sheet 6. 라벨소요량
E1: 라벨소요량(행복산업_KEC 구미공장_251128) | F1: 라벨소요량 | K1: ='1. 소켓인수검사'!R2 -> 26.06.04 씨에스_우진아이엔에스_포스코건설_양평동삼화인쇄
A5: No. | B5: 제품 번호 | C5: 가로 | D5: 세로 | E5: 소켓 Lot | F5: 면적 | G5: 둘레 | H5: 방화 소켓 | I5: 글라스울 | K5: 차열재 | M5: 차열재 | O5: 차열재 | Q5: 플래싱 | S5: 인정번호 | T5: 품명 | U5: 설치위치
I6: 25* 1400 | J6: 수량 | K6: 25* 200 | L6: 수량 | M6: 50* 400 | N6: 수량 | O6: 50* 600 | P6: 수량 | Q6: 산출량 | R6: 총량
A7: ='1. 소켓인수검사'!A9 -> 01 | B7: E255 | C7: ='1. 소켓인수검사'!C9 -> 150 | D7: ='1. 소켓인수검사'!D9 -> 150 | F7: =C7*D7/1000000 -> 0.0225 | G7: =(C7+D7)*2/1000 -> 0.6 | H7: 2 | I7: =(G7+0.4) -> 1 | J7: 10 | Q7: =(((C7+60)+250+(D7+60))*2/1000)*2 -> 2.68 | R7: =Q7*2 -> 5.36 | S7: FS-MP25-0310-3 | T7: EZ F.B POSMAC Duct-VT-049 | U7: ='1. 소켓인수검사'!G9 -> B1F
A8: ='1. 소켓인수검사'!A10 -> 02 | B8: E256 | C8: ='1. 소켓인수검사'!C10 -> 150 | D8: ='1. 소켓인수검사'!D10 -> 150 | F8: =C8*D8/1000000 -> 0.0225 | G8: =(C8+D8)*2/1000 -> 0.6 | H8: 2 | I8: =(G8+0.4) -> 1 | J8: 10 | Q8: =(((C8+60)+250+(D8+60))*2/1000)*2 -> 2.68 | R8: =Q8*2 -> 5.36 | S8: FS-MP25-0310-3 | T8: EZ F.B POSMAC Duct-VT-049 | U8: ='1. 소켓인수검사'!G10 -> B1F
A9: ='1. 소켓인수검사'!A11 -> 03 | B9: E257 | C9: ='1. 소켓인수검사'!C11 -> 150 | D9: ='1. 소켓인수검사'!D11 -> 150 | F9: =C9*D9/1000000 -> 0.0225 | G9: =(C9+D9)*2/1000 -> 0.6 | H9: 2 | I9: =(G9+0.4) -> 1 | J9: 10 | Q9: =(((C9+60)+250+(D9+60))*2/1000)*2 -> 2.68 | R9: =Q9*2 -> 5.36 | S9: FS-MP25-0310-3 | T9: EZ F.B POSMAC Duct-VT-049 | U9: ='1. 소켓인수검사'!G11 -> B2F
A10: ='1. 소켓인수검사'!A12 -> 04 | B10: E257 | C10: ='1. 소켓인수검사'!C12 -> 200 | D10: ='1. 소켓인수검사'!D12 -> 150 | F10: =C10*D10/1000000 -> 0.03 | G10: =(C10+D10)*2/1000 -> 0.7 | H10: 2 | I10: =(G10+0.4) -> 1.1 | J10: 10 | Q10: =(((C10+60)+250+(D10+60))*2/1000)*2 -> 2.88 | R10: =Q10*2 -> 5.76 | S10: FS-MP25-0310-3 | T10: EZ F.B POSMAC Duct-VT-049 | U10: ='1. 소켓인수검사'!G12 -> B1F
A11: ='1. 소켓인수검사'!A13 -> 05 | B11: E257 | C11: ='1. 소켓인수검사'!C13 -> 200 | D11: ='1. 소켓인수검사'!D13 -> 150 | F11: =C11*D11/1000000 -> 0.03 | G11: =(C11+D11)*2/1000 -> 0.7 | H11: 2 | I11: =(G11+0.4) -> 1.1 | J11: 10 | Q11: =(((C11+60)+250+(D11+60))*2/1000)*2 -> 2.88 | R11: =Q11*2 -> 5.76 | S11: FS-MP25-0310-3 | T11: EZ F.B POSMAC Duct-VT-049 | U11: ='1. 소켓인수검사'!G13 -> B1F
A12: ='1. 소켓인수검사'!A14 -> 06 | B12: E257 | C12: ='1. 소켓인수검사'!C14 -> 200 | D12: ='1. 소켓인수검사'!D14 -> 150 | F12: =C12*D12/1000000 -> 0.03 | G12: =(C12+D12)*2/1000 -> 0.7 | H12: 2 | I12: =(G12+0.4) -> 1.1 | J12: 10 | Q12: =(((C12+60)+250+(D12+60))*2/1000)*2 -> 2.88 | R12: =Q12*2 -> 5.76 | S12: FS-MP25-0310-3 | T12: EZ F.B POSMAC Duct-VT-049 | U12: ='1. 소켓인수검사'!G14 -> B3F
A13: ='1. 소켓인수검사'!A15 -> 07 | B13: E257 | C13: ='1. 소켓인수검사'!C15 -> 200 | D13: ='1. 소켓인수검사'!D15 -> 150 | F13: =C13*D13/1000000 -> 0.03 | G13: =(C13+D13)*2/1000 -> 0.7 | H13: 2 | I13: =(G13+0.4) -> 1.1 | J13: 10 | Q13: =(((C13+60)+250+(D13+60))*2/1000)*2 -> 2.88 | R13: =Q13*2 -> 5.76 | S13: FS-MP25-0310-3 | T13: EZ F.B POSMAC Duct-VT-049 | U13: ='1. 소켓인수검사'!G15 -> B3F
A14: ='1. 소켓인수검사'!A16 -> 08 | B14: E257 | C14: ='1. 소켓인수검사'!C16 -> 200 | D14: ='1. 소켓인수검사'!D16 -> 200 | F14: =C14*D14/1000000 -> 0.04 | G14: =(C14+D14)*2/1000 -> 0.8 | H14: 2 | I14: =(G14+0.4) -> 1.2 | J14: 10 | Q14: =(((C14+60)+250+(D14+60))*2/1000)*2 -> 3.08 | R14: =Q14*2 -> 6.16 | S14: FS-MP25-0310-3 | T14: EZ F.B POSMAC Duct-VT-049 | U14: ='1. 소켓인수검사'!G16 -> B1F
A15: ='1. 소켓인수검사'!A17 -> 09 | B15: E257 | C15: ='1. 소켓인수검사'!C17 -> 200 | D15: ='1. 소켓인수검사'!D17 -> 200 | F15: =C15*D15/1000000 -> 0.04 | G15: =(C15+D15)*2/1000 -> 0.8 | H15: 2 | I15: =(G15+0.4) -> 1.2 | J15: 10 | Q15: =(((C15+60)+250+(D15+60))*2/1000)*2 -> 3.08 | R15: =Q15*2 -> 6.16 | S15: FS-MP25-0310-3 | T15: EZ F.B POSMAC Duct-VT-049 | U15: ='1. 소켓인수검사'!G17 -> B1F
A16: ='1. 소켓인수검사'!A18 -> 10 | B16: E257 | C16: ='1. 소켓인수검사'!C18 -> 200 | D16: ='1. 소켓인수검사'!D18 -> 200 | F16: =C16*D16/1000000 -> 0.04 | G16: =(C16+D16)*2/1000 -> 0.8 | H16: 2 | I16: =(G16+0.4) -> 1.2 | J16: 10 | Q16: =(((C16+60)+250+(D16+60))*2/1000)*2 -> 3.08 | R16: =Q16*2 -> 6.16 | S16: FS-MP25-0310-3 | T16: EZ F.B POSMAC Duct-VT-049 | U16: ='1. 소켓인수검사'!G18 -> B1F
A17: ='1. 소켓인수검사'!A19 -> 11 | B17: E257 | C17: ='1. 소켓인수검사'!C19 -> 200 | D17: ='1. 소켓인수검사'!D19 -> 200 | F17: =C17*D17/1000000 -> 0.04 | G17: =(C17+D17)*2/1000 -> 0.8 | H17: 2 | I17: =(G17+0.4) -> 1.2 | J17: 10 | Q17: =(((C17+60)+250+(D17+60))*2/1000)*2 -> 3.08 | R17: =Q17*2 -> 6.16 | S17: FS-MP25-0310-3 | T17: EZ F.B POSMAC Duct-VT-049 | U17: ='1. 소켓인수검사'!G19 -> B1F
A18: ='1. 소켓인수검사'!A20 -> 12 | B18: E257 | C18: ='1. 소켓인수검사'!C20 -> 200 | D18: ='1. 소켓인수검사'!D20 -> 200 | F18: =C18*D18/1000000 -> 0.04 | G18: =(C18+D18)*2/1000 -> 0.8 | H18: 2 | I18: =(G18+0.4) -> 1.2 | J18: 10 | Q18: =(((C18+60)+250+(D18+60))*2/1000)*2 -> 3.08 | R18: =Q18*2 -> 6.16 | S18: FS-MP25-0310-3 | T18: EZ F.B POSMAC Duct-VT-049 | U18: ='1. 소켓인수검사'!G20 -> B2F
... A46: ='1. 소켓인수검사'!A48 -> 40 | B46: E257 | C46: ='1. 소켓인수검사'!C48 -> 1000 | D46: ='1. 소켓인수검사'!D48 -> 400 | F46: =C46*D46/1000000 -> 0.4 | G46: =(C46+D46)*2/1000 -> 2.8 | H46: 2 | I46: =(G46+0.4) -> 3.2 | J46: 10 | Q46: =(((C46+60)+250+(D46+60))*2/1000)*2 -> 7.08 | R46: =Q46*2 -> 14.16 | S46: FS-MP25-0310-3 | T46: EZ F.B POSMAC Duct-VT-049 | U46: ='1. 소켓인수검사'!G48 -> B1F
A47: ='1. 소켓인수검사'!A49 -> 41 | B47: E257 | C47: ='1. 소켓인수검사'!C49 -> 500 | D47: ='1. 소켓인수검사'!D49 -> 300 | F47: =C47*D47/1000000 -> 0.15 | G47: =(C47+D47)*2/1000 -> 1.6 | H47: 2 | K47: =G47+0.5 -> 2.1 | L47: 10 | Q47: =(((C47+60)+250+(D47+60))*2/1000)*2 -> 4.68 | R47: =Q47*2 -> 9.36 | S47: FS-MP25-0310-4 | T47: EZ F.B POSMAC Duct-VA-064 | U47: ='1. 소켓인수검사'!G49 -> 제연B4F
A48: ='1. 소켓인수검사'!A50 -> 42 | B48: E257 | C48: ='1. 소켓인수검사'!C50 -> 500 | D48: ='1. 소켓인수검사'!D50 -> 300 | F48: =C48*D48/1000000 -> 0.15 | G48: =(C48+D48)*2/1000 -> 1.6 | H48: 2 | K48: =G48+0.5 -> 2.1 | L48: 10 | Q48: =(((C48+60)+250+(D48+60))*2/1000)*2 -> 4.68 | R48: =Q48*2 -> 9.36 | S48: FS-MP25-0310-4 | T48: EZ F.B POSMAC Duct-VA-064 | U48: ='1. 소켓인수검사'!G50 -> 제연B4F
A49: ='1. 소켓인수검사'!A51 -> 43 | B49: E257 | C49: ='1. 소켓인수검사'!C51 -> 700 | D49: ='1. 소켓인수검사'!D51 -> 250 | F49: =C49*D49/1000000 -> 0.175 | G49: =(C49+D49)*2/1000 -> 1.9 | H49: 2 | K49: =G49+0.5 -> 2.4 | L49: 10 | Q49: =(((C49+60)+250+(D49+60))*2/1000)*2 -> 5.28 | R49: =Q49*2 -> 10.56 | S49: FS-MP25-0310-4 | T49: EZ F.B POSMAC Duct-VA-064 | U49: ='1. 소켓인수검사'!G51 -> 제연B3~4F
A50: ='1. 소켓인수검사'!A52 -> 44 | B50: E257 | C50: ='1. 소켓인수검사'!C52 -> 700 | D50: ='1. 소켓인수검사'!D52 -> 250 | F50: =C50*D50/1000000 -> 0.175 | G50: =(C50+D50)*2/1000 -> 1.9 | H50: 2 | K50: =G50+0.5 -> 2.4 | L50: 10 | Q50: =(((C50+60)+250+(D50+60))*2/1000)*2 -> 5.28 | R50: =Q50*2 -> 10.56 | S50: FS-MP25-0310-4 | T50: EZ F.B POSMAC Duct-VA-064 | U50: ='1. 소켓인수검사'!G52 -> 제연B3~4F
A51: ='1. 소켓인수검사'!A53 -> 45 | B51: E257 | C51: ='1. 소켓인수검사'!C53 -> 1000 | D51: ='1. 소켓인수검사'!D53 -> 350 | F51: =C51*D51/1000000 -> 0.35 | G51: =(C51+D51)*2/1000 -> 2.7 | H51: 2 | K51: =G51+0.5 -> 3.2 | L51: 10 | Q51: =(((C51+60)+250+(D51+60))*2/1000)*2 -> 6.88 | R51: =Q51*2 -> 13.76 | S51: FS-MP25-0310-4 | T51: EZ F.B POSMAC Duct-VA-064 | U51: ='1. 소켓인수검사'!G53 -> 제연B2F
A52: TTL | H52: =SUM(H7:H51) -> 90 | J52: =SUM(J7:J51) -> 400 | L52: =SUM(L7:L51) -> 50 | N52: =SUM(N7:N51) -> 0 | P52: =SUM(P7:P51) -> 0 | Q52: =SUM(Q7:Q51) -> 172.6 | R52: =SUM(R7:R51) -> 345.2
A54: 특이사항 및 조치사항
